Workbook

Sheet CCF
B2: Kondisi Terkini Fisiologis*
B3: Waktu | C3: CCF
C4: Urinasi | D4: Defekasi | E4: Kotor | F4: Energi | G4: Lapar | H4: Haus | I4: Lelah | J4: Kantuk
C5: UR | D5: DF | E5: DR | F5: EN | G5: HG | H5: TH | I5: EX | J5: SL
B6: 0.31944444 | C6: 6 | D6: 3 | E6: 2 | F6: 9 | G6: 4 | H6: 2 | I6: 1 | J6: 0.75
B8: *Rekap data setiap ada perubahan pada KAL.F
B9: CCF dan Standar Fisiologis masuk dalam perhitungan di pilih

Sheet CCE
B2: Kondisi Terkini Emosi*
B3: Waktu | C3: CCE**
B4: 0.33333333 | C4: =[1]Kal.E!L7 -> 1.0617
B6: *Rekap data setiap ada perubahan pada KAL.E
B7: **Total efek di KAL.E, terjadi perubahan di Total Efek setiap aktivitas berubah atau terinterupsi
B8: CCE dan Standar Emosi masuk dalam perhitungan di pilih

Sheet Data Agen
A1: OPERASI
B2: Rekap Data Agen Terkini
B4: Waktu | C4: Fisik | D4: CCE | E4: CCB | M4: Aktivitas | N4: Posisi Ruang | O4: Posisi Titik
E5: UR | F5: DF | G5: DR | H5: EN | I5: HG | J5: TH | K5: EX | L5: SL
E6: =CCF!C6 -> 6 | F6: =CCF!D6 -> 3 | G6: =CCF!E6 -> 2 | H6: =CCF!F6 -> 9 | I6: =CCF!G6 -> 4 | J6: =CCF!H6 -> 2 | K6: =CCF!I6 -> 1 | L6: =CCF!J6 -> 0.75 | N6: RMK01 | O6: KU02
B7: waktu terakhir | C7: Copy Kal.F | D7: copy Kal.E | E7: copy Kal.B | M7: aktivitas terakhir | N7: ruang apa | O7: duduk/tidur/berdiri dimana

Sheet Pilih_Tergabung
B1: KETERANGAN | F1: JENIS AKTIVITAS | H1: STATUS | L1: PRIORITAS
C2: Aktivitas prasyarat: hanya bisa dilakukan jika didahului aktivitas tertentu (PR;KODE AKTIVITAS PENDAHULU) | F2: 0 | G2: outdoor | H2: SL | I2: Selesai | J2: Aktivitas selesai, sisa pengulangan > 0, R: bisa terkalkulasi pada proses pilih selanjutnya | L2: 0 | M2: Tidak mengubah status R ke I, aktivitas tertunda bisa terkalkulasi di proses pilih selanjutnya
C3: Data yang bisa berubah: dari CCF & CCE; tingkat kotor diri sendiri; berubah karena waktu dibatalkan; status R/I; batas waktu insidental; status SL/ BM/ BS; sisa pengulangan; Pengali emosi; Urutan pengali emosi | F3: I | G3: indoor | H3: BM | I3: Belum mulai | J3: Aktivitas belum mulai, sisa pengulangan > 0, R/I: bisa terkalkulasi pada proses pilih selanjutnya (jika I, hanya terkalkulasi ketika waktu terkini > batas waktu I) | sisa pengulangan = 0, R/I: tidak bisa terkalkulasi pada proses pilih selanjutnya (jika I, hanya terkalkulasi pada hari/ minggu berikutnya sesuai dengan nilai prioritas 3/4) | L3: 1 | M3: Mengubah R ke I, aktivitas tidak terkalkulasi dalam proses pilih hingga 6 jam berikutnya
C4: Input data eksternal agen (tingkat fisiologis agen lain, urgensi lingkungan) dari Data Dasar Agen Dummy 25 Aug | F4: PR | G4: prerequisite | H4: BS | I4: Belum selesai | J4: Aktivitas sedang berjalan/ tertunda, sisa pengulangan > 0, status R ke I (prioritas 1-4): bisa terkalkulasi pada proses pilih selanjutnya (jika I, hanya terkalkulasi ketika waktu terkini > batas waktu I) | L4: 2 | M4: Mengubah R ke I, aktivitas tidak terkalkulasi dalam proses pilih hingga 12 jam berikutnya
C5: Total Nilai = Total Jadwal + Total EF.F + Urgensi waktu terpilih | F5: PA | G5: planned | L5: 3 | M5: Mengubah R ke I, aktivitas tidak terkalkulasi dalam proses pilih hingga 24 jam berikutnya (hari berikutnya di jadwal yang sama)
C6: Kalkulasi urgensi waktu; kalkulasi selisih nilai fisiologis; kalkulasi per karakteristik aktivitas | F6: UA | G6: unplanned | L6: 4 | M6: Mengubah R ke I, aktivitas tidak terkalkulasi dalam proses pilih hingga minggu berikutnya di jadwal yang sama
C7: Data konstan dari Data Dasar Survei Agen 25 Aug | F7: A | G7: auto (durasi = durasi alat listrik digunakan, durasi aktivitas agen = 5 menit)
B9: No | C9: Jenis | D9: Kode | E9: Aktivitas | F9: Informasi | N9: TOTAL NILAI | O9: Waktu | T9: Fisiologis | AS9: Karakter Aktivitas
T10: Total EF.F | U10: Selisih | AC10: CCF | AK10: Standar Fisiologis | AS10: TOTAL JADWAL | AT10: Keinginan | BB10: Keuntungan | BE10: Aturan | BJ10: Kebutuhan
F11: Status (SL/ BM/ BS) | G11: Kode Pengulangan Waktu (aktivitas berjalan) | H11: Status Aktivitas | I11: Status Aktivitas | J11: Pengulangan (kalau batal dalam H/M) | L11: Prioritas (kalau batal dalam H/M) | O11: Urgensi waktu terpilih | P11: 0.31944444 | Q11: Batas Mulai (Sequence by survey) | R11: Rentang Waktu Insidental | U11: Urinasi | V11: Defekasi | W11: Kotor | X11: Energi | Y11: Lapar | Z11: Haus | AA11: Lelah | AB11: Kantuk | AC11: Urinasi | AD11: Defekasi | AE11: Kotor | AF11: Energi | AG11: Lapar | AH11: Haus | AI11: Lelah | AJ11: Kantuk | AK11: Urinasi | AL11: Defekasi | AM11: Kotor | AN11: Energi | AO11: Lapar | AP11: Haus | AQ11: Lelah | AR11: Kantuk | AT11: Total | AU11: SN | AV11: Emosi | BB11: Total | BC11: SN | BD11: Nilai Matriks | BE11: Total | BF11: Pengaruh agen otoritas | BG11: Obligate time (belum diperhitungkan) | BH11: Otoritas | BI11: Kepatuhan | BJ11: Total | BK11: SN Urgensi | BL11: Diri sendiri | BM11: Ayah | BO11: Nenek | BQ11: Anak 1 | BS11: Anak 2 | BV11: Urgensi Lingkungan
H12: DI/MI | I12: R/I | J12: Jumlah | K12: Sisa | P12: Selisih batas waktu | R12: Waktu dibatalkan | S12: Batas Waktu Insidental | U12: UR | V12: DF | W12: DR | X12: EN | Y12: HG | Z12: TH | AA12: EX | AB12: SL | AC12: UR | AD12: DF | AE12: DR | AF12: EN | AG12: HG | AH12: TH | AI12: EX | AJ12: SL | AK12: UR | AL12: DF | AM12: DR | AN12: EN | AO12: HG | AP12: TH | AQ12: EX | AR12: SL | AV12: Pengali Emosi | AW12: Urutan Pengali Emosi | AX12: YA/ TIDAK | AY12: TOTAL EF.E | AZ12: CCE | BA12: Standar Emosi | BL12: Kotor | BM12: Lapar | BN12: Haus | BO12: Lapar | BP12: Haus | BQ12: Lapar | BR12: Haus | BS12: Lapar | BT12: Haus | BU12: Kotor
B13: 1 | C13: PA-I | D13: A1 | E13: Membereskan kasur & karpet tidur di pagi hari | G13: H | H13: DI | I13: =IF(R13>0,IF(S13-$P$11>0,"I","R"),"R") -> R | J13: 2 | L13: 0 | M13: 0.25 | N13: =IF(I13="I",0,IF(AX13="YA",O13+T13+AS13,0)) -> 16.364583 | O13: =IF(P13="-",5,IF(10-(P13/60)>10,10+(P13/60*10),10-(P13/60))) -> 7.3333333 | P13: =IF(Q13="-","-",IF((Q13-$P$11)*1440>1,(Q13-$P$11)*1440,-1*(Q13-$P$11)*1440)) -> 160 | Q13: 0.20833333 | S13: =IF(L13=0,0,IF(L13=1,R13+$M$13,IF(L13=2,R13+$M$14,IF(L13=3,R13+$M$15,IF(L13=4,R13+$M$16,0))))) -> 0 | T13: =SUM(U13:AB13)/8 -> 4.03125 | U13: =AK13-$AC$13 -> 3 | V13: =AL13-$AD$13 -> 5 | W13: =AM13-$AE$13 -> 7 | X13: =$AF$13-AN13 -> 2 | Y13: =AO13-$AG$13 -> 5 | Z13: =AP13-$AH$13 -> 7 | AA13: =AQ13-$AH$13 -> 1 | AB13: =AR13-$AJ$13 -> 2.25 | AC13: 6 | AD13: 3 | AE13: 2 | AF13: 9 | AG13: 4 | AH13: 2 | AI13: 1 | AJ13: 0.75 | AK13: 9 | AL13: 8 | AM13: 9 | AN13: 7 | AO13: 9 | AP13: 9 | AQ13: 3 | AR13: 3 | AS13: =(AT13+BB13+BE13+BJ13)/4 -> 5 | AT13: =AU13*AV13 -> 0 | AU13: 3 | AV13: =IF(AW13=1,1,IF(AW13=2,0.9,IF(AW13=3,0.8,IF(AW13=4,0.7,IF(AW13=5,0.6,IF(AW13=6,0.5,IF(AW13=7,0.4,IF(AW13=8,0.3,IF(AW13=9,0.2,IF(AW13=10,0.1,IF(AW13=0,0,0))))))))))) -> 0 | AX13: =IF($AZ$13>=BA13,"YA","TIDAK") -> YA | AY13: =IF($AZ$13-BA13>0,$AZ$13-BA13,"0") -> 0.26 | AZ13: 1.01 | BA13: 0.75 | BB13: =BC13+BD13 -> 5 | BC13: 5 | BE13: =BF13*BH13*BI13 -> 0 | BJ13: =SUM(BK13:BV13) -> 15 | BK13: 5 | BV13: 10
B14: 2 | C14: PA-I;A | D14: A2 | E14: Mengisi ulang daya gadget | G14: H | H14: DI | I14: =IF(R14>0,IF(S14-$P$11>0,"I","R"),"R") -> R | J14: 3 | L14: 0 | M14: 0.5 | N14: =IF(I14="I",0,IF(AX14="YA",O14+T14+AS14,0)) -> 15.697917 | O14: =IF(P14="-",5,IF(10-(P14/60)>10,10+(P14/60*10),10-(P14/60))) -> 7.4166667 | P14: =IF(Q14="-","-",IF((Q14-$P$11)*1440>1,(Q14-$P$11)*1440,-1*(Q14-$P$11)*1440)) -> 155 | Q14: 0.21180556 | S14: =IF(L14=0,0,IF(L14=1,R14+$M$13,IF(L14=2,R14+$M$14,IF(L14=3,R14+$M$15,IF(L14=4,R14+$M$16,0))))) -> 0 | T14: =SUM(U14:AB14)/8 -> 4.53125 | U14: =AK14-$AC$13 -> 3 | V14: =AL14-$AD$13 -> 5 | W14: =AM14-$AE$13 -> 7 | X14: =$AF$13-AN14 -> 2 | Y14: =AO14-$AG$13 -> 5 | Z14: =AP14-$AH$13 -> 7 | AA14: =AQ14-$AH$13 -> 3 | AB14: =AR14-$AJ$13 -> 4.25 | AK14: 9 | AL14: 8 | AM14: 9 | AN14: 7 | AO14: 9 | AP14: 9 | AQ14: 5 | AR14: 5 | AS14: =(AT14+BB14+BE14+BJ14)/4 -> 3.75 | AT14: =AU14*AV14 -> 0 | AU14: 5 | AV14: =IF(AW14=1,1,IF(AW14=2,0.9,IF(AW14=3,0.8,IF(AW14=4,0.7,IF(AW14=5,0.6,IF(AW14=6,0.5,IF(AW14=7,0.4,IF(AW14=8,0.3,IF(AW14=9,0.2,IF(AW14=10,0.1,IF(AW14=0,0,0))))))))))) -> 0 | AX14: =IF($AZ$13>=BA14,"YA","TIDAK") -> YA | AY14: =IF($AZ$13-BA14>0,$AZ$13-BA14,"0") -> 0.76 | BA14: 0.25 | BB14: =BC14+BD14 -> 8 | BC14: 8 | BE14: =BF14*BH14*BI14 -> 0 | BJ14: =SUM(BK14:BV14) -> 7 | BK14: 7
B15: 3 | C15: PR;A55 | D15: A3 | E15: Mematikan lampu garasi di pagi hari | G15: H | H15: DI | I15: =IF(R15>0,IF(S15-$P$11>0,"I","R"),"R") -> R | J15: 3 | L15: 0 | M15: 0.99930556 | N15: =IF(I15="I",0,IF(AX15="YA",O15+T15+AS15,0)) -> 15.747917 | O15: =IF(P15="-",5,IF(10-(P15/60)>10,10+(P15/60*10),10-(P15/60))) -> 7.4666667 | P15: =IF(Q15="-","-",IF((Q15-$P$11)*1440>1,(Q15-$P$11)*1440,-1*(Q15-$P$11)*1440)) -> 152 | Q15: 0.21388889 | S15: =IF(L15=0,0,IF(L15=1,R15+$M$13,IF(L15=2,R15+$M$14,IF(L15=3,R15+$M$15,IF(L15=4,R15+$M$16,0))))) -> 0 | T15: =SUM(U15:AB15)/8 -> 4.53125 | U15: =AK15-$AC$13 -> 3 | V15: =AL15-$AD$13 -> 5 | W15: =AM15-$AE$13 -> 7 | X15: =$AF$13-AN15 -> 2 | Y15: =AO15-$AG$13 -> 5 | Z15: =AP15-$AH$13 -> 7 | AA15: =AQ15-$AH$13 -> 3 | AB15: =AR15-$AJ$13 -> 4.25 | AK15: 9 | AL15: 8 | AM15: 9 | AN15: 7 | AO15: 9 | AP15: 9 | AQ15: 5 | AR15: 5 | AS15: =(AT15+BB15+BE15+BJ15)/4 -> 3.75 | AT15: =AU15*AV15 -> 0 | AU15: 5 | AV15: =IF(AW15=1,1,IF(AW15=2,0.9,IF(AW15=3,0.8,IF(AW15=4,0.7,IF(AW15=5,0.6,IF(AW15=6,0.5,IF(AW15=7,0.4,IF(AW15=8,0.3,IF(AW15=9,0.2,IF(AW15=10,0.1,IF(AW15=0,0,0))))))))))) -> 0 | AX15: =IF($AZ$13>=BA15,"YA","TIDAK") -> YA | AY15: =IF($AZ$13-BA15>0,$AZ$13-BA15,"0") -> 0.76 | BA15: 0.25 | BB15: =BC15+BD15 -> 8 | BC15: 8 | BE15: =BF15*BH15*BI15 -> 0 | BH15: 1 | BI15: 8 | BJ15: =SUM(BK15:BV15) -> 7 | BK15: 7
B16: 4 | C16: PA-O | D16: A4 | E16: Belanja | G16: M;5 | H16: DI/MI | I16: =IF(R16>0,IF(S16-$P$11>0,"I","R"),"R") -> R | J16: -1 | L16: 3 | M16: 7 | N16: =IF(I16="I",0,IF(AX16="YA",O16+T16+AS16,0)) -> 14.489583 | O16: =IF(P16="-",5,IF(10-(P16/60)>10,10+(P16/60*10),10-(P16/60))) -> 7.8333333 | P16: =IF(Q16="-","-",IF((Q16-$P$11)*1440>1,(Q16-$P$11)*1440,-1*(Q16-$P$11)*1440)) -> 130 | Q16: 0.22916667 | S16: =IF(L16=0,0,IF(L16=1,R16+$M$13,IF(L16=2,R16+$M$14,IF(L16=3,R16+$M$15,IF(L16=4,R16+$M$16,0))))) -> 0.99930556 | T16: =SUM(U16:AB16)/8 -> 2.65625 | U16: =AK16-$AC$13 -> 2 | V16: =AL16-$AD$13 -> 5 | W16: =AM16-$AE$13 -> 6 | X16: =$AF$13-AN16 -> 5 | Y16: =AO16-$AG$13 -> 1 | Z16: =AP16-$AH$13 -> 0 | AA16: =AQ16-$AH$13 -> 0 | AB16: =AR16-$AJ$13 -> 2.25 | AK16: 8 | AL16: 8 | AM16: 8 | AN16: 4 | AO16: 5 | AP16: 2 | AQ16: 2 | AR16: 3 | AS16: =(AT16+BB16+BE16+BJ16)/4 -> 4 | AT16: =AU16*AV16 -> 0 | AU16: 5 | AV16: =IF(AW16=1,1,IF(AW16=2,0.9,IF(AW16=3,0.8,IF(AW16=4,0.7,IF(AW16=5,0.6,IF(AW16=6,0.5,IF(AW16=7,0.4,IF(AW16=8,0.3,IF(AW16=9,0.2,IF(AW16=10,0.1,IF(AW16=0,0,0))))))))))) -> 0 | AX16: =IF($AZ$13>=BA16,"YA","TIDAK") -> YA | AY16: =IF($AZ$13-BA16>0,$AZ$13-BA16,"0") -> 0.01 | BA16: 1 | BB16: =BC16+BD16 -> 8 | BC16: 8 | BE16: =BF16*BH16*BI16 -> 0 | BJ16: =SUM(BK16:BV16) -> 8 | BK16: 8
B17: 5 | C17: PA-I | D17: A5 | E17: Menyapu Ruang Tidur Utama 1 | G17: H | H17: DI/MI | I17: =IF(R17>0,IF(S17-$P$11>0,"I","R"),"R") -> R | J17: 3 | L17: 0 | N17: =IF(I17="I",0,IF(AX17="YA",O17+T17+AS17,0)) -> 15.739583 | O17: =IF(P17="-",5,IF(10-(P17/60)>10,10+(P17/60*10),10-(P17/60))) -> 7.8333333 | P17: =IF(Q17="-","-",IF((Q17-$P$11)*1440>1,(Q17-$P$11)*1440,-1*(Q17-$P$11)*1440)) -> 130 | Q17: 0.22916667 | S17: =IF(L17=0,0,IF(L17=1,R17+$M$13,IF(L17=2,R17+$M$14,IF(L17=3,R17+$M$15,IF(L17=4,R17+$M$16,0))))) -> 0 | T17: =SUM(U17:AB17)/8 -> 4.65625 | U17: =AK17-$AC$13 -> 3 | V17: =AL17-$AD$13 -> 5 | W17: =AM17-$AE$13 -> 7 | X17: =$AF$13-AN17 -> 3 | Y17: =AO17-$AG$13 -> 5 | Z17: =AP17-$AH$13 -> 7 | AA17: =AQ17-$AH$13 -> 1 | AB17: =AR17-$AJ$13 -> 6.25 | AK17: 9 | AL17: 8 | AM17: 9 | AN17: 6 | AO17: 9 | AP17: 9 | AQ17: 3 | AR17: 7 | AS17: =(AT17+BB17+BE17+BJ17)/4 -> 3.25 | AT17: =AU17*AV17 -> 0 | AU17: 2 | AV17: =IF(AW17=1,1,IF(AW17=2,0.9,IF(AW17=3,0.8,IF(AW17=4,0.7,IF(AW17=5,0.6,IF(AW17=6,0.5,IF(AW17=7,0.4,IF(AW17=8,0.3,IF(AW17=9,0.2,IF(AW17=10,0.1,IF(AW17=0,0,0))))))))))) -> 0 | AX17: =IF($AZ$13>=BA17,"YA","TIDAK") -> YA | AY17: =IF($AZ$13-BA17>0,$AZ$13-BA17,"0") -> 0.26 | BA17: 0.75 | BB17: =BC17+BD17 -> 10 | BC17: 10 | BE17: =BF17*BH17*BI17 -> 0 | BH17: 1 | BI17: 5 | BJ17: =SUM(BK17:BV17) -> 3 | BK17: 3
B18: 6 | C18: PA-I | D18: A6 | E18: Menyapu Ruang Tidur Utama 2 | G18: H | H18: DI/MI | I18: =IF(R18>0,IF(S18-$P$11>0,"I","R"),"R") -> R | J18: 3 | L18: 0 | N18: =IF(I18="I",0,IF(AX18="YA",O18+T18+AS18,0)) -> 15.80625 | O18: =IF(P18="-",5,IF(10-(P18/60)>10,10+(P18/60*10),10-(P18/60))) -> 7.9 | P18: =IF(Q18="-","-",IF((Q18-$P$11)*1440>1,(Q18-$P$11)*1440,-1*(Q18-$P$11)*1440)) -> 126 | Q18: 0.23194444 | S18: =IF(L18=0,0,IF(L18=1,R18+$M$13,IF(L18=2,R18+$M$14,IF(L18=3,R18+$M$15,IF(L18=4,R18+$M$16,0))))) -> 0 | T18: =SUM(U18:AB18)/8 -> 4.65625 | U18: =AK18-$AC$13 -> 3 | V18: =AL18-$AD$13 -> 5 | W18: =AM18-$AE$13 -> 7 | X18: =$AF$13-AN18 -> 3 | Y18: =AO18-$AG$13 -> 5 | Z18: =AP18-$AH$13 -> 7 | AA18: =AQ18-$AH$13 -> 1 | AB18: =AR18-$AJ$13 -> 6.25 | AK18: 9 | AL18: 8 | AM18: 9 | AN18: 6 | AO18: 9 | AP18: 9 | AQ18: 3 | AR18: 7 | AS18: =(AT18+BB18+BE18+BJ18)/4 -> 3.25 | AT18: =AU18*AV18 -> 0 | AU18: 2 | AV18: =IF(AW18=1,1,IF(AW18=2,0.9,IF(AW18=3,0.8,IF(AW18=4,0.7,IF(AW18=5,0.6,IF(AW18=6,0.5,IF(AW18=7,0.4,IF(AW18=8,0.3,IF(AW18=9,0.2,IF(AW18=10,0.1,IF(AW18=0,0,0))))))))))) -> 0 | AX18: =IF($AZ$13>=BA18,"YA","TIDAK") -> YA | AY18: =IF($AZ$13-BA18>0,$AZ$13-BA18,"0") -> 0.26 | BA18: 0.75 | BB18: =BC18+BD18 -> 10 | BC18: 10 | BE18: =BF18*BH18*BI18 -> 0 | BH18: 1 | BI18: 5 | BJ18: =SUM(BK18:BV18) -> 3 | BK18: 3
B19: 7 | C19: PA-I | D19: A7 | E19: Menyapu Ruang Kerja | G19: H | H19: DI/MI | I19: =IF(R19>0,IF(S19-$P$11>0,"I","R"),"R") -> R | J19: 3 | L19: 0 | N19: =IF(I19="I",0,IF(AX19="YA",O19+T19+AS19,0)) -> 15.889583 | O19: =IF(P19="-",5,IF(10-(P19/60)>10,10+(P19/60*10),10-(P19/60))) -> 7.9833333 | P19: =IF(Q19="-","-",IF((Q19-$P$11)*1440>1,(Q19-$P$11)*1440,-1*(Q19-$P$11)*1440)) -> 121 | Q19: 0.23541667 | S19: =IF(L19=0,0,IF(L19=1,R19+$M$13,IF(L19=2,R19+$M$14,IF(L19=3,R19+$M$15,IF(L19=4,R19+$M$16,0))))) -> 0 | T19: =SUM(U19:AB19)/8 -> 4.65625 | U19: =AK19-$AC$13 -> 3 | V19: =AL19-$AD$13 -> 5 | W19: =AM19-$AE$13 -> 7 | X19: =$AF$13-AN19 -> 3 | Y19: =AO19-$AG$13 -> 5 | Z19: =AP19-$AH$13 -> 7 | AA19: =AQ19-$AH$13 -> 1 | AB19: =AR19-$AJ$13 -> 6.25 | AK19: 9 | AL19: 8 | AM19: 9 | AN19: 6 | AO19: 9 | AP19: 9 | AQ19: 3 | AR19: 7 | AS19: =(AT19+BB19+BE19+BJ19)/4 -> 3.25 | AT19: =AU19*AV19 -> 0 | AU19: 2 | AV19: =IF(AW19=1,1,IF(AW19=2,0.9,IF(AW19=3,0.8,IF(AW19=4,0.7,IF(AW19=5,0.6,IF(AW19=6,0.5,IF(AW19=7,0.4,IF(AW19=8,0.3,IF(AW19=9,0.2,IF(AW19=10,0.1,IF(AW19=0,0,0))))))))))) -> 0 | AX19: =IF($AZ$13>=BA19,"YA","TIDAK") -> YA | AY19: =IF($AZ$13-BA19>0,$AZ$13-BA19,"0") -> 0.26 | BA19: 0.75 | BB19: =BC19+BD19 -> 10 | BC19: 10 | BE19: =BF19*BH19*BI19 -> 0 | BH19: 1 | BI19: 5 | BJ19: =SUM(BK19:BV19) -> 3 | BK19: 3
B20: 8 | C20: PA-I | D20: A8 | E20: Menyapu Ruang Belakang | G20: H | H20: DI/MI | I20: =IF(R20>0,IF(S20-$P$11>0,"I","R"),"R") -> R | J20: 3 | L20: 0 | N20: =IF(I20="I",0,IF(AX20="YA",O20+T20+AS20,0)) -> 16.00625 | O20: =IF(P20="-",5,IF(10-(P20/60)>10,10+(P20/60*10),10-(P20/60))) -> 8.1 | P20: =IF(Q20="-","-",IF((Q20-$P$11)*1440>1,(Q20-$P$11)*1440,-1*(Q20-$P$11)*1440)) -> 114 | Q20: 0.24027778 | S20: =IF(L20=0,0,IF(L20=1,R20+$M$13,IF(L20=2,R20+$M$14,IF(L20=3,R20+$M$15,IF(L20=4,R20+$M$16,0))))) -> 0 | T20: =SUM(U20:AB20)/8 -> 4.65625 | U20: =AK20-$AC$13 -> 3 | V20: =AL20-$AD$13 -> 5 | W20: =AM20-$AE$13 -> 7 | X20: =$AF$13-AN20 -> 3 | Y20: =AO20-$AG$13 -> 5 | Z20: =AP20-$AH$13 -> 7 | AA20: =AQ20-$AH$13 -> 1 | AB20: =AR20-$AJ$13 -> 6.25 | AK20: 9 | AL20: 8 | AM20: 9 | AN20: 6 | AO20: 9 | AP20: 9 | AQ20: 3 | AR20: 7 | AS20: =(AT20+BB20+BE20+BJ20)/4 -> 3.25 | AT20: =AU20*AV20 -> 0 | AU20: 2 | AV20: =IF(AW20=1,1,IF(AW20=2,0.9,IF(AW20=3,0.8,IF(AW20=4,0.7,IF(AW20=5,0.6,IF(AW20=6,0.5,IF(AW20=7,0.4,IF(AW20=8,0.3,IF(AW20=9,0.2,IF(AW20=10,0.1,IF(AW20=0,0,0))))))))))) -> 0 | AX20: =IF($AZ$13>=BA20,"YA","TIDAK") -> YA | AY20: =IF($AZ$13-BA20>0,$AZ$13-BA20,"0") -> 0.26 | BA20: 0.75 | BB20: =BC20+BD20 -> 10 | BC20: 10 | BE20: =BF20*BH20*BI20 -> 0 | BH20: 1 | BI20: 5 | BJ20: =SUM(BK20:BV20) -> 3 | BK20: 3
B21: 9 | C21: PA-I | D21: A9 | E21: Menyapu Dapur Kotor | G21: H | H21: DI/MI | I21: =IF(R21>0,IF(S21-$P$11>0,"I","R"),"R") -> R | J21: 3 | L21: 0 | N21: =IF(I21="I",0,IF(AX21="YA",O21+T21+AS21,0)) -> 16.039583 | O21: =IF(P21="-",5,IF(10-(P21/60)>10,10+(P21/60*10),10-(P21/60))) -> 8.1333333 | P21: =IF(Q21="-","-",IF((Q21-$P$11)*1440>1,(Q21-$P$11)*1440,-1*(Q21-$P$11)*1440)) -> 112 | Q21: 0.24166667 | S21: =IF(L21=0,0,IF(L21=1,R21+$M$13,IF(L21=2,R21+$M$14,IF(L21=3,R21+$M$15,IF(L21=4,R21+$M$16,0))))) -> 0 | T21: =SUM(U21:AB21)/8 -> 4.65625 | U21: =AK21-$AC$13 -> 3 | V21: =AL21-$AD$13 -> 5 | W21: =AM21-$AE$13 -> 7 | X21: =$AF$13-AN21 -> 3 | Y21: =AO21-$AG$13 -> 5 | Z21: =AP21-$AH$13 -> 7 | AA21: =AQ21-$AH$13 -> 1 | AB21: =AR21-$AJ$13 -> 6.25 | AK21: 9 | AL21: 8 | AM21: 9 | AN21: 6 | AO21: 9 | AP21: 9 | AQ21: 3 | AR21: 7 | AS21: =(AT21+BB21+BE21+BJ21)/4 -> 3.25 | AT21: =AU21*AV21 -> 0 | AU21: 2 | AV21: =IF(AW21=1,1,IF(AW21=2,0.9,IF(AW21=3,0.8,IF(AW21=4,0.7,IF(AW21=5,0.6,IF(AW21=6,0.5,IF(AW21=7,0.4,IF(AW21=8,0.3,IF(AW21=9,0.2,IF(AW21=10,0.1,IF(AW21=0,0,0))))))))))) -> 0 | AX21: =IF($AZ$13>=BA21,"YA","TIDAK") -> YA | AY21: =IF($AZ$13-BA21>0,$AZ$13-BA21,"0") -> 0.26 | BA21: 0.75 | BB21: =BC21+BD21 -> 10 | BC21: 10 | BE21: =BF21*BH21*BI21 -> 0 | BH21: 1 | BI21: 5 | BJ21: =SUM(BK21:BV21) -> 3 | BK21: 3
B22: 10 | C22: PA-I | D22: A10 | E22: Menyapu Dapur Bersih | G22: H | H22: DI/MI | I22: =IF(R22>0,IF(S22-$P$11>0,"I","R"),"R") -> R | J22: 3 | L22: 0 | N22: =IF(I22="I",0,IF(AX22="YA",O22+T22+AS22,0)) -> 16.139583 | O22: =IF(P22="-",5,IF(10-(P22/60)>10,10+(P22/60*10),10-(P22/60))) -> 8.2333333 | P22: =IF(Q22="-","-",IF((Q22-$P$11)*1440>1,(Q22-$P$11)*1440,-1*(Q22-$P$11)*1440)) -> 106 | Q22: 0.24583333 | S22: =IF(L22=0,0,IF(L22=1,R22+$M$13,IF(L22=2,R22+$M$14,IF(L22=3,R22+$M$15,IF(L22=4,R22+$M$16,0))))) -> 0 | T22: =SUM(U22:AB22)/8 -> 4.65625 | U22: =AK22-$AC$13 -> 3 | V22: =AL22-$AD$13 -> 5 | W22: =AM22-$AE$13 -> 7 | X22: =$AF$13-AN22 -> 3 | Y22: =AO22-$AG$13 -> 5 | Z22: =AP22-$AH$13 -> 7 | AA22: =AQ22-$AH$13 -> 1 | AB22: =AR22-$AJ$13 -> 6.25 | AK22: 9 | AL22: 8 | AM22: 9 | AN22: 6 | AO22: 9 | AP22: 9 | AQ22: 3 | AR22: 7 | AS22: =(AT22+BB22+BE22+BJ22)/4 -> 3.25 | AT22: =AU22*AV22 -> 0 | AU22: 2 | AV22: =IF(AW22=1,1,IF(AW22=2,0.9,IF(AW22=3,0.8,IF(AW22=4,0.7,IF(AW22=5,0.6,IF(AW22=6,0.5,IF(AW22=7,0.4,IF(AW22=8,0.3,IF(AW22=9,0.2,IF(AW22=10,0.1,IF(AW22=0,0,0))))))))))) -> 0 | AX22: =IF($AZ$13>=BA22,"YA","TIDAK") -> YA | AY22: =IF($AZ$13-BA22>0,$AZ$13-BA22,"0") -> 0.26 | BA22: 0.75 | BB22: =BC22+BD22 -> 10 | BC22: 10 | BE22: =BF22*BH22*BI22 -> 0 | BH22: 1 | BI22: 5 | BJ22: =SUM(BK22:BV22) -> 3 | BK22: 3
B23: 11 | C23: PA-I | D23: A11 | E23: Menyapu Ruang Keluarga | G23: H | H23: DI/MI | I23: =IF(R23>0,IF(S23-$P$11>0,"I","R"),"R") -> R | J23: 3 | L23: 0 | N23: =IF(I23="I",0,IF(AX23="YA",O23+T23+AS23,0)) -> 16.189583 | O23: =IF(P23="-",5,IF(10-(P23/60)>10,10+(P23/60*10),10-(P23/60))) -> 8.2833333 | P23: =IF(Q23="-","-",IF((Q23-$P$11)*1440>1,(Q23-$P$11)*1440,-1*(Q23-$P$11)*1440)) -> 103 | Q23: 0.24791667 | S23: =IF(L23=0,0,IF(L23=1,R23+$M$13,IF(L23=2,R23+$M$14,IF(L23=3,R23+$M$15,IF(L23=4,R23+$M$16,0))))) -> 0 | T23: =SUM(U23:AB23)/8 -> 4.65625 | U23: =AK23-$AC$13 -> 3 | V23: =AL23-$AD$13 -> 5 | W23: =AM23-$AE$13 -> 7 | X23: =$AF$13-AN23 -> 3 | Y23: =AO23-$AG$13 -> 5 | Z23: =AP23-$AH$13 -> 7 | AA23: =AQ23-$AH$13 -> 1 | AB23: =AR23-$AJ$13 -> 6.25 | AK23: 9 | AL23: 8 | AM23: 9 | AN23: 6 | AO23: 9 | AP23: 9 | AQ23: 3 | AR23: 7 | AS23: =(AT23+BB23+BE23+BJ23)/4 -> 3.25 | AT23: =AU23*AV23 -> 0 | AU23: 2 | AV23: =IF(AW23=1,1,IF(AW23=2,0.9,IF(AW23=3,0.8,IF(AW23=4,0.7,IF(AW23=5,0.6,IF(AW23=6,0.5,IF(AW23=7,0.4,IF(AW23=8,0.3,IF(AW23=9,0.2,IF(AW23=10,0.1,IF(AW23=0,0,0))))))))))) -> 0 | AX23: =IF($AZ$13>=BA23,"YA","TIDAK") -> YA | AY23: =IF($AZ$13-BA23>0,$AZ$13-BA23,"0") -> 0.26 | BA23: 0.75 | BB23: =BC23+BD23 -> 10 | BC23: 10 | BE23: =BF23*BH23*BI23 -> 0 | BH23: 1 | BI23: 5 | BJ23: =SUM(BK23:BV23) -> 3 | BK23: 3
B24: 12 | C24: PA-I | D24: A12 | E24: Menyapu Ruang Tamu | G24: H | H24: DI/MI | I24: =IF(R24>0,IF(S24-$P$11>0,"I","R"),"R") -> R | J24: 3 | L24: 0 | N24: =IF(I24="I",0,IF(AX24="YA",O24+T24+AS24,0)) -> 16.322917 | O24: =IF(P24="-",5,IF(10-(P24/60)>10,10+(P24/60*10),10-(P24/60))) -> 8.4166667 | P24: =IF(Q24="-","-",IF((Q24-$P$11)*1440>1,(Q24-$P$11)*1440,-1*(Q24-$P$11)*1440)) -> 95 | Q24: 0.25347222 | S24: =IF(L24=0,0,IF(L24=1,R24+$M$13,IF(L24=2,R24+$M$14,IF(L24=3,R24+$M$15,IF(L24=4,R24+$M$16,0))))) -> 0 | T24: =SUM(U24:AB24)/8 -> 4.65625 | U24: =AK24-$AC$13 -> 3 | V24: =AL24-$AD$13 -> 5 | W24: =AM24-$AE$13 -> 7 | X24: =$AF$13-AN24 -> 3 | Y24: =AO24-$AG$13 -> 5 | Z24: =AP24-$AH$13 -> 7 | AA24: =AQ24-$AH$13 -> 1 | AB24: =AR24-$AJ$13 -> 6.25 | AK24: 9 | AL24: 8 | AM24: 9 | AN24: 6 | AO24: 9 | AP24: 9 | AQ24: 3 | AR24: 7 | AS24: =(AT24+BB24+BE24+BJ24)/4 -> 3.25 | AT24: =AU24*AV24 -> 0 | AU24: 2 | AV24: =IF(AW24=1,1,IF(AW24=2,0.9,IF(AW24=3,0.8,IF(AW24=4,0.7,IF(AW24=5,0.6,IF(AW24=6,0.5,IF(AW24=7,0.4,IF(AW24=8,0.3,IF(AW24=9,0.2,IF(AW24=10,0.1,IF(AW24=0,0,0))))))))))) -> 0 | AX24: =IF($AZ$13>=BA24,"YA","TIDAK") -> YA | AY24: =IF($AZ$13-BA24>0,$AZ$13-BA24,"0") -> 0.26 | BA24: 0.75 | BB24: =BC24+BD24 -> 10 | BC24: 10 | BE24: =BF24*BH24*BI24 -> 0 | BH24: 1 | BI24: 5 | BJ24: =SUM(BK24:BV24) -> 3 | BK24: 3
B25: 13 | C25: PA-I | D25: A13 | E25: Menyapu Teras | G25: H | H25: DI/MI | I25: =IF(R25>0,IF(S25-$P$11>0,"I","R"),"R") -> R | J25: 3 | L25: 0 | N25: =IF(I25="I",0,IF(AX25="YA",O25+T25+AS25,0)) -> 16.422917 | O25: =IF(P25="-",5,IF(10-(P25/60)>10,10+(P25/60*10),10-(P25/60))) -> 8.5166667 | P25: =IF(Q25="-","-",IF((Q25-$P$11)*1440>1,(Q25-$P$11)*1440,-1*(Q25-$P$11)*1440)) -> 89 | Q25: 0.25763889 | S25: =IF(L25=0,0,IF(L25=1,R25+$M$13,IF(L25=2,R25+$M$14,IF(L25=3,R25+$M$15,IF(L25=4,R25+$M$16,0))))) -> 0 | T25: =SUM(U25:AB25)/8 -> 4.65625 | U25: =AK25-$AC$13 -> 3 | V25: =AL25-$AD$13 -> 5 | W25: =AM25-$AE$13 -> 7 | X25: =$AF$13-AN25 -> 3 | Y25: =AO25-$AG$13 -> 5 | Z25: =AP25-$AH$13 -> 7 | AA25: =AQ25-$AH$13 -> 1 | AB25: =AR25-$AJ$13 -> 6.25 | AK25: 9 | AL25: 8 | AM25: 9 | AN25: 6 | AO25: 9 | AP25: 9 | AQ25: 3 | AR25: 7 | AS25: =(AT25+BB25+BE25+BJ25)/4 -> 3.25 | AT25: =AU25*AV25 -> 0 | AU25: 2 | AV25: =IF(AW25=1,1,IF(AW25=2,0.9,IF(AW25=3,0.8,IF(AW25=4,0.7,IF(AW25=5,0.6,IF(AW25=6,0.5,IF(AW25=7,0.4,IF(AW25=8,0.3,IF(AW25=9,0.2,IF(AW25=10,0.1,IF(AW25=0,0,0))))))))))) -> 0 | AX25: =IF($AZ$13>=BA25,"YA","TIDAK") -> YA | AY25: =IF($AZ$13-BA25>0,$AZ$13-BA25,"0") -> 0.26 | BA25: 0.75 | BB25: =BC25+BD25 -> 10 | BC25: 10 | BE25: =BF25*BH25*BI25 -> 0 | BH25: 1 | BI25: 5 | BJ25: =SUM(BK25:BV25) -> 3 | BK25: 3
B26: 14 | C26: PA-I | D26: A80 | E26: Menyapu Halaman Depan | G26: H | H26: DI/MI | I26: =IF(R26>0,IF(S26-$P$11>0,"I","R"),"R") -> R | J26: 3 | L26: 0 | N26: =IF(I26="I",0,IF(AX26="YA",O26+T26+AS26,0)) -> 16.467917 | O26: =IF(P26="-",5,IF(10-(P26/60)>10,10+(P26/60*10),10-(P26/60))) -> 8.5616667 | P26: =IF(Q26="-","-",IF((Q26-$P$11)*1440>1,(Q26-$P$11)*1440,-1*(Q26-$P$11)*1440)) -> 86.3 | Q26: 0.25951389 | S26: =IF(L26=0,0,IF(L26=1,R26+$M$13,IF(L26=2,R26+$M$14,IF(L26=3,R26+$M$15,IF(L26=4,R26+$M$16,0))))) -> 0 | T26: =SUM(U26:AB26)/8 -> 4.65625 | U26: =AK26-$AC$13 -> 3 | V26: =AL26-$AD$13 -> 5 | W26: =AM26-$AE$13 -> 7 | X26: =$AF$13-AN26 -> 3 | Y26: =AO26-$AG$13 -> 5 | Z26: =AP26-$AH$13 -> 7 | AA26: =AQ26-$AH$13 -> 1 | AB26: =AR26-$AJ$13 -> 6.25 | AK26: 9 | AL26: 8 | AM26: 9 | AN26: 6 | AO26: 9 | AP26: 9 | AQ26: 3 | AR26: 7 | AS26: =(AT26+BB26+BE26+BJ26)/4 -> 3.25 | AT26: =AU26*AV26 -> 0 | AU26: 2 | AV26: =IF(AW26=1,1,IF(AW26=2,0.9,IF(AW26=3,0.8,IF(AW26=4,0.7,IF(AW26=5,0.6,IF(AW26=6,0.5,IF(AW26=7,0.4,IF(AW26=8,0.3,IF(AW26=9,0.2,IF(AW26=10,0.1,IF(AW26=0,0,0))))))))))) -> 0 | AX26: =IF($AZ$13>=BA26,"YA","TIDAK") -> YA | AY26: =IF($AZ$13-BA26>0,$AZ$13-BA26,"0") -> 0.26 | BA26: 0.75 | BB26: =BC26+BD26 -> 10 | BC26: 10 | BE26: =BF26*BH26*BI26 -> 0 | BH26: 1 | BI26: 5 | BJ26: =SUM(BK26:BV26) -> 3 | BK26: 3
B27: 14 | C27: PR;A5 | D27: A14 | E27: Mengepel Ruang Tidur Utama 1 | G27: H | H27: MI | I27: =IF(R27>0,IF(S27-$P$11>0,"I","R"),"R") -> R | J27: 2 | L27: 0 | N27: =IF(I27="I",0,IF(AX27="YA",O27+T27+AS27,0)) -> 17.134583 | O27: =IF(P27="-",5,IF(10-(P27/60)>10,10+(P27/60*10),10-(P27/60))) -> 8.7283333 | P27: =IF(Q27="-","-",IF((Q27-$P$11)*1440>1,(Q27-$P$11)*1440,-1*(Q27-$P$11)*1440)) -> 76.3 | Q27: 0.26645833 | S27: =IF(L27=0,0,IF(L27=1,R27+$M$13,IF(L27=2,R27+$M$14,IF(L27=3,R27+$M$15,IF(L27=4,R27+$M$16,0))))) -> 0 | T27: =SUM(U27:AB27)/8 -> 4.65625 | U27: =AK27-$AC$13 -> 3 | V27: =AL27-$AD$13 -> 5 | W27: =AM27-$AE$13 -> 7 | X27: =$AF$13-AN27 -> 3 | Y27: =AO27-$AG$13 -> 5 | Z27: =AP27-$AH$13 -> 7 | AA27: =AQ27-$AH$13 -> 1 | AB27: =AR27-$AJ$13 -> 6.25 | AK27: 9 | AL27: 8 | AM27: 9 | AN27: 6 | AO27: 9 | AP27: 9 | AQ27: 3 | AR27: 7 | AS27: =(AT27+BB27+BE27+BJ27)/4 -> 3.75 | AT27: =AU27*AV27 -> 0 | AU27: 4 | AV27: =IF(AW27=1,1,IF(AW27=2,0.9,IF(AW27=3,0.8,IF(AW27=4,0.7,IF(AW27=5,0.6,IF(AW27=6,0.5,IF(AW27=7,0.4,IF(AW27=8,0.3,IF(AW27=9,0.2,IF(AW27=10,0.1,IF(AW27=0,0,0))))))))))) -> 0 | AX27: =IF($AZ$13>=BA27,"YA","TIDAK") -> YA | AY27: =IF($AZ$13-BA27>0,$AZ$13-BA27,"0") -> 0.26 | BA27: 0.75 | BB27: =BC27+BD27 -> 10 | BC27: 10 | BE27: =BF27*BH27*BI27 -> 0 | BH27: 1 | BI27: 5 | BJ27: =SUM(BK27:BV27) -> 5 | BK27: 5
B28: 15 | C28: PR;A6 | D28: A15 | E28: Mengepel Ruang Tidur Utama 2 | G28: H | H28: MI | I28: =IF(R28>0,IF(S28-$P$11>0,"I","R"),"R") -> R | J28: 2 | L28: 0 | N28: =IF(I28="I",0,IF(AX28="YA",O28+T28+AS28,0)) -> 17.20125 | O28: =IF(P28="-",5,IF(10-(P28/60)>10,10+(P28/60*10),10-(P28/60))) -> 8.795 | P28: =IF(Q28="-","-",IF((Q28-$P$11)*1440>1,(Q28-$P$11)*1440,-1*(Q28-$P$11)*1440)) -> 72.3 | Q28: 0.26923611 | S28: =IF(L28=0,0,IF(L28=1,R28+$M$13,IF(L28=2,R28+$M$14,IF(L28=3,R28+$M$15,IF(L28=4,R28+$M$16,0))))) -> 0 | T28: =SUM(U28:AB28)/8 -> 4.65625 | U28: =AK28-$AC$13 -> 3 | V28: =AL28-$AD$13 -> 5 | W28: =AM28-$AE$13 -> 7 | X28: =$AF$13-AN28 -> 3 | Y28: =AO28-$AG$13 -> 5 | Z28: =AP28-$AH$13 -> 7 | AA28: =AQ28-$AH$13 -> 1 | AB28: =AR28-$AJ$13 -> 6.25 | AK28: 9 | AL28: 8 | AM28: 9 | AN28: 6 | AO28: 9 | AP28: 9 | AQ28: 3 | AR28: 7 | AS28: =(AT28+BB28+BE28+BJ28)/4 -> 3.75 | AT28: =AU28*AV28 -> 0 | AU28: 4 | AV28: =IF(AW28=1,1,IF(AW28=2,0.9,IF(AW28=3,0.8,IF(AW28=4,0.7,IF(AW28=5,0.6,IF(AW28=6,0.5,IF(AW28=7,0.4,IF(AW28=8,0.3,IF(AW28=9,0.2,IF(AW28=10,0.1,IF(AW28=0,0,0))))))))))) -> 0 | AX28: =IF($AZ$13>=BA28,"YA","TIDAK") -> YA | AY28: =IF($AZ$13-BA28>0,$AZ$13-BA28,"0") -> 0.26 | BA28: 0.75 | BB28: =BC28+BD28 -> 10 | BC28: 10 | BE28: =BF28*BH28*BI28 -> 0 | BH28: 1 | BI28: 5 | BJ28: =SUM(BK28:BV28) -> 5 | BK28: 5
... B32: 19 | C32: PR;A11 | D32: A19 | E32: Mengepel Ruang Keluarga | G32: H | H32: MI | I32: =IF(R32>0,IF(S32-$P$11>0,"I","R"),"R") -> R | J32: 2 | L32: 0 | N32: =IF(I32="I",0,IF(AX32="YA",O32+T32+AS32,0)) -> 17.00125 | O32: =IF(P32="-",5,IF(10-(P32/60)>10,10+(P32/60*10),10-(P32/60))) -> 9.095 | P32: =IF(Q32="-","-",IF((Q32-$P$11)*1440>1,(Q32-$P$11)*1440,-1*(Q32-$P$11)*1440)) -> 54.3 | Q32: 0.28173611 | S32: =IF(L32=0,0,IF(L32=1,R32+$M$13,IF(L32=2,R32+$M$14,IF(L32=3,R32+$M$15,IF(L32=4,R32+$M$16,0))))) -> 0 | T32: =SUM(U32:AB32)/8 -> 4.65625 | U32: =AK32-$AC$13 -> 3 | V32: =AL32-$AD$13 -> 5 | W32: =AM32-$AE$13 -> 7 | X32: =$AF$13-AN32 -> 3 | Y32: =AO32-$AG$13 -> 5 | Z32: =AP32-$AH$13 -> 7 | AA32: =AQ32-$AH$13 -> 1 | AB32: =AR32-$AJ$13 -> 6.25 | AK32: 9 | AL32: 8 | AM32: 9 | AN32: 6 | AO32: 9 | AP32: 9 | AQ32: 3 | AR32: 7 | AS32: =(AT32+BB32+BE32+BJ32)/4 -> 3.25 | AT32: =AU32*AV32 -> 0 | AU32: 4 | AV32: =IF(AW32=1,1,IF(AW32=2,0.9,IF(AW32=3,0.8,IF(AW32=4,0.7,IF(AW32=5,0.6,IF(AW32=6,0.5,IF(AW32=7,0.4,IF(AW32=8,0.3,IF(AW32=9,0.2,IF(AW32=10,0.1,IF(AW32=0,0,0))))))))))) -> 0 | AX32: =IF($AZ$13>=BA32,"YA","TIDAK") -> YA | AY32: =IF($AZ$13-BA32>0,$AZ$13-BA32,"0") -> 0.26 | BA32: 0.75 | BB32: =BC32+BD32 -> 8 | BC32: 8 | BE32: =BF32*BH32*BI32 -> 0 | BH32: 1 | BI32: 5 | BJ32: =SUM(BK32:BV32) -> 5 | BK32: 5
B33: 20 | C33: PR;A12 | D33: A20 | E33: Mengepel Ruang Tamu | I33: =IF(R33>0,IF(S33-$P$11>0,"I","R"),"R") -> R | N33: =IF(I33="I",0,IF(AX33="YA",O33+T33+AS33,0)) -> 13.884583 | O33: =IF(P33="-",5,IF(10-(P33/60)>10,10+(P33/60*10),10-(P33/60))) -> 9.2283333 | P33: =IF(Q33="-","-",IF((Q33-$P$11)*1440>1,(Q33-$P$11)*1440,-1*(Q33-$P$11)*1440)) -> 46.3 | Q33: 0.28729167 | S33: =IF(L33=0,0,IF(L33=1,R33+$M$13,IF(L33=2,R33+$M$14,IF(L33=3,R33+$M$15,IF(L33=4,R33+$M$16,0))))) -> 0 | T33: =SUM(U33:AB33)/8 -> 4.65625 | U33: =AK33-$AC$13 -> 3 | V33: =AL33-$AD$13 -> 5 | W33: =AM33-$AE$13 -> 7 | X33: =$AF$13-AN33 -> 3 | Y33: =AO33-$AG$13 -> 5 | Z33: =AP33-$AH$13 -> 7 | AA33: =AQ33-$AH$13 -> 1 | AB33: =AR33-$AJ$13 -> 6.25 | AK33: 9 | AL33: 8 | AM33: 9 | AN33: 6 | AO33: 9 | AP33: 9 | AQ33: 3 | AR33: 7 | AS33: =(AT33+BB33+BE33+BJ33)/4 -> 0 | AT33: =AU33*AV33 -> 0 | AV33: =IF(AW33=1,1,IF(AW33=2,0.9,IF(AW33=3,0.8,IF(AW33=4,0.7,IF(AW33=5,0.6,IF(AW33=6,0.5,IF(AW33=7,0.4,IF(AW33=8,0.3,IF(AW33=9,0.2,IF(AW33=10,0.1,IF(AW33=0,0,0))))))))))) -> 0 | AX33: =IF($AZ$13>=BA33,"YA","TIDAK") -> YA | AY33: =IF($AZ$13-BA33>0,$AZ$13-BA33,"0") -> 0.26 | BA33: 0.75 | BB33: =BC33+BD33 -> 0 | BE33: =BF33*BH33*BI33 -> 0 | BJ33: =SUM(BK33:BV33) -> 0
B34: 21 | C34: PR;A13 | D34: A21 | E34: Mengepel Teras | G34: H | H34: MI | I34: =IF(R34>0,IF(S34-$P$11>0,"I","R"),"R") -> R | J34: 2 | L34: 0 | N34: =IF(I34="I",0,IF(AX34="YA",O34+T34+AS34,0)) -> 17.234583 | O34: =IF(P34="-",5,IF(10-(P34/60)>10,10+(P34/60*10),10-(P34/60))) -> 9.3283333 | P34: =IF(Q34="-","-",IF((Q34-$P$11)*1440>1,(Q34-$P$11)*1440,-1*(Q34-$P$11)*1440)) -> 40.3 | Q34: 0.29145833 | S34: =IF(L34=0,0,IF(L34=1,R34+$M$13,IF(L34=2,R34+$M$14,IF(L34=3,R34+$M$15,IF(L34=4,R34+$M$16,0))))) -> 0 | T34: =SUM(U34:AB34)/8 -> 4.65625 | U34: =AK34-$AC$13 -> 3 | V34: =AL34-$AD$13 -> 5 | W34: =AM34-$AE$13 -> 7 | X34: =$AF$13-AN34 -> 3 | Y34: =AO34-$AG$13 -> 5 | Z34: =AP34-$AH$13 -> 7 | AA34: =AQ34-$AH$13 -> 1 | AB34: =AR34-$AJ$13 -> 6.25 | AK34: 9 | AL34: 8 | AM34: 9 | AN34: 6 | AO34: 9 | AP34: 9 | AQ34: 3 | AR34: 7 | AS34: =(AT34+BB34+BE34+BJ34)/4 -> 3.25 | AT34: =AU34*AV34 -> 0 | AU34: 4 | AV34: =IF(AW34=1,1,IF(AW34=2,0.9,IF(AW34=3,0.8,IF(AW34=4,0.7,IF(AW34=5,0.6,IF(AW34=6,0.5,IF(AW34=7,0.4,IF(AW34=8,0.3,IF(AW34=9,0.2,IF(AW34=10,0.1,IF(AW34=0,0,0))))))))))) -> 0 | AX34: =IF($AZ$13>=BA34,"YA","TIDAK") -> YA | AY34: =IF($AZ$13-BA34>0,$AZ$13-BA34,"0") -> 0.26 | BA34: 0.75 | BB34: =BC34+BD34 -> 8 | BC34: 8 | BE34: =BF34*BH34*BI34 -> 0 | BH34: 1 | BI34: 5 | BJ34: =SUM(BK34:BV34) -> 5 | BK34: 5
B35: 22 | C35: PA-I;A | D35: A22 | E35: Memasak makan pagi dengan rice cooker | G35: H | H35: DI/MI | I35: =IF(R35>0,IF(S35-$P$11>0,"I","R"),"R") -> R | J35: 3 | L35: 0 | N35: =IF(I35="I",0,IF(AX35="YA",O35+T35+AS35,0)) -> 14.864583 | O35: =IF(P35="-",5,IF(10-(P35/60)>10,10+(P35/60*10),10-(P35/60))) -> 8.3333333 | P35: =IF(Q35="-","-",IF((Q35-$P$11)*1440>1,(Q35-$P$11)*1440,-1*(Q35-$P$11)*1440)) -> 100 | Q35: 0.25 | S35: =IF(L35=0,0,IF(L35=1,R35+$M$13,IF(L35=2,R35+$M$14,IF(L35=3,R35+$M$15,IF(L35=4,R35+$M$16,0))))) -> 0 | T35: =SUM(U35:AB35)/8 -> 2.53125 | U35: =AK35-$AC$13 -> 2 | V35: =AL35-$AD$13 -> 5 | W35: =AM35-$AE$13 -> 6 | X35: =$AF$13-AN35 -> 3 | Y35: =AO35-$AG$13 -> 1 | Z35: =AP35-$AH$13 -> 2 | AA35: =AQ35-$AH$13 -> 0 | AB35: =AR35-$AJ$13 -> 1.25 | AK35: 8 | AL35: 8 | AM35: 8 | AN35: 6 | AO35: 5 | AP35: 4 | AQ35: 2 | AR35: 2 | AS35: =(AT35+BB35+BE35+BJ35)/4 -> 4 | AT35: =AU35*AV35 -> 0 | AU35: 5 | AV35: =IF(AW35=1,1,IF(AW35=2,0.9,IF(AW35=3,0.8,IF(AW35=4,0.7,IF(AW35=5,0.6,IF(AW35=6,0.5,IF(AW35=7,0.4,IF(AW35=8,0.3,IF(AW35=9,0.2,IF(AW35=10,0.1,IF(AW35=0,0,0))))))))))) -> 0 | AX35: =IF($AZ$13>=BA35,"YA","TIDAK") -> YA | AY35: =IF($AZ$13-BA35>0,$AZ$13-BA35,"0") -> 0.01 | BA35: 1 | BB35: =BC35+BD35 -> 8 | BC35: 8 | BE35: =BF35*BH35*BI35 -> 0 | BH35: 1 | BI35: 4 | BJ35: =SUM(BK35:BV35) -> 8 | BK35: 8
B36: 23 | C36: PA-O;E;A24 | D36: A23 | E36: Pergi membeli makan pagi di luar rumah | G36: M;4 | H36: DI | I36: =IF(R36>0,IF(S36-$P$11>0,"I","R"),"R") -> R | J36: -1 | L36: 3 | N36: =IF(I36="I",0,IF(AX36="YA",O36+T36+AS36,0)) -> 17.364583 | O36: =IF(P36="-",5,IF(10-(P36/60)>10,10+(P36/60*10),10-(P36/60))) -> 9.0833333 | P36: =IF(Q36="-","-",IF((Q36-$P$11)*1440>1,(Q36-$P$11)*1440,-1*(Q36-$P$11)*1440)) -> 55 | Q36: 0.28125 | S36: =IF(L36=0,0,IF(L36=1,R36+$M$13,IF(L36=2,R36+$M$14,IF(L36=3,R36+$M$15,IF(L36=4,R36+$M$16,0))))) -> 0.99930556 | T36: =SUM(U36:AB36)/8 -> 5.03125 | U36: =AK36-$AC$13 -> 3 | V36: =AL36-$AD$13 -> 5 | W36: =AM36-$AE$13 -> 7 | X36: =$AF$13-AN36 -> 6 | Y36: =AO36-$AG$13 -> 5 | Z36: =AP36-$AH$13 -> 7 | AA36: =AQ36-$AH$13 -> 1 | AB36: =AR36-$AJ$13 -> 6.25 | AK36: 9 | AL36: 8 | AM36: 9 | AN36: 3 | AO36: 9 | AP36: 9 | AQ36: 3 | AR36: 7 | AS36: =(AT36+BB36+BE36+BJ36)/4 -> 3.25 | AT36: =AU36*AV36 -> 0 | AU36: 8 | AV36: =IF(AW36=1,1,IF(AW36=2,0.9,IF(AW36=3,0.8,IF(AW36=4,0.7,IF(AW36=5,0.6,IF(AW36=6,0.5,IF(AW36=7,0.4,IF(AW36=8,0.3,IF(AW36=9,0.2,IF(AW36=10,0.1,IF(AW36=0,0,0))))))))))) -> 0 | AX36: =IF($AZ$13>=BA36,"YA","TIDAK") -> YA | AY36: =IF($AZ$13-BA36>0,$AZ$13-BA36,"0") -> 0.51 | BA36: 0.5 | BB36: =BC36+BD36 -> 8 | BC36: 8 | BE36: =BF36*BH36*BI36 -> 0 | BJ36: =SUM(BK36:BV36) -> 5 | BK36: 5
B37: 24 | C37: PA-I;E;A23 | D37: A24 | E37: Memasak makan pagi dengan kompor gas | G37: M;3 | H37: DI/MI | I37: =IF(R37>0,IF(S37-$P$11>0,"I","R"),"R") -> R | J37: -1 | L37: 3 | N37: =IF(I37="I",0,IF(AX37="YA",O37+T37+AS37,0)) -> 14.864583 | O37: =IF(P37="-",5,IF(10-(P37/60)>10,10+(P37/60*10),10-(P37/60))) -> 9.0833333 | P37: =IF(Q37="-","-",IF((Q37-$P$11)*1440>1,(Q37-$P$11)*1440,-1*(Q37-$P$11)*1440)) -> 55 | Q37: 0.28125 | S37: =IF(L37=0,0,IF(L37=1,R37+$M$13,IF(L37=2,R37+$M$14,IF(L37=3,R37+$M$15,IF(L37=4,R37+$M$16,0))))) -> 0.99930556 | T37: =SUM(U37:AB37)/8 -> 2.53125 | U37: =AK37-$AC$13 -> 2 | V37: =AL37-$AD$13 -> 5 | W37: =AM37-$AE$13 -> 6 | X37: =$AF$13-AN37 -> 3 | Y37: =AO37-$AG$13 -> 1 | Z37: =AP37-$AH$13 -> 2 | AA37: =AQ37-$AH$13 -> 0 | AB37: =AR37-$AJ$13 -> 1.25 | AK37: 8 | AL37: 8 | AM37: 8 | AN37: 6 | AO37: 5 | AP37: 4 | AQ37: 2 | AR37: 2 | AS37: =(AT37+BB37+BE37+BJ37)/4 -> 3.25 | AT37: =AU37*AV37 -> 0 | AU37: 3 | AV37: =IF(AW37=1,1,IF(AW37=2,0.9,IF(AW37=3,0.8,IF(AW37=4,0.7,IF(AW37=5,0.6,IF(AW37=6,0.5,IF(AW37=7,0.4,IF(AW37=8,0.3,IF(AW37=9,0.2,IF(AW37=10,0.1,IF(AW37=0,0,0))))))))))) -> 0 | AX37: =IF($AZ$13>=BA37,"YA","TIDAK") -> YA | AY37: =IF($AZ$13-BA37>0,$AZ$13-BA37,"0") -> 0.26 | BA37: 0.75 | BB37: =BC37+BD37 -> 6 | BC37: 6 | BE37: =BF37*BH37*BI37 -> 0 | BJ37: =SUM(BK37:BV37) -> 7 | BK37: 7
B38: 25 | C38: PA-I | D38: A25 | E38: Membangunkan anak di pagi hari | G38: H | H38: MI | I38: =IF(R38>0,IF(S38-$P$11>0,"I","R"),"R") -> R | J38: 2 | L38: 0 | N38: =IF(I38="I",0,IF(AX38="YA",O38+T38+AS38,0)) -> 15.364583 | O38: =IF(P38="-",5,IF(10-(P38/60)>10,10+(P38/60*10),10-(P38/60))) -> 9.3333333 | P38: =IF(Q38="-","-",IF((Q38-$P$11)*1440>1,(Q38-$P$11)*1440,-1*(Q38-$P$11)*1440)) -> 40 | Q38: 0.29166667 | S38: =IF(L38=0,0,IF(L38=1,R38+$M$13,IF(L38=2,R38+$M$14,IF(L38=3,R38+$M$15,IF(L38=4,R38+$M$16,0))))) -> 0 | T38: =SUM(U38:AB38)/8 -> 2.53125 | U38: =AK38-$AC$13 -> 2 | V38: =AL38-$AD$13 -> 5 | W38: =AM38-$AE$13 -> 6 | X38: =$AF$13-AN38 -> 3 | Y38: =AO38-$AG$13 -> 1 | Z38: =AP38-$AH$13 -> 2 | AA38: =AQ38-$AH$13 -> 0 | AB38: =AR38-$AJ$13 -> 1.25 | AK38: 8 | AL38: 8 | AM38: 8 | AN38: 6 | AO38: 5 | AP38: 4 | AQ38: 2 | AR38: 2 | AS38: =(AT38+BB38+BE38+BJ38)/4 -> 3.5 | AT38: =AU38*AV38 -> 0 | AU38: 4 | AV38: =IF(AW38=1,1,IF(AW38=2,0.9,IF(AW38=3,0.8,IF(AW38=4,0.7,IF(AW38=5,0.6,IF(AW38=6,0.5,IF(AW38=7,0.4,IF(AW38=8,0.3,IF(AW38=9,0.2,IF(AW38=10,0.1,IF(AW38=0,0,0))))))))))) -> 0 | AX38: =IF($AZ$13>=BA38,"YA","TIDAK") -> YA | AY38: =IF($AZ$13-BA38>0,$AZ$13-BA38,"0") -> 0.76 | BA38: 0.25 | BB38: =BC38+BD38 -> 8 | BC38: 8 | BE38: =BF38*BH38*BI38 -> 0 | BJ38: =SUM(BK38:BV38) -> 6 | BK38: 6
B39: 26 | C39: PR-D;A25 | D39: A26 | E39: Membuat susu anak di pagi hari | G39: H | H39: MI | I39: =IF(R39>0,IF(S39-$P$11>0,"I","R"),"R") -> R | J39: 3 | L39: 0 | N39: =IF(I39="I",0,IF(AX39="YA",O39+T39+AS39,0)) -> 16.864583 | O39: =IF(P39="-",5,IF(10-(P39/60)>10,10+(P39/60*10),10-(P39/60))) -> 9.0833333 | P39: =IF(Q39="-","-",IF((Q39-$P$11)*1440>1,(Q39-$P$11)*1440,-1*(Q39-$P$11)*1440)) -> 55 | Q39: 0.28125 | S39: =IF(L39=0,0,IF(L39=1,R39+$M$13,IF(L39=2,R39+$M$14,IF(L39=3,R39+$M$15,IF(L39=4,R39+$M$16,0))))) -> 0 | T39: =SUM(U39:AB39)/8 -> 4.78125 | U39: =AK39-$AC$13 -> 3 | V39: =AL39-$AD$13 -> 5 | W39: =AM39-$AE$13 -> 7 | X39: =$AF$13-AN39 -> 4 | Y39: =AO39-$AG$13 -> 5 | Z39: =AP39-$AH$13 -> 7 | AA39: =AQ39-$AH$13 -> 1 | AB39: =AR39-$AJ$13 -> 6.25 | AK39: 9 | AL39: 8 | AM39: 9 | AN39: 5 | AO39: 9 | AP39: 9 | AQ39: 3 | AR39: 7 | AS39: =(AT39+BB39+BE39+BJ39)/4 -> 3 | AT39: =AU39*AV39 -> 0 | AU39: 3 | AV39: =IF(AW39=1,1,IF(AW39=2,0.9,IF(AW39=3,0.8,IF(AW39=4,0.7,IF(AW39=5,0.6,IF(AW39=6,0.5,IF(AW39=7,0.4,IF(AW39=8,0.3,IF(AW39=9,0.2,IF(AW39=10,0.1,IF(AW39=0,0,0))))))))))) -> 0 | AX39: =IF($AZ$13>=BA39,"YA","TIDAK") -> YA | AY39: =IF($AZ$13-BA39>0,$AZ$13-BA39,"0") -> 0.76 | BA39: 0.25 | BB39: =BC39+BD39 -> 6 | BC39: 6 | BE39: =BF39*BH39*BI39 -> 0 | BJ39: =SUM(BK39:BV39) -> 6 | BK39: 6
B40: 27 | C40: PA-I | D40: A27 | E40: Membuang sampah | G40: H | H40: MI | I40: =IF(R40>0,IF(S40-$P$11>0,"I","R"),"R") -> I | J40: 1 | L40: 2 | N40: =IF(I40="I",0,IF(AX40="YA",O40+T40+AS40,0)) -> 0 | O40: =IF(P40="-",5,IF(10-(P40/60)>10,10+(P40/60*10),10-(P40/60))) -> 9.3333333 | P40: =IF(Q40="-","-",IF((Q40-$P$11)*1440>1,(Q40-$P$11)*1440,-1*(Q40-$P$11)*1440)) -> 40 | Q40: 0.29166667 | R40: 0.29166667 | S40: =IF(L40=0,0,IF(L40=1,R40+$M$13,IF(L40=2,R40+$M$14,IF(L40=3,R40+$M$15,IF(L40=4,R40+$M$16,0))))) -> 0.79166667 | T40: =SUM(U40:AB40)/8 -> 4.65625 | U40: =AK40-$AC$13 -> 3 | V40: =AL40-$AD$13 -> 5 | W40: =AM40-$AE$13 -> 7 | X40: =$AF$13-AN40 -> 3 | Y40: =AO40-$AG$13 -> 5 | Z40: =AP40-$AH$13 -> 7 | AA40: =AQ40-$AH$13 -> 1 | AB40: =AR40-$AJ$13 -> 6.25 | AK40: 9 | AL40: 8 | AM40: 9 | AN40: 6 | AO40: 9 | AP40: 9 | AQ40: 3 | AR40: 7 | AS40: =(AT40+BB40+BE40+BJ40)/4 -> 3.25 | AT40: =AU40*AV40 -> 0 | AU40: 5 | AV40: =IF(AW40=1,1,IF(AW40=2,0.9,IF(AW40=3,0.8,IF(AW40=4,0.7,IF(AW40=5,0.6,IF(AW40=6,0.5,IF(AW40=7,0.4,IF(AW40=8,0.3,IF(AW40=9,0.2,IF(AW40=10,0.1,IF(AW40=0,0,0))))))))))) -> 0 | AX40: =IF($AZ$13>=BA40,"YA","TIDAK") -> YA | AY40: =IF($AZ$13-BA40>0,$AZ$13-BA40,"0") -> 0.76 | BA40: 0.25 | BB40: =BC40+BD40 -> 8 | BC40: 8 | BE40: =BF40*BH40*BI40 -> 0 | BH40: 1 | BI40: 5 | BJ40: =SUM(BK40:BV40) -> 5 | BK40: 5
B41: 28 | C41: PA-I | D41: A28 | E41: Membakar sampah | G41: M;1 | H41: MI | I41: =IF(R41>0,IF(S41-$P$11>0,"I","R"),"R") -> R | J41: -1 | L41: 3 | N41: =IF(I41="I",0,IF(AX41="YA",O41+T41+AS41,0)) -> 16.489583 | O41: =IF(P41="-",5,IF(10-(P41/60)>10,10+(P41/60*10),10-(P41/60))) -> 9.8333333 | P41: =IF(Q41="-","-",IF((Q41-$P$11)*1440>1,(Q41-$P$11)*1440,-1*(Q41-$P$11)*1440)) -> 10 | Q41: 0.3125 | S41: =IF(L41=0,0,IF(L41=1,R41+$M$13,IF(L41=2,R41+$M$14,IF(L41=3,R41+$M$15,IF(L41=4,R41+$M$16,0))))) -> 0.99930556 | T41: =SUM(U41:AB41)/8 -> 4.15625 | U41: =AK41-$AC$13 -> 3 | V41: =AL41-$AD$13 -> 5 | W41: =AM41-$AE$13 -> 7 | X41: =$AF$13-AN41 -> 3 | Y41: =AO41-$AG$13 -> 5 | Z41: =AP41-$AH$13 -> 7 | AA41: =AQ41-$AH$13 -> 1 | AB41: =AR41-$AJ$13 -> 2.25 | AK41: 9 | AL41: 8 | AM41: 9 | AN41: 6 | AO41: 9 | AP41: 9 | AQ41: 3 | AR41: 3 | AS41: =(AT41+BB41+BE41+BJ41)/4 -> 2.5 | AT41: =AU41*AV41 -> 0 | AU41: 2 | AV41: =IF(AW41=1,1,IF(AW41=2,0.9,IF(AW41=3,0.8,IF(AW41=4,0.7,IF(AW41=5,0.6,IF(AW41=6,0.5,IF(AW41=7,0.4,IF(AW41=8,0.3,IF(AW41=9,0.2,IF(AW41=10,0.1,IF(AW41=0,0,0))))))))))) -> 0 | AX41: =IF($AZ$13>=BA41,"YA","TIDAK") -> YA | AY41: =IF($AZ$13-BA41>0,$AZ$13-BA41,"0") -> 0.01 | BA41: 1 | BB41: =BC41+BD41 -> 5 | BC41: 5 | BE41: =BF41*BH41*BI41 -> 0 | BH41: 1 | BI41: 5 | BJ41: =SUM(BK41:BV41) -> 5 | BK41: 5
B42: 29 | C42: PA-I;A | D42: A29 | E42: Memasak air untuk mandi di pagi hari | G42: H | H42: DI/MI | I42: =IF(R42>0,IF(S42-$P$11>0,"I","R"),"R") -> R | J42: 3 | L42: 0 | N42: =IF(I42="I",0,IF(AX42="YA",O42+T42+AS42,0)) -> 17.864583 | O42: =IF(P42="-",5,IF(10-(P42/60)>10,10+(P42/60*10),10-(P42/60))) -> 9.8333333 | P42: =IF(Q42="-","-",IF((Q42-$P$11)*1440>1,(Q42-$P$11)*1440,-1*(Q42-$P$11)*1440)) -> 10 | Q42: 0.3125 | S42: =IF(L42=0,0,IF(L42=1,R42+$M$13,IF(L42=2,R42+$M$14,IF(L42=3,R42+$M$15,IF(L42=4,R42+$M$16,0))))) -> 0 | T42: =SUM(U42:AB42)/8 -> 4.53125 | U42: =AK42-$AC$13 -> 3 | V42: =AL42-$AD$13 -> 5 | W42: =AM42-$AE$13 -> 7 | X42: =$AF$13-AN42 -> 2 | Y42: =AO42-$AG$13 -> 5 | Z42: =AP42-$AH$13 -> 7 | AA42: =AQ42-$AH$13 -> 3 | AB42: =AR42-$AJ$13 -> 4.25 | AK42: 9 | AL42: 8 | AM42: 9 | AN42: 7 | AO42: 9 | AP42: 9 | AQ42: 5 | AR42: 5 | AS42: =(AT42+BB42+BE42+BJ42)/4 -> 3.5 | AT42: =AU42*AV42 -> 0 | AU42: 3 | AV42: =IF(AW42=1,1,IF(AW42=2,0.9,IF(AW42=3,0.8,IF(AW42=4,0.7,IF(AW42=5,0.6,IF(AW42=6,0.5,IF(AW42=7,0.4,IF(AW42=8,0.3,IF(AW42=9,0.2,IF(AW42=10,0.1,IF(AW42=0,0,0))))))))))) -> 0 | AX42: =IF($AZ$13>=BA42,"YA","TIDAK") -> YA | AY42: =IF($AZ$13-BA42>0,$AZ$13-BA42,"0") -> 0.76 | BA42: 0.25 | BB42: =BC42+BD42 -> 8 | BC42: 8 | BE42: =BF42*BH42*BI42 -> 0 | BH42: 1 | BI42: 8 | BJ42: =SUM(BK42:BV42) -> 6 | BK42: 6
B43: 30 | C43: PR-D;A29 | D43: A30 | E43: Memandikan anak pagi hari | G43: H | H43: MI | I43: =IF(R43>0,IF(S43-$P$11>0,"I","R"),"R") -> R | J43: 3 | L43: 0 | N43: =IF(I43="I",0,IF(AX43="YA",O43+T43+AS43,0)) -> 18.15625 | O43: =IF(P43="-",5,IF(10-(P43/60)>10,10+(P43/60*10),10-(P43/60))) -> 10 | P43: =IF(Q43="-","-",IF((Q43-$P$11)*1440>1,(Q43-$P$11)*1440,-1*(Q43-$P$11)*1440)) -> 7.9936058e-14 | Q43: 0.31944444 | S43: =IF(L43=0,0,IF(L43=1,R43+$M$13,IF(L43=2,R43+$M$14,IF(L43=3,R43+$M$15,IF(L43=4,R43+$M$16,0))))) -> 0 | T43: =SUM(U43:AB43)/8 -> 4.90625 | U43: =AK43-$AC$13 -> 3 | V43: =AL43-$AD$13 -> 5 | W43: =AM43-$AE$13 -> 7 | X43: =$AF$13-AN43 -> 5 | Y43: =AO43-$AG$13 -> 5 | Z43: =AP43-$AH$13 -> 7 | AA43: =AQ43-$AH$13 -> 1 | AB43: =AR43-$AJ$13 -> 6.25 | AK43: 9 | AL43: 8 | AM43: 9 | AN43: 4 | AO43: 9 | AP43: 9 | AQ43: 3 | AR43: 7 | AS43: =(AT43+BB43+BE43+BJ43)/4 -> 3.25 | AT43: =AU43*AV43 -> 0 | AU43: 5 | AV43: =IF(AW43=1,1,IF(AW43=2,0.9,IF(AW43=3,0.8,IF(AW43=4,0.7,IF(AW43=5,0.6,IF(AW43=6,0.5,IF(AW43=7,0.4,IF(AW43=8,0.3,IF(AW43=9,0.2,IF(AW43=10,0.1,IF(AW43=0,0,0))))))))))) -> 0 | AX43: =IF($AZ$13>=BA43,"YA","TIDAK") -> YA | AY43: =IF($AZ$13-BA43>0,$AZ$13-BA43,"0") -> 0.76 | BA43: 0.25 | BB43: =BC43+BD43 -> 8 | BC43: 8 | BE43: =BF43*BH43*BI43 -> 0 | BJ43: =SUM(BK43:BV43) -> 5 | BK43: 5
B44: 31 | C44: PA-I | D44: A31 | E44: Membuat minuman herbal | G44: H | H44: MI | I44: =IF(R44>0,IF(S44-$P$11>0,"I","R"),"R") -> R | J44: 3 | L44: 0 | N44: =IF(I44="I",0,IF(AX44="YA",O44+T44+AS44,0)) -> 18.197917 | O44: =IF(P44="-",5,IF(10-(P44/60)>10,10+(P44/60*10),10-(P44/60))) -> 9.9166667 | P44: =IF(Q44="-","-",IF((Q44-$P$11)*1440>1,(Q44-$P$11)*1440,-1*(Q44-$P$11)*1440)) -> 5 | Q44: 0.32291667 | S44: =IF(L44=0,0,IF(L44=1,R44+$M$13,IF(L44=2,R44+$M$14,IF(L44=3,R44+$M$15,IF(L44=4,R44+$M$16,0))))) -> 0 | T44: =SUM(U44:AB44)/8 -> 4.78125 | U44: =AK44-$AC$13 -> 3 | V44: =AL44-$AD$13 -> 5 | W44: =AM44-$AE$13 -> 7 | X44: =$AF$13-AN44 -> 4 | Y44: =AO44-$AG$13 -> 5 | Z44: =AP44-$AH$13 -> 7 | AA44: =AQ44-$AH$13 -> 1 | AB44: =AR44-$AJ$13 -> 6.25 | AK44: 9 | AL44: 8 | AM44: 9 | AN44: 5 | AO44: 9 | AP44: 9 | AQ44: 3 | AR44: 7 | AS44: =(AT44+BB44+BE44+BJ44)/4 -> 3.5 | AT44: =AU44*AV44 -> 0 | AU44: 6 | AV44: =IF(AW44=1,1,IF(AW44=2,0.9,IF(AW44=3,0.8,IF(AW44=4,0.7,IF(AW44=5,0.6,IF(AW44=6,0.5,IF(AW44=7,0.4,IF(AW44=8,0.3,IF(AW44=9,0.2,IF(AW44=10,0.1,IF(AW44=0,0,0))))))))))) -> 0 | AX44: =IF($AZ$13>=BA44,"YA","TIDAK") -> YA | AY44: =IF($AZ$13-BA44>0,$AZ$13-BA44,"0") -> 0.76 | BA44: 0.25 | BB44: =BC44+BD44 -> 8 | BC44: 8 | BE44: =BF44*BH44*BI44 -> 0 | BH44: 1 | BI44: 8 | BJ44: =SUM(BK44:BV44) -> 6 | BK44: 6
...
