Workbook

Sheet ES
B2: No | C2: Identitas | D2: Kode | E2: Tingkat Emosi dan Sosial
E3: Kondisi Psikologis | M3: Pengaruh Sosial Ketika Menghadapi Orang Lain
E4: Emosi | G4: Suasana Hati | I4: Stres | K4: Kesepian | M4: Kesungkanan | N4: Ayah | O4: Ibu | P4: Nenek | Q4: Anak 1 | R4: Anak 2 | S4: Tamu
E5: Posisi normal | F5: Tingkat ke normal | G5: Posisi normal | H5: Tingkat ke normal | I5: Posisi normal | J5: Tingkat ke normal | K5: Posisi normal | L5: Tingkat ke normal | M5: Karakter Sosial | N5: Tingkat pengaruh | O5: Tingkat pengaruh | P5: Tingkat pengaruh | Q5: Tingkat pengaruh | R5: Tingkat pengaruh | S5: Tingkat pengaruh
B6: 2 | D6: ART
C8: perlu diisi

Sheet FIS
B2: No | C2: Identitas | D2: Kode | E2: Kemampuan | H2: Batas Indera | K2: Efek Khusus
E3: Kemampuan pada tingkat normal (0-10) | F3: Kondisi Terkini | H3: Penglihatan | I3: Termal | K3: Kandung Kemih (Cairan) | L3: Kondisi Terkini | M3: Usus besar (Padatan) | N3: Kondisi Terkini
F4: Kemudahan Beraktivitas | G4: Kemampuan capaian Fisik | H4: Intensitas Cahaya (Lux) | I4: Tingkat Temperatur (°C) | J4: Perf. Kelembaban (%) | K4: Daya Tampung 500 (ml) | M4: Daya Tampung 1200 (ml)
B5: 2 | D5: ART
C7: perlu diisi

Sheet BIO
B1: No | C1: Identitas | D1: Kode | E1: Data Reaksi Biologis
E2: Laju Pengaruh Internal Berdasarkan Waktu
E3: Urinasi | G3: Defekasi | I3: Kotor | K3: Energi (0,625 poin/jam) | M3: Kelaparan (1,6 poin/jam) | O3: Kehausan (3,33 poin/jam) | Q3: Kelelahan (1,25 poin/jam) | S3: Kantuk (1,25 poin/jam)
E4: ml/Menit | F4: Ditambahkan | G4: ml/Menit | H4: Ditambahkan | I4: Poin/Menit | J4: Ditambahkan | K4: Poin/Jam | L4: Ditambahkan | M4: Poin/Menit | N4: Ditambahkan | O4: Poin/Menit | P4: Ditambahkan | Q4: Poin/Menit | R4: Ditambahkan | S4: Poin/Menit | T4: Ditambahkan
B5: 2 | D5: ART | E5: 1 | G5: 0.00021 | I5: 0.013 | K5: 0.01 | M5: 0.027 | O5: 0.055 | Q5: 0.02 | S5: 0.02
C6: perlu diisi

Sheet DP
C1: perlu diisi
B2: No | C2: Kode | D2: Aktivitas | E2: Jadwal / Waktu (konstan)
E4: Rules | H4: Habit | J4: Regular Plan | L4: Rentang waktu Reg. | M4: Kelompok Waktu | N4: Insidental Plan | P4: Rentang waktu Insi. | Q4: Lama aktivitas dilakukan
E5: ya/tidak | F5: Otoritas (Ayah(1,2)/ Ibu(1)/ Kakak(0,6)/ Nenek(0,8)) | G5: Kepatuhan (Obeidince) SKALA (0,2,4,6,8,10) | H5: ya/tidak | I5: Kebiasaan SKALA (10,8,6,4,2) | J5: ya / tidak | K5: Urgensi SKALA (0,2,4,6,8,10) | N5: ya / tidak | O5: Slot waktu | Q5: durasi (menit)
B7: 1 | C7: SP | D7: Membuang sampah | E7: Ya | H7: Tidak | J7: Ya
B8: 2 | C8: M1A | D8: Membersihkan Teras A | E8: Ya | H8: Tidak | J8: Tidak
B9: 3 | C9: M1B | D9: Membersihkan Teras B | E9: Ya | H9: Tidak | J9: Tidak
B10: 4 | C10: M3A | D10: Membersihkan Ruang Keluarga Depan | E10: Ya | H10: Tidak | J10: Tidak
B11: 5 | C11: M3B | D11: Membersihkan Ruang Keluarga Belakang | E11: Ya | H11: Ya | J11: Tidak
B12: 6 | C12: M4 | D12: Membersihkan Ruang Tidur Utama | E12: Ya | H12: Ya | J12: Tidak
B13: 7 | C13: M5A | D13: Membersihkan Ruang Tidur Anak 1 | E13: Ya | H13: Ya | J13: Tidak
B14: 8 | C14: M5B | D14: Membersihkan Ruang Tidur Anak 2 | E14: Ya | H14: Ya | J14: Tidak
B15: 9 | C15: M5C | D15: Membersihkan Ruang Tidur Anak 3 | E15: Ya | H15: Ya | J15: Tidak
B16: 10 | C16: M6 | D16: Membersihkan Ruang Tidur Tamu | E16: Ya | H16: Ya | J16: Tidak
B17: 11 | C17: M7 | D17: Membersihkan dapur | E17: Ya | H17: Ya | J17: Ya
B18: 12 | C18: M11A | D18: Membersihkan Kamar Mandi Kamar Utama | E18: Ya | H18: Ya | J18: Ya
... B41: 35 | C41: GL | D41: Mengganti galon (AIR RO) | E41: Ya | H41: Ya | J41: Tidak

Sheet TP
B2: No | C2: Kode | D2: Aktivitas | E2: Nilai Aktivitas | F2: Bisa Menginterupsi (Ya/Tidak) | G2: Bisa Diinterupsi (Ya/Tidak) | H2: Rentang waktu (00.00 – 23.59) | I2: Lama Aktivitas Dilakukan (Menit) | J2: Lama aktivitas dilakukan (MENIT) | K2: Ruang untuk Aktivitas | M2: Aktivitas Terencana | X2: Pengaruh Kondisi Biologis dan Fisiologi | AX2: Pengaruh Tingkat Emosi dan Sosial
X3: Dampak dari Aktivitas | AX3: Dampak Psikologi Terhadap Aktivitas | BJ3: Kesungkanan
K4: Ruang Alternatif 1 | L4: Ruang Alternatif 2 | M4: Rencana Reguler | P4: Kebiasaan | S4: Aturan | V4: Rencana Insidental | X4: Kelelahan | AA4: Kantuk | AD4: Kotor | AG4: Urinasi | AJ4: Defekasi | AM4: Energi | AP4: Kelaparan | AS4: Kehausan | AV4: Kemampuan | AX4: Emosi | BA4: Suasana Hati | BD4: Stres | BG4: Kesepian
M5: Ya / Tidak | N5: Karakter | O5: Urgensi | P5: Ya / Tidak | Q5: Karakter | R5: Kebiasaan | S5: Ya / Tidak | T5: Karakter | U5: Nilai | V5: Ya / Tidak | W5: Slot waktu | X5: Ya / Tidak | Y5: Karakter | Z5: Nilai | AA5: Ya / Tidak | AB5: Karakter | AC5: Nilai | AD5: Ya / Tidak | AE5: Karakter | AF5: Nilai | AG5: Ya / Tidak | AH5: Karakter | AI5: Nilai | AJ5: Ya / Tidak | AK5: Karakter | AL5: Nilai | AM5: Ya / Tidak | AN5: Karakter | AO5: Nilai | AP5: Ya / Tidak | AQ5: Karakter | AR5: Nilai | AS5: Ya / Tidak | AT5: Karakter | AU5: Nilai | AV5: Karakter | AW5: Nilai | AX5: Ya / Tidak | AY5: Karakter | AZ5: Nilai | BA5: Ya / Tidak | BB5: Karakter | BC5: Nilai | BD5: Ya / Tidak | BE5: Karakter | BF5: Nilai | BG5: Ya / Tidak | BH5: Karakter | BI5: Nilai | BJ5: Ya / Tidak | BK5: Karakter | BL5: Nilai
B7: =DP!B7 -> 1 | C7: =DP!C7 -> SP | D7: =DP!D7 -> Membuang sampah | K7: 0 | L7: 0
B8: =DP!B8 -> 2 | C8: =DP!C8 -> M1A | D8: =DP!D8 -> Membersihkan Teras A | K8: 0 | L8: 0
B9: =DP!B9 -> 3 | C9: =DP!C9 -> M1B | D9: =DP!D9 -> Membersihkan Teras B | K9: 0 | L9: 0
B10: =DP!B10 -> 4 | C10: =DP!C10 -> M3A | D10: =DP!D10 -> Membersihkan Ruang Keluarga Depan | K10: 0 | L10: 0
B11: =DP!B11 -> 5 | C11: =DP!C11 -> M3B | D11: =DP!D11 -> Membersihkan Ruang Keluarga Belakang | K11: 0 | L11: 0
B12: =DP!B12 -> 6 | C12: =DP!C12 -> M4 | D12: =DP!D12 -> Membersihkan Ruang Tidur Utama | K12: 0 | L12: 0
B13: =DP!B13 -> 7 | C13: =DP!C13 -> M5A | D13: =DP!D13 -> Membersihkan Ruang Tidur Anak 1 | K13: 0 | L13: 0
B14: =DP!B14 -> 8 | C14: =DP!C14 -> M5B | D14: =DP!D14 -> Membersihkan Ruang Tidur Anak 2 | K14: 0 | L14: 0
B15: =DP!B15 -> 9 | C15: =DP!C15 -> M5C | D15: =DP!D15 -> Membersihkan Ruang Tidur Anak 3 | K15: 0 | L15: 0
B16: =DP!B16 -> 10 | C16: =DP!C16 -> M6 | D16: =DP!D16 -> Membersihkan Ruang Tidur Tamu | K16: 0 | L16: 0
B17: =DP!B17 -> 11 | C17: =DP!C17 -> M7 | D17: =DP!D17 -> Membersihkan dapur | K17: 0 | L17: 0
B18: =DP!B18 -> 12 | C18: =DP!C18 -> M11A | D18: =DP!D18 -> Membersihkan Kamar Mandi Kamar Utama | K18: 0 | L18: 0
... B41: =DP!B41 -> 35 | C41: =DP!C41 -> GL | D41: =DP!D41 -> Mengganti galon (AIR RO) | K41: 0 | L41: 0

Sheet SYARAT
A1: Data Prasyarat Aktivitas Berjalan
A2: NO | B2: KODE | C2: Aktivitas | D2: Tingkat Kemampuan Minimal | E2: Faktor Fisik Lingkungan | O2: Faktor Sumber Daya | AD2: Faktor Ruang | AS2: Ruang untuk aktivitas
O3: Air/Listrik/Gas/Makanan/Bahan Makanan/Bahan Bacaan | AD3: Kursi/Sofa/Karpet/Pintu/Tempat Tidur/Alat Kebersihan/ Alat Berkebun | AS3: Ruang Alternatif 1 | AT3: Ruang Alternatif 2 | AU3: Kondisi Ruang Alt 1 | AV3: Jika Hidup Pilih | AW3: Jika Mati Pilih
E4: F1 Cahaya | J4: F2 Suhu | O4: R1 | T4: R2 | Y4: R3 | AD4: D1 | AI4: D2 | AN4: D3
E5: Ya / Tidak | F5: Batas | G5: Kondisi Terkini | H5: Jika Lebih Rendah Pilih | I5: Obyek Lampu | J5: Ya / Tidak | K5: Batas | L5: Kondisi Terkini | M5: Jika Lebih Tinggi Pilih | N5: Obyek Pengatur Suhu Ruang | O5: Ya / Tidak | P5: Komponen | Q5: Kondisi Terkini | R5: Jika Komponen Mati Pilih | S5: Obyek Lingkungan | T5: Ya / Tidak | U5: Komponen | V5: Kondisi Terkini | W5: Jika Komponen Mati Pilih | X5: Obyek Lingkungan | Y5: Ya / Tidak | Z5: Komponen | AA5: Kondisi Terkini | AB5: Jika Komponen Mati Pilih | AC5: Alat | AD5: Ya / Tidak | AE5: Komponen | AF5: Kondisi Terkini | AG5: Jika Komponen Mati Pilih | AH5: Obyek Lingkungan | AI5: Ya / Tidak | AJ5: Komponen | AK5: Kondisi Terkini | AL5: Jika Komponen Mati Pilih | AM5: Obyek Lingkungan | AN5: Ya / Tidak | AO5: Komponen | AP5: Kondisi Terkini | AQ5: Jika Komponen Mati Pilih | AR5: Alat
A7: =DP!B7 -> 1 | B7: =DP!C7 -> SP | C7: =DP!D7 -> Membuang sampah | D7: 6 | E7: Ya | F7: 100 | G7: 40 | H7: S1 | I7: L17/ L25/ L27 | J7: Tidak | K7: 0 | L7: 0 | M7: 0 | N7: 0 | O7: Tidak | P7: 0 | Q7: 0 | R7: 0 | S7: 0 | T7: Tidak | U7: 0 | V7: 0 | W7: 0 | X7: 0 | Y7: Tidak | Z7: 0 | AA7: 0 | AB7: 0 | AC7: 0 | AD7: Ya | AE7: Pintu | AF7: Mati | AG7: G2 | AH7: P01/ P09 | AI7: Ya | AJ7: Alat Kebersihan | AK7: Mati | AL7: O8 | AM7: 0 | AN7: Tidak | AO7: 0 | AP7: 0 | AQ7: 0 | AR7: 0 | AS7: =TP!K7 -> 0 | AT7: =TP!L7 -> 0 | AU7: Hidup | AV7: J2 | AW7: J1
A8: =DP!B8 -> 2 | B8: =DP!C8 -> M1A | C8: =DP!D8 -> Membersihkan Teras A | D8: 6 | E8: Ya | F8: 100 | G8: 40 | H8: S2 | I8: L25 | J8: Tidak | K8: 0 | L8: 0 | M8: 0 | N8: 0 | O8: Tidak | P8: 0 | Q8: 0 | R8: 0 | S8: 0 | T8: Tidak | U8: 0 | V8: 0 | W8: 0 | X8: 0 | Y8: Tidak | Z8: 0 | AA8: 0 | AB8: 0 | AC8: 0 | AD8: Ya | AE8: Pintu | AF8: Mati | AG8: G2 | AH8: P01 | AI8: Ya | AJ8: Alat Kebersihan | AK8: Mati | AL8: O8 | AM8: 0 | AN8: Tidak | AO8: 0 | AP8: 0 | AQ8: 0 | AR8: 0 | AS8: =TP!K8 -> 0 | AT8: =TP!L8 -> 0 | AU8: Hidup | AV8: J2 | AW8: J1
A9: =DP!B9 -> 3 | B9: =DP!C9 -> M1B | C9: =DP!D9 -> Membersihkan Teras B | D9: 6 | E9: Ya | F9: 100 | G9: 40 | H9: S3 | I9: L27 | J9: Tidak | K9: 0 | L9: 0 | M9: 0 | N9: 0 | O9: Tidak | P9: 0 | Q9: 0 | R9: 0 | S9: 0 | T9: Tidak | U9: 0 | V9: 0 | W9: 0 | X9: 0 | Y9: Tidak | Z9: 0 | AA9: 0 | AB9: 0 | AC9: 0 | AD9: Ya | AE9: Pintu | AF9: Mati | AG9: G2 | AH9: P09 | AI9: Ya | AJ9: Alat Kebersihan | AK9: Mati | AL9: O8 | AN9: Tidak | AO9: 0 | AP9: 0 | AQ9: 0 | AR9: 0 | AS9: =TP!K9 -> 0 | AT9: =TP!L9 -> 0 | AU9: Hidup | AV9: J2 | AW9: J1
A10: =DP!B10 -> 4 | B10: =DP!C10 -> M3A | C10: =DP!D10 -> Membersihkan Ruang Keluarga Depan | D10: 6 | E10: Ya | F10: 100 | G10: 40 | H10: S1 | I10: L5 | J10: Tidak | K10: 0 | L10: 0 | M10: 0 | N10: 0 | O10: Tidak | P10: 0 | Q10: 0 | R10: 0 | S10: 0 | T10: Tidak | U10: 0 | V10: 0 | W10: 0 | X10: 0 | AD10: Ya | AE10: Alat Kebersihan | AF10: Mati | AG10: O8 | AI10: Tidak | AJ10: 0 | AK10: 0 | AL10: 0 | AM10: 0 | AS10: =TP!K10 -> 0 | AT10: =TP!L10 -> 0 | AU10: Hidup | AV10: J2 | AW10: J1
A11: =DP!B11 -> 5 | B11: =DP!C11 -> M3B | C11: =DP!D11 -> Membersihkan Ruang Keluarga Belakang | D11: 6 | E11: Ya | F11: 100 | G11: 40 | H11: S1 | I11: L10 | J11: Tidak | K11: 0 | L11: 0 | M11: 0 | N11: 0 | O11: Tidak | P11: 0 | Q11: 0 | R11: 0 | S11: 0 | T11: Tidak | U11: 0 | V11: 0 | W11: 0 | X11: 0 | AD11: Ya | AE11: Alat Kebersihan | AF11: Mati | AG11: O8 | AI11: Tidak | AJ11: 0 | AK11: 0 | AL11: 0 | AM11: 0 | AS11: =TP!K11 -> 0 | AT11: =TP!L11 -> 0 | AU11: Hidup | AV11: J2 | AW11: J1
A12: =DP!B12 -> 6 | B12: =DP!C12 -> M4 | C12: =DP!D12 -> Membersihkan Ruang Tidur Utama | D12: 6 | E12: Ya | F12: 100 | G12: 40 | H12: S1 | I12: L8 | J12: Tidak | K12: 0 | L12: 0 | M12: 0 | N12: 0 | O12: Tidak | P12: 0 | Q12: 0 | R12: 0 | S12: 0 | T12: Tidak | U12: 0 | V12: 0 | W12: 0 | X12: 0 | AD12: Ya | AE12: Pintu | AF12: Mati | AG12: G2 | AH12: P08 | AI12: Ya | AJ12: Alat Kebersihan | AK12: Mati | AL12: O8 | AS12: =TP!K12 -> 0 | AT12: =TP!L12 -> 0 | AU12: Hidup | AV12: J2 | AW12: J1
A13: =DP!B13 -> 7 | B13: =DP!C13 -> M5A | C13: =DP!D13 -> Membersihkan Ruang Tidur Anak 1 | D13: 6 | E13: Ya | F13: 100 | G13: 40 | H13: S1 | I13: L2 | J13: Tidak | K13: 0 | L13: 0 | M13: 0 | N13: 0 | O13: Tidak | P13: 0 | Q13: 0 | R13: 0 | S13: 0 | T13: Tidak | U13: 0 | V13: 0 | W13: 0 | X13: 0 | AD13: Ya | AE13: Pintu | AF13: Mati | AG13: G2 | AH13: P02 | AI13: Ya | AJ13: Alat Kebersihan | AK13: Mati | AL13: O8 | AS13: =TP!K13 -> 0 | AT13: =TP!L13 -> 0 | AU13: Hidup | AV13: J2 | AW13: J1
A14: =DP!B14 -> 8 | B14: =DP!C14 -> M5B | C14: =DP!D14 -> Membersihkan Ruang Tidur Anak 2 | D14: 6 | E14: Ya | F14: 100 | G14: 40 | H14: S1 | I14: L9 | J14: Tidak | K14: 0 | L14: 0 | M14: 0 | N14: 0 | O14: Tidak | P14: 0 | Q14: 0 | R14: 0 | S14: 0 | T14: Tidak | U14: 0 | V14: 0 | W14: 0 | X14: 0 | AD14: Ya | AE14: Pintu | AF14: Mati | AG14: G2 | AH14: P04 | AI14: Ya | AJ14: Alat Kebersihan | AK14: Mati | AL14: O8 | AS14: =TP!K14 -> 0 | AT14: =TP!L14 -> 0 | AU14: Hidup | AV14: J2 | AW14: J1
A15: =DP!B15 -> 9 | B15: =DP!C15 -> M5C | C15: =DP!D15 -> Membersihkan Ruang Tidur Anak 3 | D15: 6 | E15: Ya | F15: 100 | G15: 40 | H15: S1 | I15: L22 | J15: Tidak | K15: 0 | L15: 0 | M15: 0 | N15: 0 | O15: Tidak | P15: 0 | Q15: 0 | R15: 0 | S15: 0 | T15: Tidak | U15: 0 | V15: 0 | W15: 0 | X15: 0 | AD15: Ya | AE15: Pintu | AF15: Mati | AG15: G2 | AH15: P19 | AI15: Ya | AJ15: Alat Kebersihan | AK15: Mati | AL15: O8 | AS15: =TP!K15 -> 0 | AT15: =TP!L15 -> 0 | AU15: Hidup | AV15: J2 | AW15: J1
A16: =DP!B16 -> 10 | B16: =DP!C16 -> M6 | C16: =DP!D16 -> Membersihkan Ruang Tidur Tamu | D16: 6 | E16: Ya | F16: 100 | G16: 40 | H16: S1 | I16: L20 | J16: Tidak | K16: 0 | L16: 0 | M16: 0 | N16: 0 | O16: Tidak | P16: 0 | Q16: 0 | R16: 0 | S16: 0 | T16: Tidak | U16: 0 | V16: 0 | W16: 0 | X16: 0 | AD16: Ya | AE16: Pintu | AF16: Mati | AG16: G2 | AH16: P17 | AI16: Ya | AJ16: Alat Kebersihan | AK16: Mati | AL16: O8 | AS16: =TP!K16 -> 0 | AT16: =TP!L16 -> 0 | AU16: Hidup | AV16: J2 | AW16: J1
A17: =DP!B17 -> 11 | B17: =DP!C17 -> M7 | C17: =DP!D17 -> Membersihkan dapur | D17: 6 | E17: Ya | F17: 100 | G17: 40 | H17: S1 | I17: L15/ L17 | J17: Tidak | K17: 0 | L17: 0 | M17: 0 | N17: 0 | O17: Ya | P17: Listrik | Q17: Mati | R17: L2 | S17: EX03 | T17: Ya | U17: Air | V17: Mati | W17: O1 | X17: WT09 | AD17: Ya | AE17: Alat Kebersihan | AF17: Mati | AG17: O8 | AI17: Tidak | AJ17: 0 | AK17: 0 | AL17: 0 | AM17: 0 | AS17: =TP!K17 -> 0 | AT17: =TP!L17 -> 0 | AU17: Hidup | AV17: J2 | AW17: J1
A18: =DP!B18 -> 12 | B18: =DP!C18 -> M11A | C18: =DP!D18 -> Membersihkan Kamar Mandi Kamar Utama | D18: 8 | E18: Ya | F18: 100 | G18: 40 | H18: S1 | I18: L13 | J18: Tidak | K18: 0 | L18: 0 | M18: 0 | N18: 0 | O18: Ya | P18: Listrik | Q18: Mati | R18: L2 | S18: EX01 | T18: Ya | U18: Air | V18: Mati | W18: O1 | X18: WT06/ WT07/ WT08 | AD18: Ya | AE18: Pintu | AF18: Mati | AG18: G2 | AH18: P11 | AI18: Ya | AJ18: Alat Kebersihan | AK18: Mati | AL18: O8 | AS18: =TP!K18 -> 0 | AT18: =TP!L18 -> 0 | AU18: Hidup | AV18: J2 | AW18: J1
A19: =DP!B19 -> 13 | B19: =DP!C19 -> M11B | C19: =DP!D19 -> Membersihkan Kamar Mandi Luar | D19: 8 | E19: Ya | F19: 100 | G19: 40 | H19: S1 | I19: L16 | J19: Tidak | K19: 0 | L19: 0 | M19: 0 | N19: 0 | O19: Ya | P19: Listrik | Q19: Mati | R19: L2 | S19: EX02 | T19: Ya | U19: Air | V19: Mati | W19: O1 | X19: WT01/ WT02/ WT03 | AD19: Ya | AE19: Pintu | AF19: Mati | AG19: G2 | AH19: P13 | AI19: Ya | AJ19: Alat Kebersihan | AK19: Mati | AL19: O8 | AS19: =TP!K19 -> 0 | AT19: =TP!L19 -> 0 | AU19: Hidup | AV19: J2 | AW19: J1
A20: =DP!B20 -> 14 | B20: =DP!C20 -> M11C | C20: =DP!D20 -> Membersihkan Kamar Mandi Kamar Anak 3 | D20: 8 | E20: Ya | F20: 100 | G20: 40 | H20: S1 | I20: L21 | J20: Tidak | K20: 0 | L20: 0 | M20: 0 | N20: 0 | O20: Ya | P20: Air | Q20: Mati | R20: O1 | S20: WT04/ WT05 | T20: Tidak | U20: 0 | V20: 0 | W20: 0 | X20: 0 | AD20: Ya | AE20: Pintu | AF20: Mati | AG20: G2 | AH20: P16 | AI20: Ya | AJ20: Alat Kebersihan | AK20: Mati | AL20: O8 | AS20: =TP!K20 -> 0 | AT20: =TP!L20 -> 0 | AU20: Hidup | AV20: J2 | AW20: J1
A21: =DP!B21 -> 15 | B21: =DP!C21 -> M11D | C21: =DP!D21 -> Membersihkan Kamar Mandi Kamar Tamu | D21: 8 | E21: Ya | F21: 100 | G21: 40 | H21: S1 | I21: L19 | J21: Tidak | K21: 0 | L21: 0 | M21: 0 | N21: 0 | O21: Ya | P21: Air | Q21: Mati | R21: O1 | S21: WT10/ WT11 | T21: Tidak | U21: 0 | V21: 0 | W21: 0 | X21: 0 | AD21: Ya | AE21: Pintu | AF21: Mati | AG21: G2 | AH21: P18 | AI21: Ya | AJ21: Alat Kebersihan | AK21: Mati | AL21: O8 | AS21: =TP!K21 -> 0 | AT21: =TP!L21 -> 0 | AU21: Hidup | AV21: J2 | AW21: J1
A22: =DP!B22 -> 16 | B22: =DP!C22 -> MK2 | C22: =DP!D22 -> Makan pagi | D22: 2 | E22: Ya | F22: 100 | G22: 40 | H22: S1 | I22: L11 | J22: Tidak | K22: 0 | L22: 0 | M22: 0 | N22: 0 | O22: Ya | P22: Makanan | Q22: Hidup | R22: G5 | S22: RC01 | T22: Tidak | U22: 0 | V22: 0 | W22: 0 | X22: 0 | AD22: Ya | AE22: Kursi/Karpet/Sofa | AF22: Mati | AG22: K/KR/S | AH22: K03 | AI22: Tidak | AJ22: 0 | AK22: 0 | AL22: 0 | AM22: 0 | AS22: =TP!K22 -> 0 | AT22: =TP!L22 -> 0 | AU22: Hidup | AV22: J2 | AW22: J1
A23: =DP!B23 -> 17 | B23: =DP!C23 -> PG1 | C23: =DP!D23 -> Mencuci piring dan gelas | D23: 4 | E23: Ya | F23: 100 | G23: 40 | H23: S1 | I23: L15/ L17 | J23: Tidak | K23: 0 | L23: 0 | M23: 0 | N23: 0 | O23: Ya | P23: Listrik | Q23: Mati | R23: L2 | S23: EX03 | T23: Ya | U23: Air | V23: Mati | W23: O1 | X23: WT09 | AD23: Tidak | AE23: 0 | AF23: 0 | AG23: 0 | AH23: 0 | AI23: Tidak | AJ23: 0 | AK23: 0 | AL23: 0 | AM23: 0 | AS23: =TP!K23 -> 0 | AT23: =TP!L23 -> 0 | AU23: Hidup | AV23: J2 | AW23: J1
A24: =DP!B24 -> 18 | B24: =DP!C24 -> PG2 | C24: =DP!D24 -> Mencuci peralatan masak | D24: 4 | E24: Ya | F24: 100 | G24: 40 | H24: S1 | I24: L15/ L17 | J24: Tidak | K24: 0 | L24: 0 | M24: 0 | N24: 0 | O24: Ya | P24: Listrik | Q24: Mati | R24: L2 | S24: EX03 | T24: Ya | U24: Air | V24: Mati | W24: O1 | X24: WT09/ WT04 | AD24: Tidak | AE24: 0 | AF24: 0 | AG24: 0 | AH24: 0 | AI24: Tidak | AJ24: 0 | AK24: 0 | AL24: 0 | AM24: 0 | AS24: =TP!K24 -> 0 | AT24: =TP!L24 -> 0 | AU24: Hidup | AV24: J2 | AW24: J1
A25: =DP!B25 -> 19 | B25: =DP!C25 -> BR2 | C25: =DP!D25 -> Berkebun (menanam/merawat) di sore hari | D25: 6 | E25: Ya | F25: 100 | G25: 40 | H25: S1 | I25: L25/ L26/ L27 | J25: Tidak | K25: 0 | L25: 0 | M25: 0 | N25: 0 | O25: Ya | P25: Air | Q25: Mati | R25: O1 | T25: Tidak | U25: 0 | V25: 0 | W25: 0 | X25: 0 | AD25: Ya | AE25: Pintu | AF25: Mati | AG25: G2 | AH25: P01/ P09 | AI25: Tidak | AJ25: 0 | AK25: 0 | AL25: 0 | AM25: 0 | AS25: =TP!K25 -> 0 | AT25: =TP!L25 -> 0 | AU25: Hidup | AV25: J2 | AW25: J1
A26: =DP!B26 -> 20 | B26: =DP!C26 -> MT2 | C26: =DP!D26 -> Menyiram tanaman di sore hari | D26: 4 | E26: Ya | F26: 100 | G26: 40 | H26: S1 | I26: L25/ L27 | J26: Tidak | K26: 0 | L26: 0 | M26: 0 | N26: 0 | O26: Ya | P26: Air | Q26: Mati | R26: O1 | T26: Tidak | U26: 0 | V26: 0 | W26: 0 | X26: 0 | AD26: Ya | AE26: Pintu | AF26: Mati | AG26: G2 | AH26: P01/ P09 | AI26: Tidak | AJ26: 0 | AK26: 0 | AL26: 0 | AM26: 0 | AS26: =TP!K26 -> 0 | AT26: =TP!L26 -> 0 | AU26: Hidup | AV26: J2 | AW26: J1
A27: =DP!B27 -> 21 | B27: =DP!C27 -> CC2 | C27: =DP!D27 -> Menggunakan mesin cuci | D27: 6 | E27: Ya | F27: 100 | G27: 40 | H27: S1 | I27: L17 | J27: Tidak | K27: 0 | L27: 0 | M27: 0 | N27: 0 | O27: Ya | P27: Listrik | Q27: Mati | R27: L2 | S27: WM01 | T27: Ya | U27: Air | V27: Mati | W27: O1 | X27: WT04 | AD27: Tidak | AE27: 0 | AF27: 0 | AG27: 0 | AH27: 0 | AI27: Tidak | AJ27: 0 | AK27: 0 | AL27: 0 | AM27: 0 | AS27: =TP!K27 -> 0 | AT27: =TP!L27 -> 0 | AU27: Hidup | AV27: J2 | AW27: J1
A28: =DP!B28 -> 22 | B28: =DP!C28 -> CC4 | C28: =DP!D28 -> Menjemur pakaian | D28: 4 | E28: Ya | F28: 100 | G28: 40 | H28: S1 | I28: L17 | J28: Tidak | K28: 0 | L28: 0 | M28: 0 | N28: 0 | O28: Tidak | P28: 0 | Q28: 0 | R28: 0 | S28: 0 | T28: Tidak | U28: 0 | V28: 0 | W28: 0 | X28: 0 | AD28: Tidak | AE28: 0 | AF28: 0 | AG28: 0 | AH28: 0 | AI28: Tidak | AJ28: 0 | AK28: 0 | AL28: 0 | AM28: 0 | AS28: =TP!K28 -> 0 | AT28: =TP!L28 -> 0 | AU28: Hidup | AV28: J2 | AW28: J1
A29: =DP!B29 -> 23 | B29: =DP!C29 -> CC5 | C29: =DP!D29 -> Mengangkat jemuran | D29: 4 | E29: Ya | F29: 100 | G29: 40 | H29: S1 | I29: L17 | J29: Tidak | K29: 0 | L29: 0 | M29: 0 | N29: 0 | O29: Tidak | P29: 0 | Q29: 0 | R29: 0 | S29: 0 | T29: Tidak | U29: 0 | V29: 0 | W29: 0 | X29: 0 | AD29: Tidak | AE29: 0 | AF29: 0 | AG29: 0 | AH29: 0 | AI29: Tidak | AJ29: 0 | AK29: 0 | AL29: 0 | AM29: 0 | AS29: =TP!K29 -> 0 | AT29: =TP!L29 -> 0 | AU29: Hidup | AV29: J2 | AW29: J1
A30: =DP!B30 -> 24 | B30: =DP!C30 -> CY2 | C30: =DP!D30 -> Menyetrika pakaian di siang hari | D30: 8 | E30: Ya | F30: 100 | G30: 40 | H30: S1 | I30: L10 | J30: Tidak | K30: 0 | L30: 0 | M30: 0 | N30: 0 | O30: Ya | P30: Listrik | Q30: Hidup | R30: L2 | S30: DI01 | T30: Tidak | U30: 0 | V30: 0 | W30: 0 | X30: 0 | AD30: Tidak | AE30: 0 | AF30: 0 | AG30: 0 | AH30: 0 | AI30: Tidak | AJ30: 0 | AK30: 0 | AL30: 0 | AM30: 0 | AS30: =TP!K30 -> 0 | AT30: =TP!L30 -> 0 | AU30: Hidup | AV30: J2 | AW30: J1
A31: =DP!B31 -> 25 | B31: =DP!C31 -> TO | C31: =DP!D31 -> Toilet (hanya BAK/BAB) | D31: 4 | E31: Ya | F31: 100 | G31: 40 | H31: S1 | I31: L16 | J31: Tidak | K31: 0 | L31: 0 | M31: 0 | N31: 0 | O31: Ya | P31: Air | Q31: Hidup | R31: O1 | S31: WT02 | T31: Ya | U31: Listrik | V31: Mati | W31: L2 | X31: EX02 | AD31: Ya | AE31: Pintu | AF31: Mati | AG31: G2 | AH31: P13 | AI31: Tidak | AJ31: 0 | AK31: 0 | AL31: 0 | AM31: 0 | AS31: =TP!K31 -> 0 | AT31: =TP!L31 -> 0 | AU31: Hidup | AV31: J2 | AW31: J1
A32: =DP!B32 -> 26 | B32: =DP!C32 -> MD | C32: =DP!D32 -> Mandi (diluar waktu mandi pagi dan sore) | D32: 4 | E32: Ya | F32: 100 | G32: 40 | H32: S1 | I32: L16 | J32: Tidak | K32: 0 | L32: 0 | M32: 0 | N32: 0 | O32: Ya | P32: Air | Q32: Hidup | R32: O1 | S32: WT02/ WT03 | T32: Ya | U32: Listrik | V32: Mati | W32: L3 | X32: EX03 | AD32: Ya | AE32: Pintu | AF32: Mati | AG32: G2 | AH32: P13 | AI32: Tidak | AJ32: 0 | AK32: 0 | AL32: 0 | AM32: 0 | AS32: =TP!K32 -> 0 | AT32: =TP!L32 -> 0 | AU32: Hidup | AV32: J2 | AW32: J1
A33: =DP!B33 -> 27 | B33: =DP!C33 -> MK | C33: =DP!D33 -> Makan (diluar waktu makan pagi, siang, malam) | D33: 2 | E33: Ya | F33: 100 | G33: 40 | H33: S1 | I33: L11 | J33: Tidak | K33: 0 | L33: 0 | M33: 0 | N33: 0 | O33: Ya | P33: Makanan | Q33: Hidup | R33: G5 | S33: RC01 | T33: Tidak | U33: 0 | V33: 0 | W33: 0 | X33: 0 | AD33: Ya | AE33: Kursi/Karpet/Sofa | AF33: Mati | AG33: K/KR/S | AH33: K03 | AI33: Tidak | AJ33: 0 | AK33: 0 | AL33: 0 | AM33: 0 | AS33: =TP!K33 -> 0 | AT33: =TP!L33 -> 0 | AU33: Hidup | AV33: J2 | AW33: J1
A34: =DP!B34 -> 28 | B34: =DP!C34 -> MN1 | C34: =DP!D34 -> Minum setelah makan pagi | D34: 2 | E34: Ya | F34: 100 | G34: 40 | H34: S1 | I34: L11 | J34: Tidak | K34: 0 | L34: 0 | M34: 0 | N34: 0 | O34: Ya | P34: Listrik | Q34: Hidup | R34: L2 | S34: DP01 | T34: Tidak | U34: 0 | V34: 0 | W34: 0 | X34: 0 | AD34: Ya | AE34: Kursi/Karpet/Sofa | AF34: Mati | AG34: K/KR/S | AH34: K03 | AI34: Tidak | AJ34: 0 | AK34: 0 | AL34: 0 | AM34: 0 | AS34: =TP!K34 -> 0 | AT34: =TP!L34 -> 0 | AU34: Hidup | AV34: J2 | AW34: J1
A35: =DP!B35 -> 29 | B35: =DP!C35 -> MN2 | C35: =DP!D35 -> Minum setelah makan siang | D35: 2 | E35: Ya | F35: 100 | G35: 40 | H35: S1 | I35: L11 | J35: Tidak | K35: 0 | L35: 0 | M35: 0 | N35: 0 | O35: Ya | P35: Listrik | Q35: Hidup | R35: L2 | S35: DP01 | T35: Tidak | U35: 0 | V35: 0 | W35: 0 | X35: 0 | AD35: Ya | AE35: Kursi/Karpet/Sofa | AF35: Mati | AG35: K/KR/S | AH35: K03 | AI35: Tidak | AJ35: 0 | AK35: 0 | AL35: 0 | AM35: 0 | AS35: =TP!K40 -> 0 | AT35: =TP!L40 -> 0 | AU35: Hidup | AV35: J2 | AW35: J1
A36: =DP!B36 -> 30 | B36: =DP!C36 -> MN3 | C36: =DP!D36 -> Minum setelah makan malam | D36: 2 | E36: Ya | F36: 100 | G36: 40 | H36: S1 | I36: L11 | J36: Tidak | K36: 0 | L36: 0 | M36: 0 | N36: 0 | O36: Ya | P36: Listrik | Q36: Hidup | R36: L2 | S36: DP01 | T36: Tidak | U36: 0 | V36: 0 | W36: 0 | X36: 0 | AD36: Ya | AE36: Kursi/Karpet/Sofa | AF36: Mati | AG36: K/KR/S | AH36: K03 | AI36: Tidak | AJ36: 0 | AK36: 0 | AL36: 0 | AM36: 0 | AS36: =TP!K41 -> 0 | AT36: =TP!L41 -> 0 | AU36: Hidup | AV36: J2 | AW36: J1
A37: =DP!B37 -> 31 | B37: =DP!C37 -> MN4 | C37: =DP!D37 -> Minum (diluar waktu makan pagi, siang, malam) | D37: 2 | E37: Ya | F37: 100 | G37: 40 | H37: S1 | I37: L11 | J37: Tidak | K37: 0 | L37: 0 | M37: 0 | N37: 0 | O37: Ya | P37: Listrik | Q37: Hidup | R37: L2 | S37: DP01 | T37: Tidak | U37: 0 | V37: 0 | W37: 0 | X37: 0 | AD37: Ya | AE37: Kursi/Karpet/Sofa | AF37: Mati | AG37: K/KR/S | AH37: K03 | AI37: Tidak | AJ37: 0 | AK37: 0 | AL37: 0 | AM37: 0 | AS37: =TP!K42 -> 0 | AT37: =TP!L42 -> 0 | AU37: Hidup | AV37: J2 | AW37: J1
A38: =DP!B38 -> 32 | B38: =DP!C38 -> MP | C38: =DP!D38 -> Mengganti lampu | D38: 8 | E38: Ya | F38: 100 | G38: 40 | H38: S8 | I38: 0 | J38: Tidak | K38: 0 | L38: 0 | M38: 0 | N38: 0 | O38: Ya | P38: Listrik | Q38: Hidup | R38: L1 | S38: 0 | T38: Tidak | U38: 0 | V38: 0 | W38: 0 | X38: 0 | AD38: Tidak | AE38: 0 | AF38: 0 | AG38: 0 | AH38: 0 | AI38: Tidak | AJ38: 0 | AK38: 0 | AL38: 0 | AM38: 0 | AS38: =TP!K43 -> 0 | AT38: =TP!L43 -> 0 | AU38: Hidup | AV38: J2 | AW38: J1
A39: =DP!B39 -> 33 | B39: =DP!C39 -> TV | C39: =DP!D39 -> Menonton TV (waktu ditentukan responden) | D39: 2 | E39: Ya | F39: 100 | G39: 40 | H39: S1 | I39: L5/ L10 | J39: Ya | K39: 25 | L39: 27 | M39: S2 | N39: KP01 | O39: Ya | P39: Listrik | Q39: Mati | R39: L2 | S39: TV01/ TV02 | T39: Tidak | U39: 0 | V39: 0 | W39: 0 | X39: 0 | AD39: Ya | AE39: Kursi/Karpet/Sofa | AF39: Mati | AG39: K/KR/S | AH39: S09 | AI39: Tidak | AJ39: 0 | AK39: 0 | AL39: 0 | AM39: 0 | AS39: =TP!K44 -> 0 | AT39: =TP!L44 -> 0 | AU39: Hidup | AV39: J2 | AW39: J1
A40: =DP!B40 -> 34 | B40: =DP!C40 -> IB | C40: =DP!D40 -> Ibadah (di rumah responden) | D40: 4 | E40: Ya | F40: 100 | G40: 40 | H40: S1 | I40: L10 | J40: Tidak | K40: 0 | L40: 0 | M40: 0 | N40: 0 | O40: Tidak | P40: 0 | Q40: 0 | R40: 0 | S40: 0 | T40: Tidak | U40: 0 | V40: 0 | W40: 0 | X40: 0 | AD40: Tidak | AE40: 0 | AF40: 0 | AG40: 0 | AH40: 0 | AI40: Tidak | AJ40: 0 | AK40: 0 | AL40: 0 | AM40: 0 | AS40: =TP!K45 -> 0 | AT40: =TP!L45 -> 0 | AU40: Hidup | AV40: J2 | AW40: J1
A41: =DP!B41 -> 35 | B41: =DP!C41 -> GL | C41: =DP!D41 -> Mengganti galon (AIR RO) | D41: 8 | E41: Ya | F41: 100 | G41: 40 | H41: S1 | I41: L12 | J41: Tidak | K41: 0 | L41: 0 | M41: 0 | N41: 0 | O41: Ya | P41: Listrik | Q41: Hidup | R41: L1 | S41: DP01 | T41: Tidak | U41: 0 | V41: 0 | W41: 0 | X41: 0 | AD41: Tidak | AE41: 0 | AF41: 0 | AG41: 0 | AH41: 0 | AI41: Tidak | AJ41: 0 | AK41: 0 | AL41: 0 | AM41: 0 | AS41: =TP!K46 -> 0 | AT41: =TP!L46 -> 0 | AU41: Hidup | AV41: J2 | AW41: J1

Sheet PENDUKUNG
A1: Data Aktivitas Pendukung Sebelum Aktivitas Dijalankan | L1: Data Aktivitas Pendukung Setelah Aktivitas Dijalankan
A2: No | B2: Kode | C2: Aktivitas | D2: Durasi | F2: Peluang Dilakukan | G2: Efek Ke Iklim Lokal | H2: Laju Efek ke Iklim Lokal | I2: Efek ke Alat | J2: Status Operasional | L2: No | M2: Kode | N2: Aktivitas | O2: Durasi | Q2: Peluang Dilakukan | R2: Efek Ke Iklim Lokal | S2: Laju Efek ke Iklim Lokal | T2: Efek ke Alat | U2: Status Operasional
D3: Nilai | E3: Satuan | O3: Nilai | P3: Satuan
A4: 1 | B4: S1 | C4: Menghidupkan lampu | D4: 1 | E4: menit | F4: 1 | G4: pencahayaan dalam ruang lebih terang | I4: Status operasional alat | J4: Hidup / Mati | L4: 1 | M4: S8 | N4: Mematikan lampu | O4: 1 | P4: menit | Q4: 0.8 | R4: pencahayaan dalam ruang lebih gelap | T4: Status operasional alat | U4: Hidup / Mati
A5: 2 | B5: S2 | C5: Menghidupkan AC/kipas | D5: 5 | E5: menit | F5: 1 | G5: suhu ruang menurun | H5: 0.5 deg / menit | L5: 2 | M5: S9 | N5: Mematikan AC/kipas | O5: 5 | P5: menit | Q5: 0.8 | R5: suhu ruang meningkat | S5: 0.5 deg / menit
A6: 3 | B6: S3 | C6: Menghidupkan setrika | D6: 1 | E6: menit | F6: 1 | G6: suhu ruang meningkat | L6: 3 | M6: S10 | N6: Mematikan setrika | O6: 1 | P6: menit | Q6: 0.8 | R6: suhu ruang menurun
A7: 4 | B7: S4 | C7: Menghidupkan TV | D7: 1 | E7: menit | F7: 1 | G7: temperatur dan pencahayaan ruang meningkat | L7: 4 | M7: S11 | N7: Mematikan TV | O7: 1 | P7: menit | Q7: 0.8 | R7: akustika dan pencahayaan ruang menurun
A8: 5 | B8: S5 | C8: Menghidupkan radio | D8: 1 | E8: menit | F8: 1 | G8: akustika dalam ruang meningkat | L8: 5 | M8: S12 | N8: Mematikan radio | O8: 1 | P8: menit | Q8: 0.8 | R8: akustika dalam ruang menurun
A9: 6 | B9: S6 | C9: Menghidupkan komputer/laptop | D9: 1 | E9: menit | F9: 1 | G9: suhu dan pencahayaan ruang meningkat | L9: 6 | M9: S13 | N9: Mematikan komputer/laptop | O9: 1 | P9: menit | Q9: 0.8 | R9: suhu dan pencahayaan ruang menurun
A10: 7 | B10: S7 | C10: Menghidupkan mesin cuci | D10: 30 | E10: menit | F10: 1 | G10: akustika ruang meningkat | L10: 7 | M10: J3 | N10: Keluar dari ruang | O10: 1 | P10: menit | Q10: 1 | R10: suhu ruang menurun
A11: 8 | B11: J1 | C11: Berjalan ke ruang | D11: 1 | E11: menit | F11: 1 | G11: suhu ruang meningkat | L11: 8 | M11: O9 | N11: Mematikan kran air | O11: 1 | P11: menit | Q11: 0.8 | R11: bak terisi, tandon air berhenti
A12: 9 | B12: J2 | C12: Masuk ke ruang | D12: 1 | E12: menit | F12: 1 | G12: suhu ruang meningkat | L12: 9 | M12: O10 | N12: Mematikan pompa air | O12: 1 | P12: menit | Q12: 0.6 | R12: tandon air stabil
A13: 10 | B13: I1 | C13: Mengisi bahan bakar | D13: 5 | E13: menit | F13: 0.6 | L13: 10 | M13: O11 | N13: Menyimpan peralatan berkebun | O13: 1 | P13: menit | Q13: 0.4
A14: 11 | B14: O1 | C14: Menghidupkan kran air | D14: 1 | E14: menit | G14: bak terisi, kelembaban meningkat | L14: 11 | M14: O12 | N14: Menyimpan peralatan kerja | O14: 1 | P14: menit | Q14: 1
A15: 12 | B15: O2 | C15: Menghidupkan pompa air | D15: 1 | E15: menit | F15: 0.8 | G15: tandon air menurun | L15: 12 | M15: O13 | N15: Menyimpan peralatan les | O15: 1 | P15: menit | Q15: 0.4
A16: 13 | B16: O3 | C16: Mengambil peralatan berkebun | D16: 1 | E16: menit | L16: 13 | M16: O14 | N16: Meletakkan pakaian kotor | O16: 1 | P16: menit | Q16: 0.4
A17: 14 | B17: O4 | C17: Menyiapkan peralatan kerja | D17: 10 | E17: menit | L17: 14 | M17: O15 | N17: Mengambil pakaian bersih | O17: 1 | P17: menit | Q17: 0.4
A18: 15 | B18: O5 | C18: Menyiapkan peralatan les | D18: 10 | E18: menit | F18: 0.8 | L18: 17 | M18: O18 | N18: Menyimpan peralatan bersih rumah | O18: 2 | P18: menit | Q18: 0.2
A19: 16 | B19: O6 | C19: Meletakkan pakaian kotor | D19: 1 | E19: menit | F19: 0.4 | L19: 18 | M19: G9 | N19: Mengganti Gas | O19: 5 | P19: menit | Q19: 1
A20: 17 | B20: O7 | C20: Mengambil pakaian bersih | D20: 1 | E20: menit | F20: 0.4 | L20: 19 | M20: G10 | N20: Menutup pintu | O20: 1 | P20: menit | Q20: 0.8 | R20: gas tersedia
A21: 18 | B21: O8 | C21: Mengambil peralatan bersih rumah | D21: 2 | E21: menit | F21: 1 | L21: 20 | M21: G11 | N21: Mematikan Kompor | O21: 1 | P21: menit | Q21: 1 | R21: suhu ruang menurun
A22: 19 | B22: G1 | C22: Membeli gas | D22: 20 | E22: menit | F22: 1 | L22: 21 | M22: G12 | N22: Mengambil makanan | O22: 5 | P22: menit | Q22: 1
A23: 20 | B23: G2 | C23: Membuka pintu | D23: 1 | E23: menit | F23: 1 | L23: 22 | M23: G13 | N23: Mematikan printer | O23: 2 | P23: menit | Q23: 0.8
A24: 21 | B24: G3 | C24: Menghidupkan Kompor | D24: 1 | E24: menit | F24: 1 | G24: suhu ruang meningkat | L24: 23 | M24: G14 | N24: Mematikan rice cooker, microwave, oven | O24: 1 | P24: menit | Q24: 1
A25: 22 | B25: G5 | C25: Mengambil makanan | D25: 5 | E25: menit | F25: 1 | L25: 24 | M25: G15 | N25: Mematikan dispenser | O25: 1 | P25: menit | Q25: 0.8
A26: 23 | B26: G6 | C26: Menghidupkan printer | D26: 2 | E26: menit | F26: 1 | L26: 25 | M26: K2 | N26: Bangun dari duduk di kursi | O26: 1 | P26: menit | Q26: 1
A27: 24 | B27: G7 | C27: Menghidupkan rice cooker, microwave, oven | D27: 1 | E27: menit | F27: 1 | L27: 26 | M27: S2 | N27: Bangun dari duduk di sofa | O27: 1 | P27: menit | Q27: 1
A28: 25 | B28: G8 | C28: Menghidupkan dispenser | D28: 1 | E28: menit | F28: 1 | L28: 27 | M28: Kr2 | N28: Bangun dari duduk di karpet | O28: 1 | P28: menit | Q28: 1
A29: 26 | B29: G9 | C29: Mengganti galon | D29: 5 | E29: menit | F29: 1 | L29: 28 | M29: Kk2 | N29: Menutup kulkas | O29: 1 | P29: menit | Q29: 1
A30: 27 | B30: K1 | C30: Duduk di kursi | D30: 1 | E30: menit | F30: 1 | L30: 29 | M30: T4 | N30: Bangun dari Tempat Tidur | O30: 10 | P30: menit | Q30: 1
A31: 28 | B31: S1 | C31: Duduk di sofa | D31: 1 | E31: menit | F31: 1 | L31: 30 | M31: B2 | N31: Pulang belanja | O31: 10 | P31: menit | Q31: 1
A32: 29 | B32: Kr1 | C32: Duduk di karpet | D32: 1 | E32: menit | F32: 1 | L32: 31 | M32: B4 | N32: Mematikan blender | O32: 1 | P32: menit | Q32: 1
A33: 30 | B33: Kk1 | C33: Membuka kulkas | D33: 1 | E33: menit | F33: 1
A34: 31 | B34: T1 | C34: Membereskan Tempat Tidur | D34: 2 | E34: menit | F34: 1
A35: 32 | B35: T2 | C35: Berbaring di Tempat Tidur | D35: 3 | E35: menit | F35: 1
A36: 33 | B36: B1 | C36: Berangkat belanja | D36: 10 | E36: menit | F36: 1
A37: 34 | B37: B3 | C37: Menghidupkan blender | D37: 1 | E37: menit | F37: 1
A38: 35 | B38: L1 | C38: Mematikan peralatan listrik | D38: 3 | E38: menit | F38: 1
A39: 36 | B39: L2 | C39: Menghidupkan peralatan listrik | D39: 3 | E39: menit | F39: 1
A40: 37 | B40: A1 | C40: Mengambil air masak/minum | D40: 3 | E40: menit | F40: 1
...

Sheet RUN
A1: Data Aktivitas Berjalan
A2: No | B2: Aktivitas | C2: Status | D2: Diinterupsi (Ya / Tidak) | E2: Waktu
C3: Berjalan / Berhenti | E3: Durasi untuk Menyelesaikan Aktivitas (Menit) | F3: Waktu Berjalan | G3: Terpenuhi (%)
A5: 1 | B5: Bangun tidur di pagi hari | C5: Berjalan | D5: Tidak | E5: ='[1]Data Rencana'!Q15 -> 0

Sheet URUTAN
A1: Data Urutan Aktivitas
A2: No | B2: Aktivitas | C2: Nilai
A3: 1 | C3: 0
A4: 2 | C4: 0
A5: 3 | C5: 0
A6: 4 | C6: 0
A7: 5 | C7: 0
A8: 6 | C8: 0
A9: 7 | C9: 0
A10: 8 | C10: 0
A11: 9 | C11: 0
A12: 10 | C12: 0
