Workbook

Sheet Psi&Fis_IC
B3: 1 Sheet untuk masing-masing rumah
A6: NO | B6: PERAN | C6: KONDISI PSIKOLOGIS | AF6: NO | AG6: PERAN | AH6: KONDISI FISIK
C7: EMOSI | J7: SUASANA HATI | Q7: STRES | X7: KESEPIAN | AH7: KEMAMPUAN
C8: TINGKAT (√) | J8: TINGKAT (√) | Q8: TINGKAT (√) | X8: TINGKAT (√) | AH8: KEMUDAHAN BERAKTIVITAS (√) | AN8: KEMAMPUAN CAPAIAN FISIK (√)
C9: -6 | D9: -4 | E9: -2 | F9: 0 | G9: +2 | H9: +4 | I9: +6 | J9: -6 | K9: -4 | L9: -2 | M9: 0 | N9: +2 | O9: +4 | P9: +6 | Q9: -6 | R9: -4 | S9: -2 | T9: 0 | U9: +2 | V9: +4 | W9: +6 | X9: -6 | Y9: -4 | Z9: -2 | AA9: 0 | AB9: +2 | AC9: +4 | AD9: +6 | AH9: 0 | AI9: 2 | AJ9: 4 | AK9: 6 | AL9: 8 | AM9: 10 | AN9: -1 | AO9: -0,8 | AP9: -0,6 | AQ9: -0,4 | AR9: 0,2 | AS9: 0
A10: 1 | B10: AYAH | F10: √ | M10: √ | T10: √ | AA10: √ | AF10: 1 | AG10: AYAH | AL10: √ | AS10: √
A11: 2 | B11: IBU | F11: √ | M11: √ | U11: √ | AA11: √ | AF11: 2 | AG11: IBU | AL11: √ | AS11: √
A12: 3 | B12: ADIK | F12: √ | M12: √ | T12: √ | AA12: √ | AF12: 3 | AG12: ADIK | AL12: √ | AS12: √
A13: 4 | B13: KAKAK | F13: √ | M13: √ | T13: √ | AA13: √ | AF13: 4 | AG13: KAKAK | AL13: √ | AR13: √
A14: 5 | B14: NENEK | F14: √ | M14: √ | T14: √ | AA14: √ | AF14: 5 | AG14: NENEK | AJ14: √ | AP14: √

Sheet Bio_IC
B3: 1 Sheet untuk masing-masing rumah
A6: NO | B6: PERAN | C6: KONDISI BIOLOGIS
C7: KANDUNG KEMIH | I7: USUS BESAR | O7: KOTOR | U7: ENERGI | AA7: LAPAR | AG7: KEHAUSAN | AM7: KELELAHAN | AS7: MENGANTUK
C8: TINGKAT SEBELUM TIDUR (√) | I8: TINGKAT SEBELUM TIDUR (√) | O8: TINGKAT SEBELUM TIDUR (√) | U8: TINGKAT SEBELUM TIDUR (√) | AA8: TINGKAT SEBELUM TIDUR (√) | AG8: TINGKAT SEBELUM TIDUR (√) | AM8: TINGKAT SEBELUM TIDUR (√) | AS8: TINGKAT SEBELUM TIDUR (√)
C9: 0 | D9: 2 | E9: 4 | F9: 6 | G9: 8 | H9: 10 | I9: 0 | J9: 2 | K9: 4 | L9: 6 | M9: 8 | N9: 10 | O9: 0 | P9: 2 | Q9: 4 | R9: 6 | S9: 8 | T9: 10 | U9: 0 | V9: 2 | W9: 4 | X9: 6 | Y9: 8 | Z9: 10 | AA9: 0 | AB9: 2 | AC9: 4 | AD9: 6 | AE9: 8 | AF9: 10 | AG9: 0 | AH9: 2 | AI9: 4 | AJ9: 6 | AK9: 8 | AL9: 10 | AM9: 0 | AN9: 2 | AO9: 4 | AP9: 6 | AQ9: 8 | AR9: 10 | AS9: 0 | AT9: 2 | AU9: 4 | AV9: 6 | AW9: 8 | AX9: 10
A10: 1 | B10: AYAH | C10: √ | L10: √ | P10: √ | X10: √ | AB10: √ | AH10: √ | AP10: √ | AV10: √
A11: 2 | B11: IBU | C11: √ | L11: √ | P11: √ | X11: √ | AB11: √ | AH11: √ | AP11: √ | AU11: √
A12: 3 | B12: KAKAK | C12: √ | J12: √ | Q12: √ | Y12: √ | AB12: √ | AH12: √ | AP12: √ | AV12: √
A13: 4 | B13: ADIK | C13: √ | J13: √ | Q13: √ | Y13: √ | AB13: √ | AH13: √ | AP13: √ | AV13: √
A14: 5 | B14: NENEK | D14: √ | L14: √ | P14: √ | W14: √ | AB14: √ | AH14: √ | AQ14: √ | AW14: √

Sheet Kebiasaan_IC
B3: 1 Sheet untuk masing-masing rumah
A6: AYAH | L6: IBU | W6: ADIK | AH6: AYAH | AO6: IBU | AV6: ADIK
A7: AKTIVITAS (√) | D7: WAKTU (00.00-23.59) | F7: KUANTITAS BAK/BAB(√) | L7: AKTIVITAS (√) | O7: WAKTU (00.00-23.59) | Q7: KUANTITAS BAK/BAB(√) | W7: AKTIVITAS (√) | Z7: WAKTU (00.00-23.59) | AB7: KUANTITAS BAK/BAB(√) | AH7: AKTIVITAS (√) | AJ7: WAKTU (00.00-23.59) | AL7: JUMLAH PORSI | AO7: AKTIVITAS (√) | AQ7: WAKTU (00.00-23.59) | AS7: JUMLAH PORSI | AV7: AKTIVITAS (√) | AX7: WAKTU (00.00-23.59) | AZ7: JUMLAH PORSI
A8: BAK | B8: BAB | C8: MANDI | D8: JAM | E8: DURASI | F8: SANGAT BANYAK | G8: BANYAK | H8: CUKUP | I8: SEDIKIT | J8: SANGAT SEDIKIT | L8: BAK | M8: BAB | N8: MANDI | O8: JAM | P8: DURASI | Q8: SANGAT BANYAK | R8: BANYAK | S8: CUKUP | T8: SEDIKIT | U8: SANGAT SEDIKIT | W8: BAK | X8: BAB | Y8: MANDI | Z8: JAM | AA8: DURASI | AB8: SANGAT BANYAK | AC8: BANYAK | AD8: CUKUP | AE8: SEDIKIT | AF8: SANGAT SEDIKIT | AH8: MAKAN | AI8: MINUM | AJ8: JAM | AK8: DURASI | AL8: PORSI | AM8: PORSI | AO8: MAKAN | AP8: MINUM | AQ8: JAM | AR8: DURASI | AS8: PORSI | AT8: PORSI | AV8: MAKAN | AW8: MINUM | AX8: JAM | AY8: DURASI | AZ8: PORSI | BA8: PORSI
A9: √ | C9: √ | D9: 07.00 | E9: 10 | H9: √ | N9: √ | O9: 06.30 | P9: 10 | S9: √ | W9: √ | Z9: 06.00 | AD9: √ | AH9: √ | AJ9: 09.00 | AK9: 10 | AL9: 1 PRG | AO9: √ | AQ9: 08.30 | AR9: 10 | AS9: 1 PRG | AV9: √ | AX9: 09.00 | AY9: 20 | AZ9: 1/2 PRG
A10: √ | D10: 09.00 | H10: √ | L10: √ | O10: 07.30 | S10: √ | Z10: 08.00 | AD10: √ | AJ10: 13.00 | AK10: 10 | AL10: 1 PRG | AQ10: 14.00 | AR10: 10 | AS10: 1 PRG | AX10: 13.00 | AY10: 20 | AZ10: 1/2 PRG
A11: √ | D11: 11.00 | H11: √ | L11: √ | O11: 10.00 | S11: √ | Z11: 10.00 | AD11: √ | AJ11: 18.30 | AK11: 10 | AL11: 1 PRG | AQ11: 18.30 | AR11: 10 | AS11: 1 PRG | AX11: 15.00 | AY11: 20 | AZ11: 1/4 PRG
A12: √ | D12: 12.00 | H12: √ | L12: √ | O12: 12.30 | S12: √ | Z12: 12.00 | AD12: √ | AX12: 18.30 | AY12: 20 | AZ12: 1/2 PRG
A13: √ | D13: 14.00 | H13: √ | L13: √ | O13: 14.30 | S13: √ | Z13: 14.00 | AD13: √ | AI13: √ | AJ13: 07.00 | AL13: …PRG | AM13: 1 GLS | AP13: √ | AQ13: 08.00 | AS13: …PRG | AT13: 1 GLS
A14: √ | D14: 16.00 | H14: √ | L14: √ | O14: 16.15 | S14: √ | Z14: 16.00 | AD14: √ | AJ14: 08.00 | AL14: …PRG | AM14: 1 GLS | AQ14: 09.00 | AS14: …PRG | AT14: 1 GLS | AW14: √ | AX14: 08.00 | BA14: 1/2 GLS
A15: √ | C15: √ | D15: 18.00 | E15: 10 | H15: √ | L15: √ | N15: √ | O15: 17.30 | P15: 10 | S15: √ | Z15: 17.00 | AD15: √ | AH15: √ | AJ15: 09.00 | AK15: 10 | AL15: …PRG | AM15: 1 GLS | AQ15: 10.00 | AS15: …PRG | AT15: 1 GLS | AX15: 10.00 | BA15: 1/2 GLS
A16: √ | D16: 19.00 | H16: √ | L16: √ | O16: 18.45 | S16: √ | Z16: 19.00 | AD16: √
A17: √ | D17: 20.00 | H17: √ | L17: √ | O17: 20.30 | Z17: 21.00 | AD17: √ | AJ17: 10.00 | AL17: …PRG | AM17: 1 GLS | AQ17: 11.00 | AS17: …PRG | AT17: 1 GLS | AX17: 12.00 | BA17: 1/4 GLS
B18: √ | D18: 07.00 | H18: √ | AJ18: 11.00 | AL18: …PRG | AM18: 1 GLS | AQ18: 12.00 | AS18: …PRG | AT18: 1 GLS | AX18: 13.30 | BA18: 1/4 GLS
Y19: √ | Z19: 07.30 | AD19: √ | AJ19: 12.00 | AL19: …PRG | AM19: 1 GLS | AQ19: 13.00 | AS19: …PRG | AT19: 1 GLS | AX19: 15.00 | BA19: 1/2 GLS
A20: √ | D20: 03.00 | H20: √ | Y20: √ | Z20: 16.00 | AD20: √ | AX20: 16.30 | BA20: 1/2 GLS
AX21: 18.00 | BA21: 1/4 GLS
AJ22: 13.00 | AL22: …PRG | AM22: 1 GLS | AQ22: 14.00 | AS22: …PRG | AT22: 1 GLS
AJ23: 14.00 | AL23: …PRG | AM23: 1 GLS | AQ23: 15.00 | AS23: …PRG | AT23: 1 GLS
AJ24: 15.00 | AL24: …PRG | AM24: 1 GLS | AQ24: 16.00 | AS24: …PRG | AT24: 1 GLS
AJ25: 16.00 | AL25: …PRG | AM25: 1 GLS | AQ25: 17.00 | AS25: …PRG | AT25: 1 GLS
AJ26: 17.00 | AL26: …PRG | AM26: 1 GLS
AJ27: 19.00 | AL27: …PRG | AM27: 1 GLS
A29: KAKAK | L29: NENEK | AH29: KAKAK | AO29: NENEK
A30: AKTIVITAS (√) | D30: WAKTU (00.00-23.59) | F30: KUANTITAS BAK/BAB(√) | L30: AKTIVITAS (√) | O30: WAKTU (00.00-23.59) | Q30: KUANTITAS BAK/BAB(√) | AH30: AKTIVITAS (√) | AJ30: WAKTU (00.00-23.59) | AL30: JUMLAH PORSI | AO30: AKTIVITAS (√) | AQ30: WAKTU (00.00-23.59) | AS30: JUMLAH PORSI
A31: BAK | B31: BAB | C31: MANDI | D31: JAM | E31: DURASI | F31: SANGAT BANYAK | G31: BANYAK | H31: CUKUP | I31: SEDIKIT | J31: SANGAT SEDIKIT | L31: BAK | M31: BAB | N31: MANDI | O31: JAM | P31: DURASI | Q31: SANGAT BANYAK | R31: BANYAK | S31: CUKUP | T31: SEDIKIT | U31: SANGAT SEDIKIT | AH31: MAKAN | AI31: MINUM | AJ31: JAM | AK31: DURASI | AL31: PORSI | AM31: PORSI | AO31: MAKAN | AP31: MINUM | AQ31: JAM | AR31: DURASI | AS31: PORSI | AT31: PORSI
A32: √ | D32: 08.00 | H32: √ | L32: √ | O32: 03.00 | S32: √ | AH32: √ | AJ32: 09.00 | AK32: 15 | AL32: 1 PRG | AO32: √ | AQ32: 06.00 | AR32: 10 | AS32: 1 PRG
D33: 10.15 | H33: √ | O33: 06.00 | S33: √ | AJ33: 13.00 | AK33: 15 | AL33: 1 PRG | AQ33: 12.00 | AR33: 10 | AS33: 1 PRG
D34: 11.00 | H34: √ | O34: 09.00 | S34: √ | AJ34: 15.00 | AK34: 15 | AL34: 1 PRG | AQ34: 18.30 | AR34: 10 | AS34: 1 PRG
D35: 13.30 | H35: √ | O35: 13.00 | S35: √ | AJ35: 18.30 | AK35: 15 | AL35: 1 PRG
D36: 15.00 | H36: √ | O36: 15.00 | S36: √
D37: 17.30 | H37: √ | O37: 18.00 | S37: √ | AI37: √ | AJ37: 07.45 | AM37: 1 GLS | AP37: √ | AQ37: 07.30 | AT37: 1 GLS
D38: 21.00 | H38: √ | O38: 23.00 | S38: √ | AJ38: 09.00 | AM38: 1 GLS | AQ38: 09.00 | AT38: 1 GLS
AJ39: 11.30 | AM39: 1 GLS | AQ39: 12.00 | AT39: 1 GLS
C40: √ | D40: 08.00 | E40: 5 | M40: √ | O40: 06.00 | S40: √ | AJ40: 12.30 | AM40: 1 GLS | AQ40: 14.00 | AT40: 1 GLS
C41: √ | D41: 17.20 | E41: 5 | AJ41: 14.00 | AM41: 1 GLS | AQ41: 15.30 | AT41: 1 GLS
N42: √ | O42: 06.00 | P42: 5 | S42: √ | AJ42: 15.30 | AM42: 1 GLS | AQ42: 16.30 | AT42: 1 GLS
N43: √ | O43: 16.30 | P43: 5 | S43: √ | AJ43: 17.00 | AM43: 1 GLS | AQ43: 18.45 | AT43: 1 GLS
AJ44: 19.00 | AM44: 1 GLS
A50: ADIK
...

Sheet Peralatan_IC
B3: 1 Sheet untuk masing-masing rumah
B6: Ruang dan alat listrik bisa ditambah/ diperbaiki
B8: No | C8: Ruang | D8: Alat | E8: Jumlah | F8: Waktu | H8: Durasi (jam) | I8: Durasi (menit) | J8: Daya (Watt) | K8: Keterangan
F9: Nyala | G9: Mati
B11: 1 | C11: Rg. Tamu | D11: Lampu | E11: 1 | F11: 0.625 | G11: 0.91666667 | H11: =G11-F11 -> 0.29166667 | I11: =H11*1440 -> 420 | J11: 50
D13: Laptop | E13: 1 | F13: 0.70833333 | G13: 0.83333333 | H13: =G13-F13 -> 0.125 | I13: =H13*1440 -> 180 | J13: 18.8
B15: 2 | C15: Rg. Keluarga | D15: Lampu | E15: 1 | F15: 0.625 | G15: 0.91666667 | H15: =G15-F15 -> 0.29166667 | I15: =H15*1440 -> 420 | J15: 40
E16: 1 | F16: 0.29166667 | G16: 0.91666667 | H16: =G16-F16 -> 0.625 | I16: =H16*1440 -> 900 | J16: 15
D18: Kipas | E18: 1 | F18: 0.41666667 | G18: 0.91666667 | H18: =G18-F18 -> 0.5 | I18: =H18*1440 -> 720
D19: TV | E19: 1 | F19: 0.75 | G19: 0.91666667 | H19: =G19-F19 -> 0.16666667 | I19: =H19*1440 -> 240 | J19: 48.3
D20: Radio | E20: 1 | J20: 2.9
D21: TV Kabel | E21: 1 | F21: 0.75 | G21: 0.91666667 | H21: =G21-F21 -> 0.16666667 | I21: =H21*1440 -> 240 | J21: 7.7
B23: 3 | C23: Kamar Depan | D23: Lampu | E23: 1 | F23: 0.70833333 | G23: 0.91666667 | H23: =G23-F23 -> 0.20833333 | I23: =H23*1440 -> 300 | J23: 15
E24: 1 | F24: 0.91666667 | G24: 1 | H24: =G24-F24 -> 0.083333333 | I24: =H24*1440 -> 120 | J24: 5
D26: AC | E26: 1 | F26: 0.875 | G26: 1 | H26: =G26-F26 -> 0.125 | I26: =H26*1440 -> 180 | J26: 657.3
D27: Kipas | E27: 1 | F27: 0.33333333 | G27: 0.41666667 | H27: =G27-F27 -> 0.083333333 | I27: =H27*1440 -> 120 | J27: 40.6
D28: HP | E28: 1 | F28: 0.70833333 | G28: 0.75 | H28: =G28-F28 -> 0.041666667 | I28: =H28*1440 -> 60 | J28: 2.3
D29: HP | E29: 1 | F29: 0.75 | G29: 0.79166667 | H29: =G29-F29 -> 0.041666667 | I29: =H29*1440 -> 60 | J29: 2.4 | K29: Dimatikan 2-3x (10-20 menit)
D30: HP | E30: 1 | F30: 0.79166667 | G30: 0.83333333 | H30: =G30-F30 -> 0.041666667 | I30: =H30*1440 -> 60 | J30: 2.3
B32: 4 | C32: Kamar Tengah 1 | D32: Lampu | E32: 1 | F32: 0.70833333 | G32: 0.91666667 | H32: =G32-F32 -> 0.20833333 | I32: =H32*1440 -> 300 | J32: 15
E33: 1 | F33: 0.91666667 | G33: 1 | H33: =G33-F33 -> 0.083333333 | I33: =H33*1440 -> 120 | J33: 5
B35: 5 | C35: Kamar Tengah 2 | D35: Lampu | E35: 1 | F35: 0.70833333 | G35: 0.91666667 | H35: =G35-F35 -> 0.20833333 | I35: =H35*1440 -> 300 | J35: 15
E36: 1 | F36: 0.91666667 | G36: 1 | H36: =G36-F36 -> 0.083333333 | I36: =H36*1440 -> 120 | J36: 5
C38: dimana TV03? | D38: TV | E38: 1 | J38: 59.7 | K38: Standby power/tidak nyala
D39: Kipas | E39: 1 | F39: 0.74305556 | G39: 0.75694444 | H39: =G39-F39 -> 0.013888889 | I39: =H39*1440 -> 20 | J39: 37
D40: Catokan | E40: 1 | J40: 81.1
B41: 6 | C41: Koridor | D41: Lampu | E41: 1 | F41: 0.71180556 | G41: 0.91666667 | H41: =G41-F41 -> 0.20486111 | I41: =H41*1440 -> 295 | J41: 10
B44: 7 | C44: WC | D44: Lampu | E44: 1 | F44: 0.62847222 | G44: 0.91666667 | H44: =G44-F44 -> 0.28819444 | I44: =H44*1440 -> 415 | J44: 15
B47: 8 | C47: Gudang | D47: Lampu | E47: 1 | F47: 0.70833333 | G47: 0.91666667 | H47: =G47-F47 -> 0.20833333 | I47: =H47*1440 -> 300 | J47: 10
D49: Setrika | E49: 1 | I49: 393
B51: 9 | C51: Rg. Makan | D51: Lampu | E51: 1 | F51: 0.70833333 | G51: 0.91666667 | H51: =G51-F51 -> 0.20833333 | I51: =H51*1440 -> 300 | J51: 15
D53: Kulkas | E53: 1 | F53: 0 | G53: 1 | H53: =G53-F53 -> 1 | I53: =H53*1440 -> 1440 | J53: 79
D54: Rice Cooker | E54: 1 | F54: 0.20833333 | G54: 0.70833333 | H54: =G54-F54 -> 0.5 | I54: =H54*1440 -> 720 | J54: 31.6
D55: Blender | E55: 1 | F55: 0.25 | G55: 0.25347222 | H55: =G55-F55 -> 0.0034722222 | I55: =H55*1440 -> 5 | J55: 101.5
D56: Pompa | E56: 1 | J56: 125
B58: 10 | C58: Dapur | D58: Lampu | E58: 1 | F58: 0 | G58: 1 | H58: =G58-F58 -> 1 | I58: =H58*1440 -> 1440 | J58: 10
E59: 1 | F59: 0 | G59: 1 | H59: =G59-F59 -> 1 | I59: =H59*1440 -> 1440 | J59: 10
D61: Kulkas | E61: 1 | F61: 0 | G61: 1 | H61: =G61-F61 -> 1 | I61: =H61*1440 -> 1440 | J61: 78.8
D62: Rice Cooker | E62: 1 | F62: 0.70833333 | G62: 0.91666667 | H62: =G62-F62 -> 0.20833333 | I62: =H62*1440 -> 300 | J62: 73.2
B64: 11 | C64: Rg. Cuci | D64: Lampu | E64: 1 | F64: 0 | G64: 1 | H64: =G64-F64 -> 1 | I64: =H64*1440 -> 1440 | J64: 15
...

Sheet Mesin_IC
C3: 1 Sheet untuk masing-masing rumah
B5: CONTOH
B6: COMPONENTS
B7: AGENT
B8: MACHINES :
B9: No | C9: Variable i | D9: Variable ii | E9: Parameter | F9: Note
B10: A. Machine Attribute
C11: Name | E11: Mesin Cuci
C12: Code | E12: RCC01-WM01 | H12: Nama objek pada sheet Current State didahului dengan nama ruang: RCC01-WM01 (Ruang belakang 1 - Mesin Cuci 1)
C13: Appearance
D14: Color | E14: 0
D15: Reflectivity | E15: 0 | F15: %
C16: Date Created | F16: tanggal dibeli | H16: Tanggal diproduksi menentukan umur objek
C17: Life Spand | E17: =15*12*30 -> 5400 | F17: hari | H17: Masa pemakaian yang disarankan sesuai spesifikasi produk. Tahun dikonversi ke hari
C18: Status | E18: ='Data Lingkungan_IC'!W21 -> on | H18: Status on/off replace setiap digunakan dari sheet Current State, setiap "on" akan menambah 1 poin ke baris Age kolom Parameter
C19: Age | E19: 12 | F19: hari | H19: Tambahan 1 poin, replace setiap digunakan "on" dari sheet Current State
C20: Sisa Umur | E20: =E17-E19-(E21+E23)/2*10 -> 5387 | F20: hari | H20: Sisa umur = Life Spand - Age - (Cumulative Maintenance + Cleanliness level)/2 X 10
C21: Maintenance | D21: Current State | E21: =((E19/E17)*45-E22) -> 0.1 | F21: level | H21: Tingkat perlu maintance berkala. Contoh setiap 120 hari (4 bulan) atau 45 kali maintenance dalam 15 tahun = ((Age/Life Spand) x Jumlah maintenance yang disarankan selama life spand - Sub kumulatif maintenance dilakukan)
D22: Cumulative | E22: 0 | F22: kumulatif maintenance | H22: Jumlah maintenance yang dilakukan. Setiap maintenance tambah 1 poin dari Current State
C23: Cleanliness | D23: Current State | E23: ='Data Lingkungan_IC'!Z21 -> 0.1 | F23: level | H23: Tingkat kotor replace dari sheet Current State. Setiap kali digunakan mendapat 0.1 poin. Jika ada aktivitas membersihkan, poin berkurang = 0 (bersih)
C24: Condition | E24: =(E20/E17) -> 0.99759259 | F24: rusak, kurang bagus, bagus, sangat bagus | H24: Skala kondisi = Rusak < 0.25 < Kurang bagus < 0.5 < Bagus < 0.75 < Sangat bagus < 1 = Sisa Umur/Life Spand
C25: Machine
D26: Function | E26: Komputasi
D27: Energy Type | E27: Listrik
D28: Energy Consumption | E28: 0.0188 | F28: kw/j | H28: Survei alat (sudah disurvei)
D29: Consumption Time | E29: ='Data Lingkungan_IC'!Y38 -> 30 | F29: jam | H29: Replace dari sheet Current State
D30: Sub Cumulative Con. | E30: =E29*E28 -> 0.564 | H30: Consumption Time x Energy Consumption
D31: Cumulative | E31: =E30 -> 0.564 | F31: kumulatif konsumsi energi | H31: Penjumlahan Sub Cumulative
D32: Capacity | E32: 0 | F32: btu/jam | H32: Jika tidak ada = 0
B35: ABM | H35: ABM | N35: ABM | T35: ABM | Z35: ABM | AF35: ABM
B36: COMPONENTS | H36: COMPONENTS | N36: COMPONENTS | T36: COMPONENTS | Z36: COMPONENTS | AF36: COMPONENTS
B37: AGENT | H37: AGENT | N37: AGENT | T37: AGENT | Z37: AGENT | AF37: AGENT
B38: MACHINES : | H38: MACHINES : | N38: MACHINES : | T38: MACHINES : | Z38: MACHINES : | AF38: MACHINES :
B39: No | C39: Variable i | D39: Variable ii | E39: Parameter | F39: Note | H39: No | I39: Variable i | J39: Variable ii | K39: Parameter | L39: Note | N39: No | O39: Variable i | P39: Variable ii | Q39: Parameter | R39: Note | T39: No | U39: Variable i | V39: Variable ii | W39: Parameter | X39: Note | Z39: No | AA39: Variable i | AB39: Variable ii | AC39: Parameter | AD39: Note | AF39: No | AG39: Variable i | AH39: Variable ii | AI39: Parameter | AJ39: Note
B40: A. Machine Attribute | H40: A. Machine Attribute | N40: A. Machine Attribute | T40: A. Machine Attribute | Z40: A. Machine Attribute | AF40: A. Machine Attribute
C41: Name | E41: TV | I41: Name | K41: Radio | O41: Name | Q41: AC | U41: Name | W41: Kipas Angin | AA41: Name | AC41: Hair Straightener | AG41: Name | AI41: Refrigerator
C42: Code | E42: RKG01-TV01 | I42: Code | K42: RTU02-RA01 | O42: Code | Q42: RTU01-AC01 | U42: Code | W42: RKG01-KP01 | AA42: Code | AC42: RTU02-HS01 | AG42: Code | AI42: RDP01-RE01
C43: Appearance | I43: Appearance | O43: Appearance | U43: Appearance | AA43: Appearance | AG43: Appearance
D44: Color | J44: Color | P44: Color | V44: Color | AB44: Color | AH44: Color
D45: Reflectivity | F45: % | J45: Reflectivity | L45: % | P45: Reflectivity | R45: % | V45: Reflectivity | X45: % | AB45: Reflectivity | AD45: % | AH45: Reflectivity | AJ45: %
...

Sheet Lampu_IC
C3: 1 Sheet untuk masing-masing rumah
B5: ABM | H5: ABM | N5: ABM
B6: COMPONENTS | H6: COMPONENTS | N6: COMPONENTS
B7: AGENT | H7: AGENT | N7: AGENT
B8: MACHINES : | H8: MACHINES : | N8: MACHINES :
B9: No | C9: Variable i | D9: Variable ii | E9: Parameter | F9: Note | H9: No | I9: Variable i | J9: Variable ii | K9: Parameter | L9: Note | N9: No | O9: Variable i | P9: Variable ii | Q9: Parameter | R9: Note
B10: A. Machine Attribute | H10: A. Machine Attribute | N10: A. Machine Attribute
C11: Name | E11: LA01 | I11: Name | K11: LA02 | O11: Name | Q11: LA04
C12: Code | E12: RGS01-LA01 | I12: Code | K12: RTS01-LA02 | O12: Code | Q12: RTM01-LA04
C13: Appearance | I13: Appearance | O13: Appearance
D14: Color | E14: cool daylight | J14: Color | K14: cool daylight | P14: Color | Q14: cool daylight
D15: Reflectivity | F15: % | J15: Reflectivity | L15: % | P15: Reflectivity | R15: %
C16: Date Created | F16: tanggal dibeli | I16: Date Created | L16: tanggal dibeli | O16: Date Created | R16: tanggal dibeli
C17: Life Spand | E17: =13.5*12*30 -> 4860 | F17: hari | I17: Life Spand | K17: =13.5*12*30 -> 4860 | L17: hari | O17: Life Spand | Q17: =13.5*12*30 -> 4860 | R17: hari
C18: Status | E18: ='Data Lingkungan_IC'!N60 -> on | I18: Status | K18: ='Data Lingkungan_IC'!N60 -> on | O18: Status | Q18: ='Data Lingkungan_IC'!BA33 -> 0
C19: Age | E19: 0 | F19: hari | I19: Age | K19: 0 | L19: hari | O19: Age | Q19: 0 | R19: hari
C20: Sisa Umur | E20: =E17-E19-(E21+E23)/2*10 -> 4860 | F20: hari | I20: Sisa Umur | K20: =K17-K19-(K21+K23)/2*10 -> 4860 | L20: hari | O20: Sisa Umur | Q20: =Q17-Q19-(Q21+Q23)/2*10 -> 4860 | R20: hari
C21: Maintenance | D21: Current State | E21: =((E19/E17)*10-E22) -> 0 | F21: level | I21: Maintenance | J21: Current State | K21: =((K19/K17)*10-K22) -> 0 | L21: level | O21: Maintenance | P21: Current State | Q21: =((Q19/Q17)*10-Q22) -> 0 | R21: level
D22: Cumulative | E22: 0 | F22: kumulatif maintenance | J22: Cumulative | K22: 0 | L22: kumulatif maintenance | P22: Cumulative | Q22: 0 | R22: kumulatif maintenance
C23: Cleanliness | D23: Current State | E23: 0 | F23: level | I23: Cleanliness | J23: Current State | K23: 0 | L23: level | O23: Cleanliness | P23: Current State | Q23: 0 | R23: level
C24: Condition | E24: =(E20/E17) -> 1 | F24: rusak, kurang bagus, bagus, sangat bagus | I24: Condition | K24: =(K20/K17) -> 1 | L24: rusak, kurang bagus, bagus, sangat bagus | O24: Condition | Q24: =(Q20/Q17) -> 1 | R24: rusak, kurang bagus, bagus, sangat bagus
C25: Machine | I25: Machine | O25: Machine
D26: Function | J26: Function | P26: Function
D27: Energy Type | E27: Listrik | J27: Energy Type | K27: Listrik | P27: Energy Type | Q27: Listrik
D28: Energy Consumption | E28: =Peralatan_IC!J67/1000 -> 0.02 | F28: kw/j | J28: Energy Consumption | K28: =Peralatan_IC!J70/1000 -> 0.03 | L28: kw/j | P28: Energy Consumption | Q28: =Peralatan_IC!J11/1000 -> 0.05 | R28: kw/j
D29: Consumption Time | E29: ='Data Lingkungan_IC'!P60/60 -> 3 | F29: jam | J29: Consumption Time | K29: ='Data Lingkungan_IC'!Y60/60 -> 3 | L29: jam | P29: Consumption Time | Q29: ='Data Lingkungan_IC'!AH60/60 -> 7 | R29: jam
D30: Sub Cumulative Con. | E30: =E29*E28 -> 0.06 | J30: Sub Cumulative Con. | K30: =K29*K28 -> 0.09 | P30: Sub Cumulative Con. | Q30: =Q29*Q28 -> 0.35
D31: Cumulative | E31: =E30 -> 0.06 | F31: kumulatif konsumsi energi | J31: Cumulative | K31: =K30 -> 0.09 | L31: kumulatif konsumsi energi | P31: Cumulative | Q31: =Q30 -> 0.35 | R31: kumulatif konsumsi energi
D32: Capacity | E32: 0 | F32: btu/jam | J32: Capacity | K32: 0 | L32: btu/jam | P32: Capacity | Q32: 0 | R32: btu/jam
B35: ABM | H35: ABM
B36: COMPONENTS | H36: COMPONENTS
B37: AGENT | H37: AGENT
B38: MACHINES : | H38: MACHINES :
B39: No | C39: Variable i | D39: Variable ii | E39: Parameter | F39: Note | H39: No | I39: Variable i | J39: Variable ii | K39: Parameter | L39: Note
B40: A. Machine Attribute | H40: A. Machine Attribute
C41: Name | E41: LA03 | I41: Name | K41: LA18
C42: Code | E42: RTU01-LA03 | I42: Code | K42: RTU01-LA18
C43: Appearance | I43: Appearance
D44: Color | E44: cool daylight | J44: Color | K44: cool daylight
D45: Reflectivity | F45: % | J45: Reflectivity | L45: %
...

Sheet Dinamis_IC
B3: 1 Sheet untuk masing-masing rumah
B5: CONTOH
B6: COMPONENTS
B7: Object
B8: Dynamic
B9: No | C9: Variable i | D9: Variable ii | E9: Parameter | F9: Note
B10: A. Dynamic Object Attribute
C11: Name | E11: Pintu Garasi
C12: Code | E12: PT13
C13: Appearance
D14: Color | E14: 0
D15: Reflectivity | E15: 0 | F15: %
C16: Date Created | F16: tanggal dibeli
C17: Life Spand | E17: =15*12*30 -> 5400 | F17: hari
C18: Status | E18: on
C19: Age | E19: 120 | F19: hari
C20: Sisa Umur | E20: =E17-E19-(E21+E23)/2*10 -> 5279.5 | F20: hari
C21: Maintenance | D21: Current State | E21: =((E19/E17)*45-E22) -> 0 | F21: level
D22: Cumulative | E22: ='Data Lingkungan_IC'!Z41 -> 1 | F22: kumulatif maintenance
C23: Cleanliness | D23: Current State | E23: ='Data Lingkungan_IC'!Z21 -> 0.1 | F23: level
C24: Condition | E24: =(E20/E17) -> 0.97768519 | F24: rusak, kurang bagus, bagus, sangat bagus
C25: Size
D26: P | E26: 90 | F26: cm
D27: L | E27: 0.05 | F27: cm
D28: T | E28: 210 | F28: cm
C29: Mechanic | D29: Status | E29: tertutup | F29: tertutup/terbuka
D30: Function | E30: Lubang sirkulasi
D31: Time for Op | E31: 0.5 | F31: menit/aksi
D32: Condition 01 | E32: bagus | F32: rusak, kurag bagus, bagus, sangat bagus
D33: Compliment | E33: kunci
D34: Status compliment | E34: terkunci
B36: ABM | H36: ABM | N36: ABM | T36: ABM
B37: COMPONENTS | H37: COMPONENTS | N37: COMPONENTS | T37: COMPONENTS
B38: Object | H38: Object | N38: Object | T38: Object
B39: Dynamic | H39: Dynamic | N39: Dynamic | T39: Dynamic
B40: No | C40: Variable i | D40: Variable ii | E40: Parameter | F40: Note | H40: No | I40: Variable i | J40: Variable ii | K40: Parameter | L40: Note | N40: No | O40: Variable i | P40: Variable ii | Q40: Parameter | R40: Note | T40: No | U40: Variable i | V40: Variable ii | W40: Parameter | X40: Note
B41: A. Dynamic Object Attribute | H41: A. Dynamic Object Attribute | N41: A. Dynamic Object Attribute | T41: A. Dynamic Object Attribute
C42: Name | E42: Pintu Garasi | I42: Name | K42: Jendela Ruang Tamu | O42: Name | Q42: Lemari Kamar Tidur 1 | U42: Name | W42: Kran Kamar Mandi
C43: Code | E43: PT13 | I43: Code | K43: JD01 | O43: Code | Q43: RTU01-LM01 | U43: Code | W43: RKM01-WT03
C44: Appearance | I44: Appearance | O44: Appearance | U44: Appearance
...

Sheet Statis_IC
B3: 1 Sheet untuk masing-masing rumah
B5: CONTOH
B6: COMPONENTS
B7: Object
B8: Static
B9: No | C9: Variable i | D9: Variable ii | E9: Parameter | F9: Note
B10: A. Static Object Attribute
C11: Name | E11: Sofa Ruang Tamu
C12: Code | E12: SF01
C13: Appearance
D14: Color | E14: 0 | F14: warna dominan / kombinasi
D15: Reflectivity | E15: 0 | F15: %
C16: Date Created | F16: tanggal dibeli
C17: Life Spand | E17: =15*12*30 -> 5400 | F17: hari
C18: Status | E18: ='Data Lingkungan_IC'!AF66 -> on
C19: Age | E19: 120 | F19: hari
C20: Sisa Umur | E20: =E17-E19-(E21+E23)/2*10 -> 5280 | F20: hari
C21: Maintenance | D21: Current State | E21: =((E19/E17)*45-E22) -> 0 | F21: level
D22: Cumulative | E22: 1 | F22: kumulatif maintenance
C23: Cleanliness | D23: Current State | E23: ='Data Lingkungan_IC'!AI66 -> 0 | F23: level
C24: Condition | E24: =(E20/E17) -> 0.97777778 | F24: sangat bersih, bersih, cukup bersih, kotor, sangat kotor
C25: Size
D26: P | E26: 90 | F26: cm
D27: L | E27: 0.05 | F27: cm
D28: T | E28: 210 | F28: cm
C29: Object | D29: Status | E29: tertutup | F29: tertutup/terbuka
D30: Function | E30: Lubang sirkulasi
D31: Time for Op | E31: 0.5 | F31: menit/aksi
D32: Condition 01 | E32: bagus | F32: rusak, kurag bagus, bagus, sangat bagus
D33: Compliment | E33: kunci
D34: Status compliment | E34: terkunci
B36: ABM | H36: ABM | N36: ABM | T36: ABM
B37: COMPONENTS | H37: COMPONENTS | N37: COMPONENTS | T37: COMPONENTS
B38: Object | H38: Object | N38: Object | T38: Object
B39: Static | H39: Static | N39: Static | T39: Static
B40: No | C40: Variable i | D40: Variable ii | E40: Parameter | F40: Note | H40: No | I40: Variable i | J40: Variable ii | K40: Parameter | L40: Note | N40: No | O40: Variable i | P40: Variable ii | Q40: Parameter | R40: Note | T40: No | U40: Variable i | V40: Variable ii | W40: Parameter | X40: Note
B41: A. Static Object Attribute | H41: A. Static Object Attribute | N41: A. Static Object Attribute | T41: A. Static Object Attribute
C42: Name | E42: Bouven Dapur | I42: Name | K42: Sofa Ruang Tamu | O42: Name | Q42: Kursi Ruang Makan | U42: Name | W42: Meja Ruang Tamu
C43: Code | E43: BV02 | I43: Code | K43: RTM01-SF01 | O43: Code | Q43: RMK01-KU01 | U43: Code | W43: RTM01-MJ01
C44: Appearance | I44: Appearance | O44: Appearance | U44: Appearance
...

Sheet Utilitas_IC
B3: 1 Sheet untuk masing-masing rumah
B6: ABM
B7: ENVIRONMENT
B8: BUILDING
B9: UTILITIES
B10: No | C10: Variable i | D10: Variable ii | E10: Variable iii | F10: Parameter | G10: Note
C11: A. Power Meter
D12: Basic
B13: 1 | E13: Power Supply | F13: 900 | G13: watt
B14: 2 | E14: Price | F14: 1500 | G14: rp/kwh
B15: 3
D16: Status
B17: 4 | E17: Current Power Consumption
B18: 5 | E18: Power Cost
B19: 6 | E19: Availability
B20: 7
C22: B. Water Tank
D23: Basic
B24: 1 | E24: Water Supply | G24: m3
B25: 2 | E25: Price
B26: 3 | E26: Water Backup
D27: Status | E27: IC | F27: volume bak mandi? | H27: IC bak mandi penuh (malam hari bak diisi hingga penuh)
B28: 4 | E28: Current Water | G28: m3
B29: 5 | E29: Water Consumption
B30: 6 | E30: Current Water Backup
B31: 7 | E31: Water Backup Consumption
C33: C. Gas
D34: Basic
B35: 1 | E35: Gas Supply | F35: 3 | G35: Kg
B36: 2 | E36: Price | G36: rp
D37: Status | E37: IC | F37: 2.25
B38: 3 | E38: Current Power | F38: =F37-F39 -> 2.25
B39: 4 | E39: Power Consumption | F39: ='Data Lingkungan_IC'!DK82 -> 0
B40: 5 | E40: Current Backup
B41: 6 | E41: Power Backup Consumption
C42: C. Gas
D43: Basic
B44: 6.5714286 | E44: Gas Supply | F44: 7.5 | G44: Kg
B45: 7.3726708 | E45: Price | G45: rp
B46: 8.173913 | D46: Status
...

Sheet Data Lingkungan_IC
B2: DATA LINGKUNGAN TERKINI
B4: 1 Sheet untuk masing-masing rumah
B5: Perawatan: ada aktivitas membersihkan (mengurangi nilai kotor)
B6: Pemakaian: pada lantai=berpa kali ruang digunakan +1 setiap kali ada agen masuk ruang. Pada lanskap: waktu berjalan 24 jam, maks kotor 1=kering >> urgensi menyiram tanaman tinggi
B7: Kotor: Kondisi terkini=Pemakaian x 1 /10
D9: Jenis komponen | E9: Status "on" jika digunakan, "off" jika tidak digunakan | F9: Kondisi = replace dari Machine/ Dynamic/ Static/ Utility dalam skala angka/huruf | G9: Mesin/ Dinamis/Intensitas Cahaya/ Utilitas (waktu berjalan); Statis/ Lantai (kali pemakaian: 1 kali agen duduk, 1 kali agen masuk ruang) | H9: Setiap pemakaian +0.1 poin replace ke Machine/ Dynamic/ Static/ Utility | I9: Perawatan = replace dari Maintenance Machine/ Dynamic/ Static/ Utility | V9: Jenis komponen | W9: Status "on" jika digunakan, "off" jika tidak digunakan | X9: Kondisi = replace dari Machine/ Dynamic/ Static/ Utility dalam skala angka/ huruf | Y9: Mesin/ Dinamis/Intensitas Cahaya/ Utilitas (waktu berjalan); Statis/ Lantai (kali pemakaian: 1 kali agen duduk, 1 kali agen masuk ruang) | Z9: Setiap pemakaian +0.1 poin replace ke Machine/ Dynamic/ Static/ Utility | AA9: Perawatan = replace dari Maintenance Machine/ Dynamic/ Static/ Utility
B10: CONTOH | T10: CONTOH | AL10: CONTOH
B11: ENVIRONMENT | T11: ENVIRONMENT | AL11: ENVIRONMENT
B12: Ruang Halaman Depan 1 (RHD01) | T12: Ruang Belakang (RCC01) | AL12: Ruang Garasi 1 (RGS01)
B13: OUTDOOR CLIMATE | T13: INDOOR CLIMATE | AL13: OUTDOOR CLIMATE
B14: No | C14: Variabel | D14: Jenis | E14: Status | F14: Kondisi | G14: Pemakaian | H14: Kotor | I14: Respon ke Lingkungan | T14: No | U14: Variabel | V14: Jenis | W14: Status | X14: Kondisi | Y14: Pemakaian | Z14: Kotor | AA14: Perawatan | AL14: No | AM14: Variabel | AN14: Jenis | AO14: Status | AP14: Kondisi | AQ14: Pemakaian | AR14: Kotor | AS14: Perawatan
B15: A. | C15: Iklim | T15: A. | U15: Iklim | AL15: A. | AM15: Iklim
B16: 1 | C16: Temperatur | J16: replace data suhu luar ruang terkini | T16: 1 | U16: Temperatur | AB16: replace data suhu luar ruang terkini | AL16: 1 | AM16: Temperatur
B17: 2 | C17: Intensitas Cahaya | J17: replace data intensitas luar ruang terkini | T17: 2 | U17: Intensitas Cahaya | V17: Lampu 13 (RCC01-LA13) | AB17: replace data intensitas luar ruang terkini | AL17: 2 | AM17: Intensitas Cahaya
B18: 3 | C18: Kelembaban | J18: replace data kelembaban luar ruang terkini | V18: Lampu 15 (RCC01-LA15) | AB18: replace data intensitas luar ruang terkini | AL18: B. | AM18: Interior
B19: B. | C19: Lanskap | T19: 3 | U19: Kelembaban | AB19: replace data kelembaban luar ruang terkini | AL19: 1 | AM19: Mesin | AN19: Pompa Air 1 (RGS01-WP01) | AO19: off | AP19: =Mesin_IC!AX104 -> 0 | AR19: 0 | AS19: =Mesin_IC!AX101 -> 0
B20: 1 | C20: Mesin | J20: jika di luar ruang tidak ada mesin | T20: B. | U20: Interior | AL20: 2 | AM20: Dinamis | AN20: Pintu 13 (RGS01-PT13) | AO20: on | AP20: =Dinamis_IC!E55 -> 0.97685185 | AR20: =AR33/10 -> 0.1 | AS20: =Dinamis_IC!E21 -> 0
B21: 2 | C21: Dinamis | D21: Kran 4 (RHD01-WT04) | E21: on | F21: bagus | G21: =G32 -> 0 | J21: jika di luar ruang ada objek dinamis | T21: 1 | U21: Mesin | V21: Mesin Cuci 1 (RCC01-WM01) | W21: on | X21: =Mesin_IC!E24 -> 0.99759259 | Y21: =Y38 -> 30 | Z21: =Z38/10 -> 0.1 | AA21: =Mesin_IC!E21 -> 0.1 | AB21: aktivitas menggunakan mesin setiap 1 cycle selesai akan mereplace +0.1 poin ke cleanliness sheet machine | AL21: 3 | AM21: Statis
B22: 3 | C22: Statis | D22: Tanaman | F22: sangat kering, kering, basah, sangat basah | G22: =H22 -> 1 | H22: =1-I22 -> 1 | I22: =H32 -> 0 | J22: setelah selesai disiram, kotor = 0, perawatan = 0, waktu kembali mundur ke 0, jika baru 0.5, tetap dianggap belum selesai menyiram | V22: Mesin Cuci 2 (RCC01-WM02) | AL22: C. | AM22: Konstruksi
B23: C. | C23: Konstruksi | T23: 2 | U23: Dinamis | V23: Kran 2 (RCC01-WT02) | AL23: 1 | AM23: Plafond
B24: 3 | C24: Lantai | D24: Lantai 14 (RHD01-LT14) | G24: =H24 -> 1 | H24: =1-I24 -> 1 | I24: =H35 -> 0 | J24: Lantai pada halaman/ taman berkaitan dg kecepatan angin. Sementara kecepatan angin tidak dipakai, hanya +1 poin setiap agen beraktivitas di halaman/taman | V24: Pintu 12 (RCC01-PT12) | AL24: 2 | AM24: Dinding
B25: D. | C25: Utilitas | T25: 3 | U25: Statis | AL25: 3 | AM25: Lantai | AN25: Lantai 13 (RGS01-LT13) | AO25: =AO31 -> 0.1
B26: 1 | C26: Listrik | T26: C. | U26: Konstruksi | AL26: D. | AM26: Utilitas
B27: 2 | C27: Air | T27: 1 | U27: Plafond | AL27: 1 | AM27: Listrik
B28: 3 | C28: Gas | T28: 2 | U28: Dinding | V28: Dinding 10 (RCC01-D10) | AL28: 2 | AM28: Air
B29: E. | C29: Aktifitas | V29: Dinding 11 (RCC01-D11) | AL29: 3 | AM29: Gas
B30: 1 | C30: Jenis Aktifitas | D30: menyiram tanaman | T30: 3 | U30: Lantai | V30: Lantai 12 (RCC01-LT12) | Z30: =W36+W39 -> 0.2 | AL30: E. | AM30: Aktifitas
B31: 2 | C31: Siapa terlibat | D31: IB21 | T31: D. | U31: Utilitas | AL31: 1 | AM31: Jenis Aktifitas | AN31: Memarkir kendaraan | AO31: 0.1
B32: 3 | C32: waktu aktifitas berjalan | D32: 15 | G32: 0 | H32: =G32/D32 -> 0 | T32: 1 | U32: Listrik | V32: Saklar 18 (RCC01-SK18) | AL32: 2 | AM32: Siapa terlibat | AN32: Ayah (AY21)
B33: 1 | C33: Jenis Aktifitas | D33: menyapu halaman | T33: 2 | U33: Air | AL33: 3 | AM33: waktu aktifitas berjalan | AN33: 10 | AQ33: 10 | AR33: =AQ33/AN33 -> 1
B34: 2 | C34: Siapa terlibat | D34: NK21 | T34: 3 | U34: Gas | V34: Gas 2 (RCC01-GS02)
B35: 3 | C35: waktu aktifitas berjalan | D35: 15 | G35: 0 | H35: =G35/D35 -> 0 | T35: E. | U35: Aktifitas
D36: waktu yang diperlukan replace dari aktivitas yang terpilih dan akan dijalankan | G36: waktu berjalan | H36: % akt = waktu berjalan/waktu yang diperlukan | T36: 1 | U36: Jenis Aktifitas | V36: Mencuci pakaian | W36: 0.1 | AB36: aktivitas menggunakan mesin setiap 1 cycle selesai akan +1 poin ke kotor
T37: 2 | U37: Siapa terlibat | V37: IB21
T38: 3 | U38: waktu aktifitas berjalan | V38: 30 | Y38: 30 | Z38: =Y38/V38 -> 1
T39: 1 | U39: Jenis Aktifitas | V39: Membersihkan mesin cuci | W39: 0.1 | AB39: aktivitas membersihkan (perawatan) setiap 1 cycle selesai akan +1 poin ke cumulative maintenance sheet machine
T40: 2 | U40: Siapa terlibat | V40: AY21
T41: 3 | U41: waktu aktifitas berjalan | V41: 60 | Y41: 60 | Z41: =Y41/V41 -> 1
B51: Current State IC (sebelum tidur malam) setiap ruang di Rumah 2
B53: ABM | K53: ABM | T53: ABM | AC53: ABM | AL53: ABM | AU53: ABM | BD53: ABM | BM53: ABM | BV53: ABM | CE53: ABM | CN53: ABM | CW53: ABM | DF53: ABM | DO53: ABM
...
