Workbook

Sheet EQ
B1: Ruang dan alat listrik bisa ditambah/ diperbaiki
B3: No | C3: Ruang | D3: Alat | E3: Jumlah | F3: Waktu | H3: Durasi (jam) | I3: Durasi (menit) | J3: LINK Durasi (jam) | K3: Daya (Watt) | L3: LINK Daya (KWj) | M3: Keterangan
F4: Nyala | G4: Mati
B6: 1 | C6: Rg. Tamu | D6: Lampu | E6: 1 | F6: 0.625 | G6: 0.91666667 | H6: =G6-F6 -> 0.29166667 | I6: =H6*1440 -> 420 | J6: =I6/60 -> 7 | K6: 50 | L6: =K6/1000 -> 0.05
D8: Laptop | E8: 1 | F8: 0.70833333 | G8: 0.83333333 | H8: =G8-F8 -> 0.125 | I8: =H8*1440 -> 180 | J8: =I8/60 -> 3 | K8: 18.8 | L8: =K8/1000 -> 0.0188
B10: 2 | C10: Rg. Keluarga | D10: Lampu | E10: 1 | F10: 0.625 | G10: 0.91666667 | H10: =G10-F10 -> 0.29166667 | I10: =H10*1440 -> 420 | J10: =I10/60 -> 7 | K10: 40 | L10: =K10/1000 -> 0.04
E11: 1 | F11: 0.29166667 | G11: 0.91666667 | H11: =G11-F11 -> 0.625 | I11: =H11*1440 -> 900 | J11: =I11/60 -> 15 | K11: 15 | L11: =K11/1000 -> 0.015
D13: Kipas | E13: 1 | F13: 0.41666667 | G13: 0.91666667 | H13: =G13-F13 -> 0.5 | I13: =H13*1440 -> 720 | J13: =I13/60 -> 12 | K13: 30 | L13: =K13/1000 -> 0.03
D14: TV | E14: 1 | F14: 0.75 | G14: 0.91666667 | H14: =G14-F14 -> 0.16666667 | I14: =H14*1440 -> 240 | J14: =I14/60 -> 4 | K14: 48.3 | L14: =K14/1000 -> 0.0483
D15: Radio | E15: 1 | J15: =I15/60 -> 0 | K15: 2.9 | L15: =K15/1000 -> 0.0029
D16: TV Kabel | E16: 1 | F16: 0.75 | G16: 0.91666667 | H16: =G16-F16 -> 0.16666667 | I16: =H16*1440 -> 240 | J16: =I16/60 -> 4 | K16: 7.7 | L16: =K16/1000 -> 0.0077
B18: 3 | C18: Kamar Depan | D18: Lampu | E18: 1 | F18: 0.70833333 | G18: 0.91666667 | H18: =G18-F18 -> 0.20833333 | I18: =H18*1440 -> 300 | J18: =I18/60 -> 5 | K18: 15 | L18: =K18/1000 -> 0.015
F19: 0.91666667 | G19: 1.25 | H19: =G19-F19 -> 0.33333333 | I19: =H19*1440 -> 480 | J19: =I19/60 -> 8 | K19: 5 | L19: =K19/1000 -> 0.005
D21: AC | E21: 1 | F21: 0.875 | G21: 1 | H21: =G21-F21 -> 0.125 | I21: =H21*1440 -> 180 | J21: =I21/60 -> 3 | K21: 657.3 | L21: =K21/1000 -> 0.6573
D22: Kipas | E22: 1 | F22: 0.33333333 | G22: 0.41666667 | H22: =G22-F22 -> 0.083333333 | I22: =H22*1440 -> 120 | J22: =I22/60 -> 2 | K22: 40.6 | L22: =K22/1000 -> 0.0406
D23: HP | E23: 1 | F23: 0.70833333 | G23: 0.75 | H23: =G23-F23 -> 0.041666667 | I23: =H23*1440 -> 60 | J23: =I23/60 -> 1 | K23: 2.3 | L23: =K23/1000 -> 0.0023
D24: HP | E24: 1 | F24: 0.75 | G24: 0.79166667 | H24: =G24-F24 -> 0.041666667 | I24: =H24*1440 -> 60 | J24: =I24/60 -> 1 | K24: 2.4 | L24: =K24/1000 -> 0.0024 | M24: Dimatikan 2-3x (10-20 menit)
D25: HP | E25: 1 | F25: 0.79166667 | G25: 0.83333333 | H25: =G25-F25 -> 0.041666667 | I25: =H25*1440 -> 60 | J25: =I25/60 -> 1 | K25: 2.3 | L25: =K25/1000 -> 0.0023
B27: 4 | C27: Kamar Tengah 1 | D27: Lampu | E27: 1 | F27: 0.70833333 | G27: 0.91666667 | H27: =G27-F27 -> 0.20833333 | I27: =H27*1440 -> 300 | J27: =I27/60 -> 5 | K27: 15 | L27: =K27/1000 -> 0.015
F28: 0.91666667 | G28: 1 | H28: =G28-F28 -> 0.083333333 | I28: =H28*1440 -> 120 | J28: =I28/60 -> 2 | K28: 5 | L28: =K28/1000 -> 0.005
J29: =I29/60 -> 0 | L29: =K29/1000 -> 0
B30: 5 | C30: Kamar Tengah 2 | D30: Lampu | E30: 1 | F30: 0.70833333 | G30: 0.91666667 | H30: =G30-F30 -> 0.20833333 | I30: =H30*1440 -> 300 | J30: =I30/60 -> 5 | K30: 15 | L30: =K30/1000 -> 0.015
E31: 1 | F31: 0.91666667 | G31: 1 | H31: =G31-F31 -> 0.083333333 | I31: =H31*1440 -> 120 | J31: =I31/60 -> 2 | K31: 5 | L31: =K31/1000 -> 0.005
D33: TV | E33: 1 | J33: =I33/60 -> 0 | K33: 59.7 | L33: =K33/1000 -> 0.0597 | M33: Standby power/tidak nyala
D34: Kipas | E34: 1 | F34: 0.74305556 | G34: 0.75694444 | H34: =G34-F34 -> 0.013888889 | I34: =H34*1440 -> 20 | J34: =I34/60 -> 0.33333333 | K34: 37 | L34: =K34/1000 -> 0.037
D35: Catokan | E35: 1 | J35: =I35/60 -> 0 | K35: 81.1 | L35: =K35/1000 -> 0.0811
B36: 6 | C36: Koridor | D36: Lampu | E36: 1 | F36: 0.71180556 | G36: 0.91666667 | H36: =G36-F36 -> 0.20486111 | I36: =H36*1440 -> 295 | J36: =I36/60 -> 4.9166667 | K36: 10 | L36: =K36/1000 -> 0.01
J37: =I37/60 -> 0 | L37: =K37/1000 -> 0
B39: 7 | C39: WC | D39: Lampu | E39: 1 | F39: 0.62847222 | G39: 0.91666667 | H39: =G39-F39 -> 0.28819444 | I39: =H39*1440 -> 415 | J39: =I39/60 -> 6.9166667 | K39: 15 | L39: =K39/1000 -> 0.015
J40: =I40/60 -> 0 | L40: =K40/1000 -> 0
B42: 8 | C42: Gudang | D42: Lampu | E42: 1 | F42: 0.70833333 | G42: 0.91666667 | H42: =G42-F42 -> 0.20833333 | I42: =H42*1440 -> 300 | J42: =I42/60 -> 5 | K42: 10 | L42: =K42/1000 -> 0.01
D44: Setrika | E44: 1 | I44: 393 | J44: =I44/60 -> 6.55 | K44: 350 | L44: =K44/1000 -> 0.35
B46: 9 | C46: Rg. Makan | D46: Lampu | E46: 1 | F46: 0.70833333 | G46: 0.91666667 | H46: =G46-F46 -> 0.20833333 | I46: =H46*1440 -> 300 | J46: =I46/60 -> 5 | K46: 15 | L46: =K46/1000 -> 0.015
D48: Kulkas | E48: 1 | F48: 0 | G48: 1 | H48: =G48-F48 -> 1 | I48: =H48*1440 -> 1440 | J48: =I48/60 -> 24 | K48: 79 | L48: =K48/1000 -> 0.079
D49: Rice Cooker | E49: 1 | F49: 0.20833333 | G49: 0.70833333 | H49: =G49-F49 -> 0.5 | I49: =H49*1440 -> 720 | J49: =I49/60 -> 12 | K49: 31.6 | L49: =K49/1000 -> 0.0316
D50: Blender | E50: 1 | F50: 0.25 | G50: 0.25347222 | H50: =G50-F50 -> 0.0034722222 | I50: =H50*1440 -> 5 | J50: =I50/60 -> 0.083333333 | K50: 101.5 | L50: =K50/1000 -> 0.1015
D51: Pompa | E51: 1 | J51: =I51/60 -> 0 | K51: 125 | L51: =K51/1000 -> 0.125
B53: 10 | C53: Dapur | D53: Lampu | E53: 1 | F53: 0 | G53: 1 | H53: =G53-F53 -> 1 | I53: =H53*1440 -> 1440 | J53: =I53/60 -> 24 | K53: 10 | L53: =K53/1000 -> 0.01
E54: 1 | F54: 0 | G54: 1 | H54: =G54-F54 -> 1 | I54: =H54*1440 -> 1440 | J54: =I54/60 -> 24 | K54: 10 | L54: =K54/1000 -> 0.01
D56: Kulkas | E56: 1 | F56: 0 | G56: 1 | H56: =G56-F56 -> 1 | I56: =H56*1440 -> 1440 | J56: =I56/60 -> 24 | K56: 78.8 | L56: =K56/1000 -> 0.0788
...

Sheet AO-ALL
B2: CONTOH
B3: COMPONENTS
B4: ACTIVE OBJECT
B5: No | C5: Variable i | D5: Variable ii | E5: Parameter | F5: Note
B6: A. Active Attribute
C7: Name | E7: Mesin Cuci
C8: Code | E8: RCC01-WM01 | H8: Nama objek pada sheet Current State didahului dengan nama ruang: RCC01-WM01 (Ruang Cuci 1 - Mesin Cuci 1)
C9: Date Created | F9: tanggal dibeli | H9: Tanggal diproduksi menentukan umur objek
C10: Lifespan | E10: =15*12*30 -> 5400 | F10: hari | H10: Masa pemakaian yang disarankan sesuai spesifikasi produk. Tahun dikonversi ke hari
C11: Age | E11: 12 | F11: hari | H11: Tambahan 1 poin, replace setiap digunakan "on" dari sheet DL
C12: Sisa Umur | E12: =E10-E11-(E13+E15)/2*10 -> 5387 | F12: hari | H12: Sisa umur = Lifespan - Age - (Total Cumulative Energy Consumption Maintenance + Cleanliness level)/2 X 10
C13: Maintenance | D13: Current State | E13: =((E11/E10)*45-E14) -> 0.1 | F13: level | H13: Tingkat perlu maintance berkala. Contoh setiap 120 hari (4 bulan) atau 45 kali maintenance dalam 15 tahun = ((Age/Lifespan) x Jumlah maintenance yang disarankan selama Lifespan - Sub kumulatif maintenance dilakukan)
D14: Total Cumulative Maintenance | E14: 0 | F14: kumulatif maintenance | H14: Jumlah maintenance yang dilakukan. Setiap maintenance tambah 1 poin dari Current State
C15: Cleanliness | D15: Current State | E15: ='[1]Data Lingkungan_IC'!Z21 -> 0.1 | F15: level | H15: Tingkat kotor replace dari sheet DL. Setiap kali digunakan mendapat 0.1 poin. Jika ada aktivitas membersihkan, poin berkurang = 0 (bersih)
C16: Condition | E16: =(E12/E10) -> 0.99759259 | F16: rusak, kurang bagus, bagus, sangat bagus | H16: Skala kondisi = Rusak < 0.25 < Kurang bagus < 0.5 < Bagus < 0.75 < Sangat bagus < 1 = Sisa Umur/Lifespan
C17: Machine Activity | D17: Function | E17: Cleaning
D18: Status | E18: off | H18: Status on/off replace setiap digunakan dari sheet DL, setiap "on" akan menambah 1 poin ke baris Age kolom Parameter
D19: Heat Emission | F19: degC
D20: Energy Type | E20: Listrik
D21: Energy Consumption Rate | E21: 0.0188 | F21: kw/j | H21: Survei alat (sudah disurvei)
D22: Current Consumption Time | E22: 0.5 | F22: jam | H22: Replace dari sheet DL
D23: Current Energy Consumption | E23: =E22*E21 -> 0.0094 | H23: Current Consumption Time x Energy Consumption Rate
D24: Total Cumulative Energy Consumption | E24: =E23 -> 0.0094 | F24: kumulatif konsumsi energi | H24: Penjumlahan Sub Total Cumulative Energy Consumption
B26: ABM | H26: ABM | N26: ABM | T26: ABM | Z26: ABM | AF26: ABM
B27: COMPONENTS | H27: COMPONENTS | N27: COMPONENTS | T27: COMPONENTS | Z27: COMPONENTS | AF27: COMPONENTS
B28: ACTIVE OBJECT | H28: ACTIVE OBJECT | N28: ACTIVE OBJECT | T28: ACTIVE OBJECT | Z28: ACTIVE OBJECT | AF28: ACTIVE OBJECT
B29: No | C29: Variable i | D29: Variable ii | E29: Parameter | F29: Note | H29: No | I29: Variable i | J29: Variable ii | K29: Parameter | L29: Note | N29: No | O29: Variable i | P29: Variable ii | Q29: Parameter | R29: Note | T29: No | U29: Variable i | V29: Variable ii | W29: Parameter | X29: Note | Z29: No | AA29: Variable i | AB29: Variable ii | AC29: Parameter | AD29: Note | AF29: No | AG29: Variable i | AH29: Variable ii | AI29: Parameter | AJ29: Note
B30: A. Active Attribute | H30: A. Active Attribute | N30: A. Active Attribute | T30: A. Active Attribute | Z30: A. Active Attribute | AF30: A. Active Attribute
C31: Name | E31: TV | I31: Name | K31: Radio | O31: Name | Q31: AC | U31: Name | W31: Kipas Angin | AA31: Name | AC31: Hair Straightener | AG31: Name | AI31: Refrigerator
C32: Code | E32: RKG01-TV01 | I32: Code | K32: RTU02-RA01 | O32: Code | Q32: RTU01-AC01 | U32: Code | W32: RKG01-KP01 | AA32: Code | AC32: RTU02-HS01 | AG32: Code | AI32: RDP01-RE01
C33: Date Created | F33: tanggal dibeli | I33: Date Created | L33: tanggal dibeli | O33: Date Created | R33: tanggal dibeli | U33: Date Created | X33: tanggal dibeli | AA33: Date Created | AD33: tanggal dibeli | AG33: Date Created | AJ33: tanggal dibeli
C34: Lifespan | E34: =5*12*30 -> 1800 | F34: hari | I34: Lifespan | K34: =5*12*30 -> 1800 | L34: hari | O34: Lifespan | Q34: =5*12*30 -> 1800 | R34: hari | U34: Lifespan | W34: =5*12*30 -> 1800 | X34: hari | AA34: Lifespan | AC34: =5*12*30 -> 1800 | AD34: hari | AG34: Lifespan | AI34: =5*12*30 -> 1800 | AJ34: hari
C35: Age | E35: 0 | F35: hari | I35: Age | K35: 0 | L35: hari | O35: Age | Q35: 0 | R35: hari | U35: Age | W35: 0 | X35: hari | AA35: Age | AC35: 0 | AD35: hari | AG35: Age | AI35: 0 | AJ35: hari
C36: Sisa Umur | E36: =E34-E35-(E37+E39)/2*10 -> 1799.5 | F36: hari | I36: Sisa Umur | K36: =K34-K35-(K37+K39)/2*10 -> 1799.5 | L36: hari | O36: Sisa Umur | Q36: =Q34-Q35-(Q37+Q39)/2*10 -> 1799.5 | R36: hari | U36: Sisa Umur | W36: =W34-W35-(W37+W39)/2*10 -> 1799.5 | X36: hari | AA36: Sisa Umur | AC36: =AC34-AC35-(AC37+AC39)/2*10 -> 1800 | AD36: hari | AG36: Sisa Umur | AI36: =AI34-AI35-(AI37+AI39)/2*10 -> 1799.5 | AJ36: hari
C37: Maintenance | D37: Current State | E37: =((E35/E34)*10-E38) -> 0 | F37: level | I37: Maintenance | J37: Current State | K37: =((K35/K34)*10-K38) -> 0 | L37: level | O37: Maintenance | P37: Current State | Q37: =((Q35/Q34)*10-Q38) -> 0 | R37: level | U37: Maintenance | V37: Current State | W37: =((W35/W34)*10-W38) -> 0 | X37: level | AA37: Maintenance | AB37: Current State | AC37: =((AC35/AC34)*10-AC38) -> 0 | AD37: level | AG37: Maintenance | AH37: Current State | AI37: =((AI35/AI34)*10-AI38) -> 0 | AJ37: level
D38: Total Cumulative Maintenance | E38: 0 | F38: kumulatif maintenance | J38: Total Cumulative Maintenance | K38: 0 | L38: kumulatif maintenance | P38: Total Cumulative Maintenance | Q38: 0 | R38: kumulatif maintenance | V38: Total Cumulative Maintenance | W38: 0 | X38: kumulatif maintenance | AB38: Total Cumulative Maintenance | AC38: 0 | AD38: kumulatif maintenance | AH38: Total Cumulative Maintenance | AI38: 0 | AJ38: kumulatif maintenance
C39: Cleanliness | D39: Current State | E39: ='[2]Data Lingkungan (DL)'!AR63 -> 0.1 | F39: level | I39: Cleanliness | J39: Current State | K39: ='[2]Data Lingkungan (DL)'!AR64 -> 0.1 | L39: level | O39: Cleanliness | P39: Current State | Q39: ='[1]Data Lingkungan_IC'!BA64 -> 0.1 | R39: level | U39: Cleanliness | V39: Current State | W39: ='[1]Data Lingkungan_IC'!AR63 -> 0.1 | X39: level | AA39: Cleanliness | AB39: Current State | AC39: ='[1]Data Lingkungan_IC'!BS64 -> 0 | AD39: level | AG39: Cleanliness | AH39: Current State | AI39: ='[1]Data Lingkungan_IC'!DL63 -> 0.1 | AJ39: level
C40: Condition | E40: =(E36/E34) -> 0.99972222 | F40: rusak, kurang bagus, bagus, sangat bagus | I40: Condition | K40: =(K36/K34) -> 0.99972222 | L40: rusak, kurang bagus, bagus, sangat bagus | O40: Condition | Q40: =(Q36/Q34) -> 0.99972222 | R40: rusak, kurang bagus, bagus, sangat bagus | U40: Condition | W40: =(W36/W34) -> 0.99972222 | X40: rusak, kurang bagus, bagus, sangat bagus | AA40: Condition | AC40: =(AC36/AC34) -> 1 | AD40: rusak, kurang bagus, bagus, sangat bagus | AG40: Condition | AI40: =(AI36/AI34) -> 0.99972222 | AJ40: rusak, kurang bagus, bagus, sangat bagus
C41: Machine Activity | D41: Function | I41: Machine Activity | J41: Function | O41: Machine Activity | P41: Function | U41: Machine Activity | V41: Function | AA41: Machine Activity | AB41: Function | AG41: Machine Activity | AH41: Function
D42: Status | E42: ='[2]Data Lingkungan (DL)'!AO63 -> off | J42: Status | K42: ='[2]Data Lingkungan (DL)'!AO64 -> off | P42: Status | Q42: ='[2]Data Lingkungan (DL)'!AX63 -> on | V42: Status | W42: ='[2]Data Lingkungan (DL)'!AO62 -> off | AB42: Status | AC42: ='[2]Data Lingkungan (DL)'!BP63 -> off | AH42: Status | AI42: ='[2]Data Lingkungan (DL)'!DI62 -> on
...
