Workbook

Sheet ES_ALL
A1: PAULA
A2: No | B2: Kode | C2: Tingkat Emosi dan Sosial
C3: Kondisi Psikologis | K3: Pengaruh Sosial Ketika Menghadapi Orang Lain
C4: Emosi | E4: Suasana Hati | G4: Stres | I4: Kesepian | K4: Kesungkanan | L4: Ayah | M4: Ibu | N4: Nenek | O4: Anak 1 | P4: Anak 2 | Q4: Tamu
C5: Posisi normal | D5: Laju ke normal | E5: Posisi normal | F5: Laju ke normal | G5: Posisi normal | H5: Laju ke normal | I5: Posisi normal | J5: Laju ke normal | K5: Karakter Sosial | L5: Tingkat pengaruh | M5: Tingkat pengaruh | N5: Tingkat pengaruh | O5: Tingkat pengaruh | P5: Tingkat pengaruh | Q5: Tingkat pengaruh
A6: 1 | B6: AYAH
A7: 2 | B7: IBU
A8: 3 | B8: ANAK 1
A9: 4 | B9: ANAK 2
A10: 5 | B10: NENEK
A12: SILVI
A13: No | B13: Kode | C13: Tingkat Emosi dan Sosial
C14: Kondisi Psikologis | K14: Pengaruh Sosial Ketika Menghadapi Orang Lain
C15: Emosi | E15: Suasana Hati | G15: Stres | I15: Kesepian | K15: Kesungkanan | L15: Ayah | M15: Ibu | N15: Nenek | O15: Anak 1 | P15: Anak 2 | Q15: Tamu
C16: Posisi normal | D16: Laju ke normal | E16: Posisi normal | F16: Laju ke normal | G16: Posisi normal | H16: Laju ke normal | I16: Posisi normal | J16: Laju ke normal | K16: Karakter Sosial | L16: Tingkat pengaruh | M16: Tingkat pengaruh | N16: Tingkat pengaruh | O16: Tingkat pengaruh | P16: Tingkat pengaruh | Q16: Tingkat pengaruh
A17: 1 | B17: AYAH
A18: 2 | B18: IBU
A19: 3 | B19: ANAK 1
A20: 4 | B20: ANAK 2
A21: 5 | B21: CUCU
A22: 5 | B22: ART
A24: ADIT
A25: No | B25: Kode | C25: Tingkat Emosi dan Sosial
C26: Kondisi Psikologis | K26: Pengaruh Sosial Ketika Menghadapi Orang Lain
C27: Emosi | E27: Suasana Hati | G27: Stres | I27: Kesepian | K27: Kesungkanan | L27: Ayah | M27: Ibu | N27: Nenek | O27: Anak 1 | P27: Anak 2 | Q27: Tamu
C28: Posisi normal | D28: Laju ke normal | E28: Posisi normal | F28: Laju ke normal | G28: Posisi normal | H28: Laju ke normal | I28: Posisi normal | J28: Laju ke normal | K28: Karakter Sosial | L28: Tingkat pengaruh | M28: Tingkat pengaruh | N28: Tingkat pengaruh | O28: Tingkat pengaruh | P28: Tingkat pengaruh | Q28: Tingkat pengaruh
A29: 1 | B29: AYAH
A30: 2 | B30: IBU
A31: 3 | B31: ANAK 1
A32: 4 | B32: KAKEK
A33: 5 | B33: NENEK

Sheet DP_PAULA
A1: DATA RENCANA AYAH_PAULA
A2: No | B2: Kode | C2: Aktivitas | D2: KATEGORI AKTIVITAS | N2: WAKTU AKTIVITAS
D3: Aturan | H3: Kebiasaan | K3: Rencana Reguler | N3: Rentang Waktu | O3: Kelompok Waktu | T3: Rencana Insidental | V3: Rentang waktu Insidental | W3: Durasi (menit)
D4: Ya | E4: Tidak | F4: R2 | G4: R1 | H4: Ya | I4: Tidak | J4: H1 | K4: Ya | L4: Tidak | M4: P1 | O4: Pg | P4: Si | Q4: Sr | R4: Ml | S4: Al | T4: Ya / Tidak | U4: Slot waktu
A5: 1 | B5: BT | C5: Bangun tidur di pagi hari
A6: 2 | B6: BD | C6: Berdoa setelah bangun tidur di pagi hari
A7: 3 | B7: MD1 | C7: Mandi di pagi hari
A8: 4 | B8: MA1 | C8: Memandikan anak di pagi hari
A9: 5 | B9: MK2 | C9: Makan pagi
A10: 6 | B10: MC3 | C10: Membaca e-book (gadget)
A11: 7 | B11: KJ1 | C11: Berangkat kerja
A12: 8 | B12: KJ3 | C12: Pulang kerja
A13: 9 | B13: TDS | C13: Tidur siang
A14: 10 | B14: MK4 | C14: Makan siang
A15: 11 | B15: GR | C15: Memarkir kendaraan di garasi
A16: 12 | B16: MD2 | C16: Mandi di sore hari
... A40: 36 | B40: GL | C40: Mengganti galon
A42: DATA RENCANA KAKAK_PAULA
A43: No | B43: Kode | C43: Aktivitas | D43: KATEGORI AKTIVITAS | N43: WAKTU AKTIVITAS
D44: Aturan | H44: Kebiasaan | K44: Rencana Reguler | N44: Rentang Waktu | O44: Kelompok Waktu | T44: Rencana Insidental | V44: Rentang waktu Insidental | W44: Durasi (menit)
D45: Ya | E45: Tidak | F45: R2 | G45: R1 | H45: Ya | I45: Tidak | J45: H1 | K45: Ya | L45: Tidak | M45: P1 | O45: Pg | P45: Si | Q45: Sr | R45: Ml | S45: Al | T45: Ya / Tidak | U45: Slot waktu
A46: 1 | B46: BT | C46: Bangun tidur di pagi hari
A47: 2 | B47: BD | C47: Berdoa setelah bangun tidur di pagi hari
A48: 3 | B48: MD1 | C48: Mandi di pagi hari
A49: 4 | B49: MK2 | C49: Makan pagi
A50: 5 | B50: MC2 | C50: Membaca buku
A51: 6 | B51: KJ4 | C51: Les / homeshooling
A52: 7 | B52: KJ6 | C52: Belajar/bekerja tanpa komputer
A53: 8 | B53: TDS | C53: Tidur siang
A54: 9 | B54: MK4 | C54: Makan siang
A55: 10 | B55: MD2 | C55: Mandi di sore hari
A56: 11 | B56: CP2 | C56: Meletakkan pakaian kotor setelah mandi
A57: 12 | B57: CP3 | C57: Mengambil pakaian bersih sebelum mandi
... A78: 33 | B78: IB | C78: Ibadah (di rumah responden)
A89: DATA RENCANA IBU_PAULA
A90: No | B90: Kode | C90: Aktivitas | D90: KATEGORI AKTIVITAS | N90: WAKTU AKTIVITAS
D91: Aturan | H91: Kebiasaan | K91: Rencana Reguler | N91: Rentang Waktu | O91: Kelompok Waktu | T91: Rencana Insidental | V91: Rentang waktu Insidental | W91: Durasi (menit)
D92: Ya | E92: Tidak | F92: R2 | G92: R1 | H92: Ya | I92: Tidak | J92: H1 | K92: Ya | L92: Tidak | M92: P1 | O92: Pg | P92: Si | Q92: Sr | R92: Ml | S92: Al | T92: Ya / Tidak | U92: Slot waktu
A93: 1 | B93: BT | C93: Bangun tidur di pagi hari
A94: 2 | B94: BD | C94: Berdoa setelah bangun tidur di pagi hari
...

Sheet SYARAT_PAULA
A1: SYARAT AYAH_PAULA
A2: NO | B2: KODE | C2: AKTIVITAS | D2: Peluang Dilakukan | E2: Tingkat Kemampuan Minimal | F2: FAKTOR FISIK LINGKUNGAN | V2: FAKTOR SUMBER DAYA | AL2: FAKTOR RUANG | BG2: RUANG UNTUK AKTIVITAS
V3: Air/Listrik/Gas/Makanan/Bahan Makanan/Bahan Bacaan | AL3: Kursi/Sofa/Karpet/Pintu/Tempat Tidur/Alat Kebersihan/ Alat Berkebun | BG3: Ruang Alternatif 1 | BH3: Ruang Alternatif 2 | BI3: Kondisi Ruang Alt 1 | BJ3: Jika Hidup Pilih | BK3: Jika Mati Pilih
F4: F1 Cahaya | N4: F2 Suhu | V4: R1 | AD4: R2 | AL4: D1 | AT4: D2 | BB4: D3
F5: Ya / Tidak | G5: Batas | H5: Kondisi Terkini | I5: Aktivitas Pendukung Sebelum | J5: Peluang Dilakukan | K5: Aktivitas Pendukung Setelah | L5: Peluang Dilakukan | M5: Obyek Lampu | N5: Ya / Tidak | O5: Batas | P5: Kondisi Terkini | Q5: Aktivitas Pendukung Sebelum | R5: Peluang Dilakukan | S5: Aktivitas Pendukung Setelah | T5: Peluang Dilakukan | U5: Obyek Pengatur Suhu Ruang | V5: Ya / Tidak | W5: Komponen | X5: Kondisi Terkini | Y5: Aktivitas Pendukung Sebelum | Z5: Peluang Dilakukan | AA5: Aktivitas Pendukung Setelah | AB5: Peluang Dilakukan | AC5: Obyek Lingkungan | AD5: Ya / Tidak | AE5: Komponen | AF5: Kondisi Terkini | AG5: Aktivitas Pendukung Sebelum | AH5: Peluang Dilakukan | AI5: Aktivitas Pendukung Setelah | AJ5: Peluang Dilakukan | AK5: Obyek Lingkungan | AL5: Ya / Tidak | AM5: Komponen | AN5: Kondisi Terkini | AO5: Aktivitas Pendukung Sebelum | AP5: Peluang Dilakukan | AQ5: Aktivitas Pendukung Setelah | AR5: Peluang Dilakukan | AS5: Obyek Lingkungan | AT5: Ya / Tidak | AU5: Komponen | AV5: Kondisi Terkini | AW5: Aktivitas Pendukung Sebelum | AX5: Peluang Dilakukan | AY5: Aktivitas Pendukung Setelah | AZ5: Peluang Dilakukan | BA5: Obyek Lingkungan | BB5: Ya / Tidak | BC5: Komponen | BD5: Kondisi Terkini | BE5: Jika Komponen Mati Pilih | BF5: Alat
A6: =DP_PAULA!A5 -> 1 | B6: =DP_PAULA!B5 -> BT | C6: =DP_PAULA!C5 -> Bangun tidur di pagi hari | E6: 2 | F6: Tidak | G6: 0 | H6: 0 | I6: 0 | M6: 0 | N6: Tidak | O6: 0 | P6: 0 | Q6: 0 | U6: 0 | V6: Tidak | W6: 0 | X6: 0 | Y6: 0 | AC6: 0 | AD6: Tidak | AE6: 0 | AF6: 0 | AG6: 0 | AK6: 0 | AL6: Ya | AM6: Tempat Tidur | AN6: Mati | AO6: T4 | AS6: TD1 | AT6: Tidak | AU6: 0 | AV6: 0 | AW6: 0 | BA6: 0 | BB6: Tidak | BC6: 0 | BD6: 0 | BE6: 0 | BF6: 0 | BG6: Rg Tidur Utama | BI6: Hidup | BJ6: J2 | BK6: J1
A7: =DP_PAULA!A6 -> 2 | B7: =DP_PAULA!B6 -> BD | C7: =DP_PAULA!C6 -> Berdoa setelah bangun tidur di pagi hari | E7: 2 | F7: Ya | G7: 100 | H7: 40 | I7: S1 | M7: L18 | N7: Tidak | O7: 0 | P7: 0 | Q7: 0 | U7: 0 | V7: Tidak | W7: 0 | X7: 0 | Y7: 0 | AC7: 0 | AD7: Tidak | AE7: 0 | AF7: 0 | AG7: 0 | AK7: 0 | AL7: Ya | AM7: Tempat Tidur | AN7: Mati | AO7: T4 | AS7: TD1 | AT7: Tidak | AU7: 0 | AV7: 0 | AW7: 0 | BA7: 0 | BB7: Tidak | BC7: 0 | BD7: 0 | BE7: 0 | BF7: 0 | BG7: Rg Tidur Utama | BI7: Hidup | BJ7: J2 | BK7: J1
A8: =DP_PAULA!A7 -> 3 | B8: =DP_PAULA!B7 -> MD1 | C8: =DP_PAULA!C7 -> Mandi di pagi hari | E8: 4 | F8: Ya | G8: 100 | H8: 40 | I8: S1 | M8: L10 | N8: Tidak | O8: 0 | P8: 0 | Q8: 0 | U8: 0 | V8: Ya | W8: Air | X8: Hidup | Y8: O1 | AC8: WT03 | AD8: Tidak | AE8: 0 | AF8: 0 | AG8: 0 | AK8: 0 | AL8: Ya | AM8: Pintu | AN8: Mati | AO8: G3 | AS8: P8 | AT8: Tidak | AU8: 0 | AV8: 0 | AW8: 0 | BA8: 0 | BG8: KM | BI8: Hidup | BJ8: J2 | BK8: J1
A9: =DP_PAULA!A8 -> 4 | B9: =DP_PAULA!B8 -> MA1 | C9: =DP_PAULA!C8 -> Memandikan anak di pagi hari | E9: 4 | F9: Ya | G9: 100 | H9: 40 | I9: S1 | M9: L10 | N9: Tidak | O9: 0 | P9: 0 | Q9: 0 | U9: 0 | V9: Ya | W9: Air | X9: Hidup | Y9: O1 | AC9: WT03 | AD9: Tidak | AE9: 0 | AF9: 0 | AG9: 0 | AK9: 0 | AL9: Ya | AM9: Pintu | AN9: Mati | AO9: G4 | AS9: P8 | AT9: Tidak | AU9: 0 | AV9: 0 | AW9: 0 | BA9: 0 | BG9: KM | BI9: Hidup | BJ9: J2 | BK9: J1
A10: =DP_PAULA!A9 -> 5 | B10: =DP_PAULA!B9 -> MK2 | C10: =DP_PAULA!C9 -> Makan pagi | E10: 2 | F10: Ya | G10: 100 | H10: 40 | I10: S1 | M10: L11 | N10: Tidak | O10: 0 | P10: 0 | Q10: 0 | U10: 0 | V10: Ya | W10: Makanan | X10: Hidup | Y10: G5 | AC10: RC02 | AD10: Tidak | AE10: 0 | AF10: 0 | AG10: 0 | AK10: 0 | AL10: Ya | AM10: Kursi/Karpet/Sofa | AN10: Mati | AO10: K/KR/S | AS10: K01 | AT10: Tidak | AU10: 0 | AV10: 0 | AW10: 0 | BA10: 0 | BG10: RMKn | BI10: Hidup | BJ10: J2 | BK10: J1
A11: =DP_PAULA!A10 -> 6 | B11: =DP_PAULA!B10 -> MC3 | C11: =DP_PAULA!C10 -> Membaca e-book (gadget) | E11: 4 | F11: Ya | G11: 100 | H11: 40 | I11: S1 | M11: L6/ L4/ L5 | N11: Tidak | O11: 0 | P11: 0 | Q11: 0 | U11: 0 | V11: Ya | W11: Listrik | X11: Hidup | Y11: S6 | AD11: Tidak | AE11: 0 | AF11: 0 | AG11: 0 | AK11: 0 | AL11: Ya | AM11: Kursi/Karpet/Sofa | AN11: Mati | AO11: K/KR/S | AS11: S10/ KR01 | AT11: Ya | AU11: Kursi/Karpet/Sofa | AV11: Mati | AW11: K/KR/S | BA11: S04 | BG11: R Keluarga | BH11: R Tamu | BI11: Hidup | BJ11: J2 | BK11: J1
A12: =DP_PAULA!A11 -> 7 | B12: =DP_PAULA!B11 -> KJ1 | C12: =DP_PAULA!C11 -> Berangkat kerja | E12: 4 | F12: Tidak | G12: 0 | H12: 0 | I12: 0 | M12: 0 | N12: Tidak | O12: 0 | P12: 0 | Q12: 0 | U12: 0 | V12: Tidak | W12: 0 | X12: 0 | Y12: 0 | AC12: 0 | AD12: Tidak | AE12: 0 | AF12: 0 | AG12: 0 | AK12: 0 | AL12: Tidak | AM12: 0 | AN12: 0 | AO12: 0 | AS12: 0 | AT12: Tidak | AU12: 0 | AV12: 0 | AW12: 0 | BA12: 0 | BG12: Garasi | BI12: Hidup | BJ12: J2 | BK12: J1
A13: =DP_PAULA!A12 -> 8 | B13: =DP_PAULA!B12 -> KJ3 | C13: =DP_PAULA!C12 -> Pulang kerja | E13: 4 | F13: Tidak | G13: 0 | H13: 0 | I13: 0 | M13: 0 | N13: Tidak | O13: 0 | P13: 0 | Q13: 0 | U13: 0 | V13: Tidak | W13: 0 | X13: 0 | Y13: 0 | AC13: 0 | AD13: Tidak | AE13: 0 | AF13: 0 | AG13: 0 | AK13: 0 | AL13: Tidak | AM13: 0 | AN13: 0 | AO13: 0 | AS13: 0 | AT13: Tidak | AU13: 0 | AV13: 0 | AW13: 0 | BA13: 0 | BG13: Garasi | BI13: Hidup | BJ13: J2 | BK13: J1
A14: =DP_PAULA!A13 -> 9 | B14: =DP_PAULA!B13 -> TDS | C14: =DP_PAULA!C13 -> Tidur siang | E14: 2 | F14: Ya | G14: 100 | H14: 40 | I14: S1 | M14: L3 | N14: Ya | O14: 25 | P14: 27 | Q14: S2 | U14: AC01/ KP02 | V14: Tidak | W14: 0 | X14: 0 | Y14: 0 | AC14: 0 | AD14: Tidak | AE14: 0 | AF14: 0 | AG14: 0 | AK14: 0 | AL14: Ya | AM14: Tempat Tidur | AN14: Mati | AO14: T2 | AS14: TD1 | AT14: Tidak | AU14: 0 | AV14: 0 | AW14: 0 | BA14: 0 | BG14: Rg Tidur Utama | BI14: Hidup | BJ14: J2 | BK14: J1
A15: =DP_PAULA!A14 -> 10 | B15: =DP_PAULA!B14 -> MK4 | C15: =DP_PAULA!C14 -> Makan siang | E15: 2 | F15: Ya | G15: 100 | H15: 40 | I15: S1 | M15: L11 | N15: Tidak | O15: 0 | P15: 0 | Q15: 0 | U15: 0 | V15: Ya | W15: Makanan | X15: Hidup | Y15: G5 | AC15: RC02 | AD15: Tidak | AE15: 0 | AF15: 0 | AG15: 0 | AK15: 0 | AL15: Ya | AM15: Kursi/Karpet/Sofa | AN15: Mati | AO15: K/KR/S | AS15: K01 | AT15: Tidak | AU15: 0 | AV15: 0 | AW15: 0 | BA15: 0 | BG15: R Makan | BH15: R keluarga | BI15: Hidup | BJ15: J2 | BK15: J1
A16: =DP_PAULA!A15 -> 11 | B16: =DP_PAULA!B15 -> GR | C16: =DP_PAULA!C15 -> Memarkir kendaraan di garasi | E16: 8 | F16: Ya | G16: 100 | H16: 40 | I16: S1 | M16: L2 | N16: Tidak | O16: 0 | P16: 0 | Q16: 0 | U16: 0 | V16: Tidak | W16: 0 | X16: 0 | Y16: 0 | AC16: 0 | AD16: Tidak | AE16: 0 | AF16: 0 | AG16: 0 | AK16: 0 | AL16: Ya | AM16: Pintu | AN16: Mati | AO16: G2 | AS16: P13 | AT16: Tidak | AU16: 0 | AV16: 0 | AW16: 0 | BA16: 0 | BG16: Garasi | BI16: Hidup | BJ16: J2 | BK16: J1
A17: =DP_PAULA!A16 -> 12 | B17: =DP_PAULA!B16 -> MD2 | C17: =DP_PAULA!C16 -> Mandi di sore hari | E17: 4 | F17: Ya | G17: 100 | H17: 40 | I17: S1 | M17: L10 | N17: Tidak | O17: 0 | P17: 0 | Q17: 0 | U17: 0 | V17: Ya | W17: Air | X17: Hidup | Y17: O1 | AC17: WT03 | AD17: Tidak | AE17: 0 | AF17: 0 | AG17: 0 | AK17: 0 | AL17: Ya | AM17: Pintu | AN17: Mati | AO17: G2 | AS17: P8 | AT17: Tidak | AU17: 0 | AV17: 0 | AW17: 0 | BA17: 0 | BG17: KM | BI17: Hidup | BJ17: J2 | BK17: J1
A18: =DP_PAULA!A17 -> 13 | B18: =DP_PAULA!B17 -> CP2 | C18: =DP_PAULA!C17 -> Meletakkan pakaian kotor setelah mandi | E18: 2 | F18: Ya | G18: 100 | H18: 40 | I18: S1 | M18: L13 | N18: Tidak | O18: 0 | P18: 0 | Q18: 0 | U18: 0 | V18: Tidak | W18: 0 | X18: 0 | Y18: 0 | AC18: 0 | AD18: Tidak | AE18: 0 | AF18: 0 | AG18: 0 | AK18: 0 | AL18: Ya | AM18: Pintu | AN18: Mati | AO18: G2 | AS18: P11 | AT18: Tidak | AU18: 0 | AV18: 0 | AW18: 0 | BA18: 0 | BG18: R Cuci | BI18: Hidup | BJ18: J2 | BK18: J1
A19: =DP_PAULA!A18 -> 14 | B19: =DP_PAULA!B18 -> CP3 | C19: =DP_PAULA!C18 -> Mengambil pakaian bersih sebelum mandi | E19: 2 | F19: Ya | G19: 100 | H19: 40 | I19: S1 | M19: L3 | N19: Tidak | O19: 0 | P19: 0 | Q19: 0 | U19: 0 | V19: Tidak | W19: 0 | X19: 0 | Y19: 0 | AC19: 0 | AD19: Tidak | AE19: 0 | AF19: 0 | AG19: 0 | AK19: 0 | AL19: Ya | AM19: Pintu | AN19: Mati | AO19: G2 | AS19: P4 | AT19: Tidak | AU19: 0 | AV19: 0 | AW19: 0 | BA19: 0 | BG19: RT Utama | BI19: Hidup | BJ19: J2 | BK19: J1
A20: =DP_PAULA!A19 -> 15 | B20: =DP_PAULA!B19 -> MK6 | C20: =DP_PAULA!C19 -> Makan malam | E20: 2 | F20: Ya | G20: 100 | H20: 40 | I20: S1 | M20: L11 | N20: Tidak | O20: 0 | P20: 0 | Q20: 0 | U20: 0 | V20: Ya | W20: Makanan | X20: Hidup | Y20: G5 | AC20: RC02 | AD20: Tidak | AE20: 0 | AF20: 0 | AG20: 0 | AK20: 0 | AL20: Ya | AM20: Kursi/Karpet/Sofa | AN20: Mati | AO20: K/KR/S | AS20: K01 | AT20: Tidak | AU20: 0 | AV20: 0 | AW20: 0 | BA20: 0 | BG20: R Makan | BH20: R keluarga | BI20: Hidup | BJ20: J2 | BK20: J1
A21: =DP_PAULA!A20 -> 16 | B21: =DP_PAULA!B20 -> BP | C21: =DP_PAULA!C20 -> Berpakaian dan berdandan | E21: 2 | F21: Ya | G21: 100 | H21: 40 | I21: S1 | M21: L3 | N21: Tidak | O21: 0 | P21: 0 | Q21: 0 | U21: 0 | V21: Tidak | W21: 0 | X21: 0 | Y21: 0 | AC21: 0 | AD21: Tidak | AE21: 0 | AF21: 0 | AG21: 0 | AK21: 0 | AL21: Ya | AM21: Pintu | AN21: Mati | AO21: G2 | AS21: P4 | AT21: Tidak | AU21: 0 | AV21: 0 | AW21: 0 | BA21: 0 | BC21: Karpet | BD21: Hidup | BE21: Kr1 | BG21: Rg Tidur Utama | BH21: Rg Tidur 2 | BI21: Hidup | BJ21: J2 | BK21: J1
A22: =DP_PAULA!A21 -> 17 | B22: =DP_PAULA!B21 -> TDM | C22: =DP_PAULA!C21 -> Tidur malam | E22: 2 | F22: Ya | G22: 100 | H22: 40 | I22: S1 | M22: L3/ L18 | N22: Ya | O22: 25 | P22: 27 | Q22: S2 | U22: AC01/ KP02 | V22: Tidak | W22: 0 | X22: 0 | Y22: 0 | AC22: 0 | AD22: Tidak | AE22: 0 | AF22: 0 | AG22: 0 | AK22: 0 | AL22: Ya | AM22: Tempat Tidur | AN22: Mati | AO22: T2 | AS22: P4 | AT22: Tidak | AU22: 0 | AV22: 0 | AW22: 0 | BA22: 0 | BG22: Rg Tidur Utama | BI22: Hidup | BJ22: J2 | BK22: J1
A23: =DP_PAULA!A22 -> 18 | B23: =DP_PAULA!B22 -> TD | C23: =DP_PAULA!C22 -> Tidur (diluar waktu tidur malam & siang) | E23: 2 | F23: Ya | G23: 100 | H23: 40 | I23: S1 | M23: L3/ L18 | N23: Ya | O23: 25 | P23: 27 | Q23: S2 | U23: AC01/ KP02 | V23: Tidak | W23: 0 | X23: 0 | Y23: 0 | AC23: 0 | AD23: Tidak | AE23: 0 | AF23: 0 | AG23: 0 | AK23: 0 | AL23: Ya | AM23: Tempat Tidur | AN23: Mati | AO23: T2 | AS23: P4 | AT23: Tidak | AU23: 0 | AV23: 0 | AW23: 0 | BA23: 0 | BG23: Rg Tidur Utama | BI23: Hidup | BJ23: J2 | BK23: J1
A24: =DP_PAULA!A23 -> 19 | B24: =DP_PAULA!B23 -> TO | C24: =DP_PAULA!C23 -> Toilet (hanya BAK/BAB) | E24: 4 | F24: Ya | G24: 100 | H24: 40 | I24: S1 | M24: L10 | N24: Tidak | O24: 0 | P24: 0 | Q24: 0 | U24: 0 | V24: Ya | W24: Air | X24: Hidup | Y24: O1 | AC24: WT03 | AD24: Tidak | AE24: 0 | AF24: 0 | AG24: 0 | AK24: 0 | AL24: Ya | AM24: Pintu | AN24: Mati | AO24: G2 | AS24: P8 | AT24: Tidak | AU24: 0 | AV24: 0 | AW24: 0 | BA24: 0 | BG24: KM | BI24: Hidup | BJ24: J2 | BK24: J1
A25: =DP_PAULA!A24 -> 20 | B25: =DP_PAULA!B24 -> MD | C25: =DP_PAULA!C24 -> Mandi (diluar waktu mandi pagi dan sore) | E25: 4 | F25: Ya | G25: 100 | H25: 40 | I25: S1 | M25: L10 | N25: Tidak | O25: 0 | P25: 0 | Q25: 0 | U25: 0 | V25: Ya | W25: Air | X25: Hidup | Y25: O1 | AC25: WT03 | AD25: Tidak | AE25: 0 | AF25: 0 | AG25: 0 | AK25: 0 | AL25: Ya | AM25: Pintu | AN25: Mati | AO25: G2 | AS25: P8 | AT25: Tidak | AU25: 0 | AV25: 0 | AW25: 0 | BA25: 0 | BG25: KM | BI25: Hidup | BJ25: J2 | BK25: J1
A26: =DP_PAULA!A25 -> 21 | B26: =DP_PAULA!B25 -> BK | C26: =DP_PAULA!C25 -> Bercukur | E26: 6 | F26: Ya | G26: 100 | H26: 40 | I26: S1 | M26: L10 | N26: Tidak | O26: 0 | P26: 0 | Q26: 0 | U26: 0 | V26: Ya | W26: Air | X26: Hidup | Y26: O1 | AC26: WT03 | AD26: Tidak | AE26: 0 | AF26: 0 | AG26: 0 | AK26: 0 | AL26: Ya | AM26: Pintu | AN26: Mati | AO26: G2 | AS26: P8 | AT26: Tidak | AU26: 0 | AV26: 0 | AW26: 0 | BA26: 0 | BG26: KM | BI26: Hidup | BJ26: J2 | BK26: J1
A27: =DP_PAULA!A26 -> 22 | B27: =DP_PAULA!B26 -> MK | C27: =DP_PAULA!C26 -> Makan (diluar waktu makan pagi, siang, malam) | E27: 2 | F27: Ya | G27: 100 | H27: 40 | I27: S1 | M27: L11/ L6 | N27: Tidak | O27: 0 | P27: 0 | Q27: 0 | U27: 0 | V27: Ya | W27: Makanan | X27: Hidup | Y27: G5 | AC27: RC02/RC01 | AD27: Tidak | AE27: 0 | AF27: 0 | AG27: 0 | AK27: 0 | AL27: Ya | AM27: Kursi/Karpet/Sofa | AN27: Mati | AO27: K/KR/S | AS27: K01 | AT27: Tidak | AU27: 0 | AV27: 0 | AW27: 0 | BA27: 0 | BG27: R Makan | BH27: Rg Keluarga | BI27: Hidup | BJ27: J2 | BK27: J1
A28: =DP_PAULA!A27 -> 23 | B28: =DP_PAULA!B27 -> MN1 | C28: =DP_PAULA!C27 -> Minum setelah makan pagi | E28: 2 | F28: Ya | G28: 100 | H28: 40 | I28: S1 | M28: L12/ L11 | N28: Tidak | O28: 0 | P28: 0 | Q28: 0 | U28: 0 | V28: Ya | W28: Listrik | X28: Hidup | Y28: L2 | AC28: DP01 | AD28: Ya | AE28: Air | AF28: Hidup | AG28: O1 | AK28: 0 | AL28: Ya | AM28: Kursi/Karpet/Sofa | AN28: Mati | AO28: K/KR/S | AS28: K01 | AT28: Tidak | AU28: 0 | AV28: 0 | AW28: 0 | BA28: 0 | BG28: Dapur | BH28: R Makan | BI28: Hidup | BJ28: J2 | BK28: J1
A29: =DP_PAULA!A28 -> 24 | B29: =DP_PAULA!B28 -> MN2 | C29: =DP_PAULA!C28 -> Minum setelah makan siang | E29: 2 | F29: Ya | G29: 100 | H29: 40 | I29: S1 | M29: L12/ L11 | N29: Tidak | O29: 0 | P29: 0 | Q29: 0 | U29: 0 | V29: Ya | W29: Listrik | X29: Hidup | Y29: L2 | AC29: DP01 | AD29: Ya | AE29: Air | AF29: Hidup | AG29: O1 | AK29: 0 | AL29: Ya | AM29: Kursi/Karpet/Sofa | AN29: Mati | AO29: K/KR/S | AS29: K01 | AT29: Tidak | AU29: 0 | AV29: 0 | AW29: 0 | BA29: 0 | BG29: Dapur | BH29: R Makan | BI29: Hidup | BJ29: J2 | BK29: J1
A30: =DP_PAULA!A29 -> 25 | B30: =DP_PAULA!B29 -> MN3 | C30: =DP_PAULA!C29 -> Minum setelah makan malam | E30: 2 | F30: Ya | G30: 100 | H30: 40 | I30: S1 | M30: L12/ L11 | N30: Tidak | O30: 0 | P30: 0 | Q30: 0 | U30: 0 | V30: Ya | W30: Listrik | X30: Hidup | Y30: L2 | AC30: DP01 | AD30: Ya | AE30: Air | AF30: Hidup | AG30: O1 | AK30: 0 | AL30: Ya | AM30: Kursi/Karpet/Sofa | AN30: Mati | AO30: K/KR/S | AS30: K01 | AT30: Tidak | AU30: 0 | AV30: 0 | AW30: 0 | BA30: 0 | BG30: Dapur | BH30: R Makan | BI30: Hidup | BJ30: J2 | BK30: J1
A31: =DP_PAULA!A30 -> 26 | B31: =DP_PAULA!B30 -> MN4 | C31: =DP_PAULA!C30 -> Minum (diluar waktu makan pagi, siang, malam) | E31: 2 | F31: Ya | G31: 100 | H31: 40 | I31: S1 | M31: L12/ L11 | N31: Tidak | O31: 0 | P31: 0 | Q31: 0 | U31: 0 | V31: Ya | W31: Listrik | X31: Hidup | Y31: L2 | AC31: DP01 | AD31: Ya | AE31: Air | AF31: Hidup | AG31: O1 | AK31: 0 | AL31: Ya | AM31: Kursi/Karpet/Sofa | AN31: Mati | AO31: K/KR/S | AS31: K01 | AT31: Tidak | AU31: 0 | AV31: 0 | AW31: 0 | BA31: 0 | BG31: Dapur | BH31: R Makan | BI31: Hidup | BJ31: J2 | BK31: J1
A32: =DP_PAULA!A31 -> 27 | B32: =DP_PAULA!B31 -> MP | C32: =DP_PAULA!C31 -> Mengganti lampu | E32: 8 | F32: Ya | G32: 0 | H32: 40 | I32: S8 | M32: 0 | N32: Tidak | O32: 0 | P32: 0 | Q32: 0 | U32: 0 | V32: Ya | W32: Listrik | X32: Mati | Y32: L1 | AD32: Tidak | AE32: 0 | AF32: 0 | AG32: 0 | AK32: 0 | AL32: Tidak | AM32: 0 | AN32: 0 | AO32: 0 | AS32: 0 | AT32: Tidak | AU32: 0 | AV32: 0 | AW32: 0 | BA32: 0 | BI32: Hidup | BJ32: J2 | BK32: J1
A33: =DP_PAULA!A32 -> 28 | B33: =DP_PAULA!B32 -> BS | C33: =DP_PAULA!C32 -> Bersantai (waktu ditentukan responden) | E33: 2 | F33: Ya | G33: 100 | H33: 40 | I33: S1 | M33: L3/ L6 | N33: Ya | O33: 25 | P33: 27 | Q33: S2 | U33: AC01/ KP02 | V33: Tidak | W33: 0 | X33: 0 | Y33: 0 | AC33: 0 | AD33: Tidak | AE33: 0 | AF33: 0 | AG33: 0 | AK33: 0 | AL33: Ya | AM33: Tempat Tidur | AN33: Mati | AO33: T2 | AS33: TD1 | AT33: Ya | AU33: Kursi/Karpet/Sofa | AV33: Mati | AW33: K/KR/S | BA33: S10 | BG33: Rg Tidur Utama | BH33: Rg Keluarga | BI33: Hidup | BJ33: J2 | BK33: J1
A34: =DP_PAULA!A33 -> 29 | B34: =DP_PAULA!B33 -> GD1 | C34: =DP_PAULA!C33 -> Mengisi ulang daya gadget | E34: 2 | F34: Ya | G34: 100 | H34: 40 | I34: S1 | M34: L3/ L7 | N34: Tidak | O34: 0 | P34: 0 | Q34: 0 | U34: 0 | V34: Ya | W34: Listrik | X34: Mati | Y34: L2 | AD34: Tidak | AE34: 0 | AF34: 0 | AG34: 0 | AK34: 0 | AL34: Tidak | AM34: 0 | AN34: 0 | AO34: 0 | AS34: 0 | AT34: Tidak | AU34: 0 | AV34: 0 | AW34: 0 | BA34: 0 | BG34: Rg Tidur Utama | BH34: Rg Keluarga | BI34: Hidup | BJ34: J2 | BK34: J1
A35: =DP_PAULA!A34 -> 30 | B35: =DP_PAULA!B34 -> GD2 | C35: =DP_PAULA!C34 -> Mengoperasikan gadget | E35: 2 | F35: Ya | G35: 100 | H35: 40 | I35: S1 | M35: L3/ L6 | N35: Tidak | O35: 0 | P35: 0 | Q35: 0 | U35: 0 | V35: Tidak | W35: 0 | X35: 0 | Y35: 0 | AC35: 0 | AD35: Tidak | AE35: 0 | AF35: 0 | AG35: 0 | AK35: 0 | AL35: Ya | AM35: Tempat Tidur | AN35: Mati | AO35: T2 | AS35: TD1 | AT35: Ya | AU35: Kursi/Karpet/Sofa | AV35: Mati | AW35: K/KR/S | BA35: S10/ KR01 | BG35: Rg Tidur Utama | BH35: Rg Keluarga | BI35: Hidup | BJ35: J2 | BK35: J1
A36: =DP_PAULA!A35 -> 31 | B36: =DP_PAULA!B35 -> TV | C36: =DP_PAULA!C35 -> Menonton TV (waktu ditentukan responden) | E36: 2 | F36: Ya | G36: 100 | H36: 40 | I36: S1 | M36: L6 | N36: Ya | O36: 25 | P36: 27 | Q36: S2 | U36: KP01 | V36: Ya | W36: Listrik | X36: Mati | Y36: L2 | AC36: TV01 | AD36: Tidak | AE36: 0 | AF36: 0 | AG36: 0 | AK36: 0 | AL36: Ya | AM36: Kursi/Karpet/Sofa | AN36: Mati | AO36: K/KR/S | AS36: S10/ KR01 | AT36: Tidak | AU36: 0 | AV36: 0 | AW36: 0 | BA36: 0 | BG36: Rg Keluarga | BI36: Hidup | BJ36: J2 | BK36: J1
A37: =DP_PAULA!A36 -> 32 | B37: =DP_PAULA!B36 -> BM1 | C37: =DP_PAULA!C36 -> Mengawasi anak/adik bermain | E37: 4 | F37: Ya | G37: 100 | H37: 40 | I37: S1 | M37: L6/ L4/ L5 | N37: Ya | O37: 25 | P37: 27 | Q37: S2 | U37: KP01 | V37: Tidak | W37: 0 | X37: 0 | Y37: 0 | AC37: 0 | AD37: Tidak | AE37: 0 | AF37: 0 | AG37: 0 | AK37: 0 | AL37: Ya | AM37: Kursi/Karpet/Sofa | AN37: Mati | AO37: K/KR/S | AS37: S10/ KR01 | AT37: Ya | AU37: Kursi/Karpet/Sofa | AV37: Mati | AW37: K/KR/S | BA37: S04 | BG37: Rg Keluarga | BH37: R Tamu | BI37: Hidup | BJ37: J2 | BK37: J1
A38: =DP_PAULA!A37 -> 33 | B38: =DP_PAULA!B37 -> MT | C38: =DP_PAULA!C37 -> Menerima tamu | E38: 6 | F38: Ya | G38: 100 | H38: 40 | I38: S1 | M38: L4/ L5/ L6 | N38: Tidak | O38: 0 | P38: 0 | Q38: 0 | U38: 0 | V38: Tidak | W38: 0 | X38: 0 | Y38: 0 | AC38: 0 | AD38: Tidak | AE38: 0 | AF38: 0 | AG38: 0 | AK38: 0 | AL38: Ya | AM38: Kursi/Karpet/Sofa | AN38: Mati | AO38: K/KR/S | AS38: S04 | AT38: Ya | AU38: Kursi/Karpet/Sofa | AV38: Mati | AW38: K/KR/S | BA38: S10 | BG38: R Tamu | BH38: Rg Keluarga | BI38: Hidup | BJ38: J2 | BK38: J1
A39: =DP_PAULA!A38 -> 34 | B39: =DP_PAULA!B38 -> KS | C39: =DP_PAULA!C38 -> Kegiatan sosial | E39: 8 | F39: Ya | G39: 100 | H39: 40 | I39: S1 | M39: L4/ L5/ L2 | N39: Tidak | O39: 0 | P39: 0 | Q39: 0 | U39: 0 | V39: Tidak | W39: 0 | X39: 0 | Y39: 0 | AC39: 0 | AD39: Tidak | AE39: 0 | AF39: 0 | AG39: 0 | AK39: 0 | AL39: Ya | AM39: Kursi/Karpet/Sofa | AN39: Mati | AO39: K/KR/S | AS39: S04 | AT39: Tidak | AU39: 0 | AV39: 0 | AW39: 0 | BA39: 0 | BG39: R Tamu | BH39: Garasi | BI39: Hidup | BJ39: J2 | BK39: J1
A40: =DP_PAULA!A39 -> 35 | B40: =DP_PAULA!B39 -> IB | C40: =DP_PAULA!C39 -> Ibadah (di rumah responden) | E40: 4 | F40: Ya | G40: 100 | H40: 40 | I40: S1 | M40: L4/ L5 | N40: Tidak | O40: 0 | P40: 0 | Q40: 0 | U40: 0 | V40: Tidak | W40: 0 | X40: 0 | Y40: 0 | AC40: 0 | AD40: Tidak | AE40: 0 | AF40: 0 | AG40: 0 | AK40: 0 | AL40: Ya | AM40: Kursi/Karpet/Sofa | AN40: Mati | AO40: K/KR/S | AS40: S04 | AT40: Tidak | AU40: 0 | AV40: 0 | AW40: 0 | BA40: 0 | BG40: R Tamu | BI40: Hidup | BJ40: J2 | BK40: J1
...

Sheet DP_SILVI
A1: DATA RENCANA AYAH_SILVI
A2: No | B2: Kode | C2: Aktivitas | D2: KATEGORI AKTIVITAS | N2: WAKTU AKTIVITAS
D3: Aturan | H3: Kebiasaan | K3: Rencana Reguler | N3: Rentang Waktu | O3: Kelompok Waktu | T3: Rencana Insidental | V3: Rentang waktu Insidental | W3: Durasi (menit)
D4: Ya | E4: Tidak | F4: R2 | G4: R1 | H4: Ya | I4: Tidak | J4: H1 | K4: Ya | L4: Tidak | M4: P1 | O4: Pg | P4: Si | Q4: Sr | R4: Ml | S4: Al | T4: Ya / Tidak | U4: Slot waktu
A5: 1 | B5: BT | C5: Bangun tidur di pagi hari
A6: 2 | B6: OR | C6: Olahraga pagi
A7: 3 | B7: MD1 | C7: Mandi di pagi hari
A8: 4 | B8: MK2 | C8: Makan pagi
A9: 5 | B9: KJ1 | C9: Berangkat kerja
A10: 6 | B10: KJ3 | C10: Pulang kerja
A11: 7 | B11: TDS | C11: Tidur siang
A12: 8 | B12: MK4 | C12: Makan siang
A13: 9 | B13: GR | C13: Memarkir kendaraan di garasi
A14: 10 | B14: MD2 | C14: Mandi di sore hari
A15: 11 | B15: CP1 | C15: Meletakkan pakaian kotor sebelum mandi
A16: 12 | B16: CP2 | C16: Meletakkan pakaian kotor setelah mandi
... A43: 35 | B43: MK7 | C43: Makan bersama keluarga
A49: DATA RENCANA ANAK 1_SILVI
A50: No | B50: Kode | C50: Aktivitas | D50: KATEGORI AKTIVITAS | N50: WAKTU AKTIVITAS
D51: Aturan | H51: Kebiasaan | K51: Rencana Reguler | N51: Rentang Waktu | O51: Kelompok Waktu | T51: Rencana Insidental | V51: Rentang waktu Insidental | W51: Durasi (menit)
D52: Ya | E52: Tidak | F52: R2 | G52: R1 | H52: Ya | I52: Tidak | J52: H1 | K52: Ya | L52: Tidak | M52: P1 | O52: Pg | P52: Si | Q52: Sr | R52: Ml | S52: Al | T52: Ya / Tidak | U52: Slot waktu
A53: 1 | B53: BT | C53: Bangun tidur di pagi hari
A54: 2 | B54: MD1 | C54: Mandi di pagi hari
A55: 3 | B55: MA1 | C55: Memandikan anak di pagi hari
A56: 4 | B56: MK1 | C56: Menyuapi anak makan pagi
A57: 5 | B57: MK2 | C57: Makan pagi
A58: 6 | B58: TDS | C58: Tidur siang
A59: 7 | B59: MK3 | C59: Menyuapi anak makan siang
A60: 8 | B60: MK4 | C60: Makan siang
A61: 9 | B61: MD2 | C61: Mandi di sore hari
A62: 10 | B62: MA2 | C62: Memandikan anak di sore hari
A63: 11 | B63: CP1 | C63: Meletakkan pakaian kotor sebelum mandi
A64: 12 | B64: CP2 | C64: Meletakkan pakaian kotor setelah mandi
... A92: 35 | B92: MK7 | C92: Makan bersama keluarga
A96: DATA RENCANA IBU_SILVI
A97: No | B97: Kode | C97: Aktivitas | D97: KATEGORI AKTIVITAS | N97: WAKTU AKTIVITAS
D98: Aturan | H98: Kebiasaan | K98: Rencana Reguler | N98: Rentang Waktu | O98: Kelompok Waktu | T98: Rencana Insidental | V98: Rentang waktu Insidental | W98: Durasi (menit)
D99: Ya | E99: Tidak | F99: R2 | G99: R1 | H99: Ya | I99: Tidak | J99: H1 | K99: Ya | L99: Tidak | M99: P1 | O99: Pg | P99: Si | Q99: Sr | R99: Ml | S99: Al | T99: Ya / Tidak | U99: Slot waktu
A100: 1 | B100: BT | C100: Bangun tidur di pagi hari
A101: 2 | B101: M1A | C101: Membersihkan Teras A
...

Sheet SYARAT_SILVI
A1: SYARAT AYAH_PAULA
A2: NO | B2: KODE | C2: AKTIVITAS | D2: Peluang Dilakukan | E2: Tingkat Kemampuan Minimal | F2: FAKTOR FISIK LINGKUNGAN | V2: FAKTOR SUMBER DAYA | AL2: FAKTOR RUANG | BG2: RUANG UNTUK AKTIVITAS
V3: Air/Listrik/Gas/Makanan/Bahan Makanan/Bahan Bacaan | AL3: Kursi/Sofa/Karpet/Pintu/Tempat Tidur/Alat Kebersihan/ Alat Berkebun | BG3: Ruang Alternatif 1 | BH3: Ruang Alternatif 2 | BI3: Kondisi Ruang Alt 1 | BJ3: Jika Hidup Pilih | BK3: Jika Mati Pilih
F4: F1 Cahaya | N4: F2 Suhu | V4: R1 | AD4: R2 | AL4: D1 | AT4: D2 | BB4: D3
F5: Ya / Tidak | G5: Batas | H5: Kondisi Terkini | I5: Aktivitas Pendukung Sebelum | J5: Peluang Dilakukan | K5: Aktivitas Pendukung Setelah | L5: Peluang Dilakukan | M5: Obyek Lampu | N5: Ya / Tidak | O5: Batas | P5: Kondisi Terkini | Q5: Aktivitas Pendukung Sebelum | R5: Peluang Dilakukan | S5: Aktivitas Pendukung Setelah | T5: Peluang Dilakukan | U5: Obyek Pengatur Suhu Ruang | V5: Ya / Tidak | W5: Komponen | X5: Kondisi Terkini | Y5: Aktivitas Pendukung Sebelum | Z5: Peluang Dilakukan | AA5: Aktivitas Pendukung Setelah | AB5: Peluang Dilakukan | AC5: Obyek Lingkungan | AD5: Ya / Tidak | AE5: Komponen | AF5: Kondisi Terkini | AG5: Aktivitas Pendukung Sebelum | AH5: Peluang Dilakukan | AI5: Aktivitas Pendukung Setelah | AJ5: Peluang Dilakukan | AK5: Obyek Lingkungan | AL5: Ya / Tidak | AM5: Komponen | AN5: Kondisi Terkini | AO5: Aktivitas Pendukung Sebelum | AP5: Peluang Dilakukan | AQ5: Aktivitas Pendukung Setelah | AR5: Peluang Dilakukan | AS5: Obyek Lingkungan | AT5: Ya / Tidak | AU5: Komponen | AV5: Kondisi Terkini | AW5: Aktivitas Pendukung Sebelum | AX5: Peluang Dilakukan | AY5: Aktivitas Pendukung Setelah | AZ5: Peluang Dilakukan | BA5: Obyek Lingkungan | BB5: Ya / Tidak | BC5: Komponen | BD5: Kondisi Terkini | BE5: Jika Komponen Mati Pilih | BF5: Alat
A6: =DP_SILVI!A5 -> 1 | B6: =DP_SILVI!B5 -> BT | C6: =DP_SILVI!C5 -> Bangun tidur di pagi hari | E6: 2 | F6: Tidak | G6: 0 | H6: 0 | I6: 0 | M6: 0 | N6: Tidak | O6: 0 | P6: 0 | Q6: 0 | U6: 0 | V6: Tidak | W6: 0 | X6: 0 | Y6: 0 | AC6: 0 | AD6: Tidak | AE6: 0 | AF6: 0 | AG6: 0 | AK6: 0 | AL6: Ya | AM6: Tempat Tidur | AN6: Mati | AO6: T4 | AS6: TD1 | AT6: Tidak | AU6: 0 | AV6: 0 | AW6: 0 | BA6: 0 | BB6: Tidak | BC6: 0 | BD6: 0 | BE6: 0 | BF6: 0 | BG6: Rg Tidur Utama | BI6: Hidup | BJ6: J2 | BK6: J1
A7: =DP_SILVI!A6 -> 2 | B7: =DP_SILVI!B6 -> OR | C7: =DP_SILVI!C6 -> Olahraga pagi | E7: 2 | F7: Ya | G7: 100 | H7: 40 | I7: S1 | M7: L18 | N7: Tidak | O7: 0 | P7: 0 | Q7: 0 | U7: 0 | V7: Tidak | W7: 0 | X7: 0 | Y7: 0 | AC7: 0 | AD7: Tidak | AE7: 0 | AF7: 0 | AG7: 0 | AK7: 0 | AL7: Ya | AM7: Tempat Tidur | AN7: Mati | AO7: T4 | AS7: TD1 | AT7: Tidak | AU7: 0 | AV7: 0 | AW7: 0 | BA7: 0 | BB7: Tidak | BC7: 0 | BD7: 0 | BE7: 0 | BF7: 0 | BG7: Rg Tidur Utama | BI7: Hidup | BJ7: J2 | BK7: J1
A8: =DP_SILVI!A7 -> 3 | B8: =DP_SILVI!B7 -> MD1 | C8: =DP_SILVI!C7 -> Mandi di pagi hari | E8: 4 | F8: Ya | G8: 100 | H8: 40 | I8: S1 | M8: L10 | N8: Tidak | O8: 0 | P8: 0 | Q8: 0 | U8: 0 | V8: Ya | W8: Air | X8: Hidup | Y8: O1 | AC8: WT03 | AD8: Tidak | AE8: 0 | AF8: 0 | AG8: 0 | AK8: 0 | AL8: Ya | AM8: Pintu | AN8: Mati | AO8: G3 | AS8: P8 | AT8: Tidak | AU8: 0 | AV8: 0 | AW8: 0 | BA8: 0 | BG8: KM | BI8: Hidup | BJ8: J2 | BK8: J1
A9: =DP_SILVI!A8 -> 4 | B9: =DP_SILVI!B8 -> MK2 | C9: =DP_SILVI!C8 -> Makan pagi | E9: 4 | F9: Ya | G9: 100 | H9: 40 | I9: S1 | M9: L10 | N9: Tidak | O9: 0 | P9: 0 | Q9: 0 | U9: 0 | V9: Ya | W9: Air | X9: Hidup | Y9: O1 | AC9: WT03 | AD9: Tidak | AE9: 0 | AF9: 0 | AG9: 0 | AK9: 0 | AL9: Ya | AM9: Pintu | AN9: Mati | AO9: G4 | AS9: P8 | AT9: Tidak | AU9: 0 | AV9: 0 | AW9: 0 | BA9: 0 | BG9: KM | BI9: Hidup | BJ9: J2 | BK9: J1
A10: =DP_SILVI!A9 -> 5 | B10: =DP_SILVI!B9 -> KJ1 | C10: =DP_SILVI!C9 -> Berangkat kerja | E10: 2 | F10: Ya | G10: 100 | H10: 40 | I10: S1 | M10: L11 | N10: Tidak | O10: 0 | P10: 0 | Q10: 0 | U10: 0 | V10: Ya | W10: Makanan | X10: Hidup | Y10: G5 | AC10: RC02 | AD10: Tidak | AE10: 0 | AF10: 0 | AG10: 0 | AK10: 0 | AL10: Ya | AM10: Kursi/Karpet/Sofa | AN10: Mati | AO10: K/KR/S | AS10: K01 | AT10: Tidak | AU10: 0 | AV10: 0 | AW10: 0 | BA10: 0 | BG10: RMKn | BI10: Hidup | BJ10: J2 | BK10: J1
A11: =DP_SILVI!A10 -> 6 | B11: =DP_SILVI!B10 -> KJ3 | C11: =DP_SILVI!C10 -> Pulang kerja | E11: 4 | F11: Ya | G11: 100 | H11: 40 | I11: S1 | M11: L6/ L4/ L5 | N11: Tidak | O11: 0 | P11: 0 | Q11: 0 | U11: 0 | V11: Ya | W11: Listrik | X11: Hidup | Y11: S6 | AD11: Tidak | AE11: 0 | AF11: 0 | AG11: 0 | AK11: 0 | AL11: Ya | AM11: Kursi/Karpet/Sofa | AN11: Mati | AO11: K/KR/S | AS11: S10/ KR01 | AT11: Ya | AU11: Kursi/Karpet/Sofa | AV11: Mati | AW11: K/KR/S | BA11: S04 | BG11: R Keluarga | BH11: R Tamu | BI11: Hidup | BJ11: J2 | BK11: J1
A12: =DP_SILVI!A11 -> 7 | B12: =DP_SILVI!B11 -> TDS | C12: =DP_SILVI!C11 -> Tidur siang | E12: 4 | F12: Tidak | G12: 0 | H12: 0 | I12: 0 | M12: 0 | N12: Tidak | O12: 0 | P12: 0 | Q12: 0 | U12: 0 | V12: Tidak | W12: 0 | X12: 0 | Y12: 0 | AC12: 0 | AD12: Tidak | AE12: 0 | AF12: 0 | AG12: 0 | AK12: 0 | AL12: Tidak | AM12: 0 | AN12: 0 | AO12: 0 | AS12: 0 | AT12: Tidak | AU12: 0 | AV12: 0 | AW12: 0 | BA12: 0 | BG12: Garasi | BI12: Hidup | BJ12: J2 | BK12: J1
A13: =DP_SILVI!A12 -> 8 | B13: =DP_SILVI!B12 -> MK4 | C13: =DP_SILVI!C12 -> Makan siang | E13: 4 | F13: Tidak | G13: 0 | H13: 0 | I13: 0 | M13: 0 | N13: Tidak | O13: 0 | P13: 0 | Q13: 0 | U13: 0 | V13: Tidak | W13: 0 | X13: 0 | Y13: 0 | AC13: 0 | AD13: Tidak | AE13: 0 | AF13: 0 | AG13: 0 | AK13: 0 | AL13: Tidak | AM13: 0 | AN13: 0 | AO13: 0 | AS13: 0 | AT13: Tidak | AU13: 0 | AV13: 0 | AW13: 0 | BA13: 0 | BG13: Garasi | BI13: Hidup | BJ13: J2 | BK13: J1
A14: =DP_SILVI!A13 -> 9 | B14: =DP_SILVI!B13 -> GR | C14: =DP_SILVI!C13 -> Memarkir kendaraan di garasi | E14: 2 | F14: Ya | G14: 100 | H14: 40 | I14: S1 | M14: L3 | N14: Ya | O14: 25 | P14: 27 | Q14: S2 | U14: AC01/ KP02 | V14: Tidak | W14: 0 | X14: 0 | Y14: 0 | AC14: 0 | AD14: Tidak | AE14: 0 | AF14: 0 | AG14: 0 | AK14: 0 | AL14: Ya | AM14: Tempat Tidur | AN14: Mati | AO14: T2 | AS14: TD1 | AT14: Tidak | AU14: 0 | AV14: 0 | AW14: 0 | BA14: 0 | BG14: Rg Tidur Utama | BI14: Hidup | BJ14: J2 | BK14: J1
A15: =DP_SILVI!A14 -> 10 | B15: =DP_SILVI!B14 -> MD2 | C15: =DP_SILVI!C14 -> Mandi di sore hari | E15: 2 | F15: Ya | G15: 100 | H15: 40 | I15: S1 | M15: L11 | N15: Tidak | O15: 0 | P15: 0 | Q15: 0 | U15: 0 | V15: Ya | W15: Makanan | X15: Hidup | Y15: G5 | AC15: RC02 | AD15: Tidak | AE15: 0 | AF15: 0 | AG15: 0 | AK15: 0 | AL15: Ya | AM15: Kursi/Karpet/Sofa | AN15: Mati | AO15: K/KR/S | AS15: K01 | AT15: Tidak | AU15: 0 | AV15: 0 | AW15: 0 | BA15: 0 | BG15: R Makan | BH15: R keluarga | BI15: Hidup | BJ15: J2 | BK15: J1
A16: =DP_SILVI!A15 -> 11 | B16: =DP_SILVI!B15 -> CP1 | C16: =DP_SILVI!C15 -> Meletakkan pakaian kotor sebelum mandi | E16: 8 | F16: Ya | G16: 100 | H16: 40 | I16: S1 | M16: L2 | N16: Tidak | O16: 0 | P16: 0 | Q16: 0 | U16: 0 | V16: Tidak | W16: 0 | X16: 0 | Y16: 0 | AC16: 0 | AD16: Tidak | AE16: 0 | AF16: 0 | AG16: 0 | AK16: 0 | AL16: Ya | AM16: Pintu | AN16: Mati | AO16: G2 | AS16: P13 | AT16: Tidak | AU16: 0 | AV16: 0 | AW16: 0 | BA16: 0 | BG16: Garasi | BI16: Hidup | BJ16: J2 | BK16: J1
A17: =DP_SILVI!A16 -> 12 | B17: =DP_SILVI!B16 -> CP2 | C17: =DP_SILVI!C16 -> Meletakkan pakaian kotor setelah mandi | E17: 4 | F17: Ya | G17: 100 | H17: 40 | I17: S1 | M17: L10 | N17: Tidak | O17: 0 | P17: 0 | Q17: 0 | U17: 0 | V17: Ya | W17: Air | X17: Hidup | Y17: O1 | AC17: WT03 | AD17: Tidak | AE17: 0 | AF17: 0 | AG17: 0 | AK17: 0 | AL17: Ya | AM17: Pintu | AN17: Mati | AO17: G2 | AS17: P8 | AT17: Tidak | AU17: 0 | AV17: 0 | AW17: 0 | BA17: 0 | BG17: KM | BI17: Hidup | BJ17: J2 | BK17: J1
A18: =DP_SILVI!A17 -> 13 | B18: =DP_SILVI!B17 -> CP3 | C18: =DP_SILVI!C17 -> Mengambil pakaian bersih sebelum mandi | E18: 2 | F18: Ya | G18: 100 | H18: 40 | I18: S1 | M18: L13 | N18: Tidak | O18: 0 | P18: 0 | Q18: 0 | U18: 0 | V18: Tidak | W18: 0 | X18: 0 | Y18: 0 | AC18: 0 | AD18: Tidak | AE18: 0 | AF18: 0 | AG18: 0 | AK18: 0 | AL18: Ya | AM18: Pintu | AN18: Mati | AO18: G2 | AS18: P11 | AT18: Tidak | AU18: 0 | AV18: 0 | AW18: 0 | BA18: 0 | BG18: R Cuci | BI18: Hidup | BJ18: J2 | BK18: J1
A19: =DP_SILVI!A18 -> 14 | B19: =DP_SILVI!B18 -> CP4 | C19: =DP_SILVI!C18 -> Mengambil pakaian bersih setelah mandi | E19: 2 | F19: Ya | G19: 100 | H19: 40 | I19: S1 | M19: L3 | N19: Tidak | O19: 0 | P19: 0 | Q19: 0 | U19: 0 | V19: Tidak | W19: 0 | X19: 0 | Y19: 0 | AC19: 0 | AD19: Tidak | AE19: 0 | AF19: 0 | AG19: 0 | AK19: 0 | AL19: Ya | AM19: Pintu | AN19: Mati | AO19: G2 | AS19: P4 | AT19: Tidak | AU19: 0 | AV19: 0 | AW19: 0 | BA19: 0 | BG19: RT Utama | BI19: Hidup | BJ19: J2 | BK19: J1
A20: =DP_SILVI!A19 -> 15 | B20: =DP_SILVI!B19 -> MK6 | C20: =DP_SILVI!C19 -> Makan malam | E20: 2 | F20: Ya | G20: 100 | H20: 40 | I20: S1 | M20: L11 | N20: Tidak | O20: 0 | P20: 0 | Q20: 0 | U20: 0 | V20: Ya | W20: Makanan | X20: Hidup | Y20: G5 | AC20: RC02 | AD20: Tidak | AE20: 0 | AF20: 0 | AG20: 0 | AK20: 0 | AL20: Ya | AM20: Kursi/Karpet/Sofa | AN20: Mati | AO20: K/KR/S | AS20: K01 | AT20: Tidak | AU20: 0 | AV20: 0 | AW20: 0 | BA20: 0 | BG20: R Makan | BH20: R keluarga | BI20: Hidup | BJ20: J2 | BK20: J1
A21: =DP_SILVI!A20 -> 16 | B21: =DP_SILVI!B20 -> BP | C21: =DP_SILVI!C20 -> Berpakaian dan berdandan | E21: 2 | F21: Ya | G21: 100 | H21: 40 | I21: S1 | M21: L3 | N21: Tidak | O21: 0 | P21: 0 | Q21: 0 | U21: 0 | V21: Tidak | W21: 0 | X21: 0 | Y21: 0 | AC21: 0 | AD21: Tidak | AE21: 0 | AF21: 0 | AG21: 0 | AK21: 0 | AL21: Ya | AM21: Pintu | AN21: Mati | AO21: G2 | AS21: P4 | AT21: Tidak | AU21: 0 | AV21: 0 | AW21: 0 | BA21: 0 | BC21: Karpet | BD21: Hidup | BE21: Kr1 | BG21: Rg Tidur Utama | BH21: Rg Tidur 2 | BI21: Hidup | BJ21: J2 | BK21: J1
A22: =DP_SILVI!A21 -> 17 | B22: =DP_SILVI!B21 -> TDM | C22: =DP_SILVI!C21 -> Tidur malam | E22: 2 | F22: Ya | G22: 100 | H22: 40 | I22: S1 | M22: L3/ L18 | N22: Ya | O22: 25 | P22: 27 | Q22: S2 | U22: AC01/ KP02 | V22: Tidak | W22: 0 | X22: 0 | Y22: 0 | AC22: 0 | AD22: Tidak | AE22: 0 | AF22: 0 | AG22: 0 | AK22: 0 | AL22: Ya | AM22: Tempat Tidur | AN22: Mati | AO22: T2 | AS22: P4 | AT22: Tidak | AU22: 0 | AV22: 0 | AW22: 0 | BA22: 0 | BG22: Rg Tidur Utama | BI22: Hidup | BJ22: J2 | BK22: J1
A23: =DP_SILVI!A22 -> 18 | B23: =DP_SILVI!B22 -> TD | C23: =DP_SILVI!C22 -> Tidur (diluar waktu tidur malam & siang) | E23: 2 | F23: Ya | G23: 100 | H23: 40 | I23: S1 | M23: L3/ L18 | N23: Ya | O23: 25 | P23: 27 | Q23: S2 | U23: AC01/ KP02 | V23: Tidak | W23: 0 | X23: 0 | Y23: 0 | AC23: 0 | AD23: Tidak | AE23: 0 | AF23: 0 | AG23: 0 | AK23: 0 | AL23: Ya | AM23: Tempat Tidur | AN23: Mati | AO23: T2 | AS23: P4 | AT23: Tidak | AU23: 0 | AV23: 0 | AW23: 0 | BA23: 0 | BG23: Rg Tidur Utama | BI23: Hidup | BJ23: J2 | BK23: J1
A24: =DP_SILVI!A23 -> 19 | B24: =DP_SILVI!B23 -> TO | C24: =DP_SILVI!C23 -> Toilet (hanya BAK/BAB) | E24: 4 | F24: Ya | G24: 100 | H24: 40 | I24: S1 | M24: L10 | N24: Tidak | O24: 0 | P24: 0 | Q24: 0 | U24: 0 | V24: Ya | W24: Air | X24: Hidup | Y24: O1 | AC24: WT03 | AD24: Tidak | AE24: 0 | AF24: 0 | AG24: 0 | AK24: 0 | AL24: Ya | AM24: Pintu | AN24: Mati | AO24: G2 | AS24: P8 | AT24: Tidak | AU24: 0 | AV24: 0 | AW24: 0 | BA24: 0 | BG24: KM | BI24: Hidup | BJ24: J2 | BK24: J1
A25: =DP_SILVI!A24 -> 20 | B25: =DP_SILVI!B24 -> MD | C25: =DP_SILVI!C24 -> Mandi (diluar waktu mandi pagi dan sore) | E25: 4 | F25: Ya | G25: 100 | H25: 40 | I25: S1 | M25: L10 | N25: Tidak | O25: 0 | P25: 0 | Q25: 0 | U25: 0 | V25: Ya | W25: Air | X25: Hidup | Y25: O1 | AC25: WT03 | AD25: Tidak | AE25: 0 | AF25: 0 | AG25: 0 | AK25: 0 | AL25: Ya | AM25: Pintu | AN25: Mati | AO25: G2 | AS25: P8 | AT25: Tidak | AU25: 0 | AV25: 0 | AW25: 0 | BA25: 0 | BG25: KM | BI25: Hidup | BJ25: J2 | BK25: J1
A26: =DP_SILVI!A25 -> 21 | B26: =DP_SILVI!B25 -> MK | C26: =DP_SILVI!C25 -> Makan (diluar waktu makan pagi, siang, malam) | E26: 6 | F26: Ya | G26: 100 | H26: 40 | I26: S1 | M26: L10 | N26: Tidak | O26: 0 | P26: 0 | Q26: 0 | U26: 0 | V26: Ya | W26: Air | X26: Hidup | Y26: O1 | AC26: WT03 | AD26: Tidak | AE26: 0 | AF26: 0 | AG26: 0 | AK26: 0 | AL26: Ya | AM26: Pintu | AN26: Mati | AO26: G2 | AS26: P8 | AT26: Tidak | AU26: 0 | AV26: 0 | AW26: 0 | BA26: 0 | BG26: KM | BI26: Hidup | BJ26: J2 | BK26: J1
A27: =DP_SILVI!A26 -> 22 | B27: =DP_SILVI!B26 -> MN1 | C27: =DP_SILVI!C26 -> Minum setelah makan pagi | E27: 2 | F27: Ya | G27: 100 | H27: 40 | I27: S1 | M27: L11/ L6 | N27: Tidak | O27: 0 | P27: 0 | Q27: 0 | U27: 0 | V27: Ya | W27: Makanan | X27: Hidup | Y27: G5 | AC27: RC02/RC01 | AD27: Tidak | AE27: 0 | AF27: 0 | AG27: 0 | AK27: 0 | AL27: Ya | AM27: Kursi/Karpet/Sofa | AN27: Mati | AO27: K/KR/S | AS27: K01 | AT27: Tidak | AU27: 0 | AV27: 0 | AW27: 0 | BA27: 0 | BG27: R Makan | BH27: Rg Keluarga | BI27: Hidup | BJ27: J2 | BK27: J1
A28: =DP_SILVI!A27 -> 23 | B28: =DP_SILVI!B27 -> MN2 | C28: =DP_SILVI!C27 -> Minum setelah makan siang | E28: 2 | F28: Ya | G28: 100 | H28: 40 | I28: S1 | M28: L12/ L11 | N28: Tidak | O28: 0 | P28: 0 | Q28: 0 | U28: 0 | V28: Ya | W28: Listrik | X28: Hidup | Y28: L2 | AC28: DP01 | AD28: Ya | AE28: Air | AF28: Hidup | AG28: O1 | AK28: 0 | AL28: Ya | AM28: Kursi/Karpet/Sofa | AN28: Mati | AO28: K/KR/S | AS28: K01 | AT28: Tidak | AU28: 0 | AV28: 0 | AW28: 0 | BA28: 0 | BG28: Dapur | BH28: R Makan | BI28: Hidup | BJ28: J2 | BK28: J1
A29: =DP_SILVI!A28 -> 24 | B29: =DP_SILVI!B28 -> MN3 | C29: =DP_SILVI!C28 -> Minum setelah makan malam | E29: 2 | F29: Ya | G29: 100 | H29: 40 | I29: S1 | M29: L12/ L11 | N29: Tidak | O29: 0 | P29: 0 | Q29: 0 | U29: 0 | V29: Ya | W29: Listrik | X29: Hidup | Y29: L2 | AC29: DP01 | AD29: Ya | AE29: Air | AF29: Hidup | AG29: O1 | AK29: 0 | AL29: Ya | AM29: Kursi/Karpet/Sofa | AN29: Mati | AO29: K/KR/S | AS29: K01 | AT29: Tidak | AU29: 0 | AV29: 0 | AW29: 0 | BA29: 0 | BG29: Dapur | BH29: R Makan | BI29: Hidup | BJ29: J2 | BK29: J1
A30: =DP_SILVI!A29 -> 25 | B30: =DP_SILVI!B29 -> MN4 | C30: =DP_SILVI!C29 -> Minum (diluar waktu makan pagi, siang, malam) | E30: 2 | F30: Ya | G30: 100 | H30: 40 | I30: S1 | M30: L12/ L11 | N30: Tidak | O30: 0 | P30: 0 | Q30: 0 | U30: 0 | V30: Ya | W30: Listrik | X30: Hidup | Y30: L2 | AC30: DP01 | AD30: Ya | AE30: Air | AF30: Hidup | AG30: O1 | AK30: 0 | AL30: Ya | AM30: Kursi/Karpet/Sofa | AN30: Mati | AO30: K/KR/S | AS30: K01 | AT30: Tidak | AU30: 0 | AV30: 0 | AW30: 0 | BA30: 0 | BG30: Dapur | BH30: R Makan | BI30: Hidup | BJ30: J2 | BK30: J1
A31: =DP_SILVI!A30 -> 26 | B31: =DP_SILVI!B30 -> BS | C31: =DP_SILVI!C30 -> Bersantai (waktu ditentukan responden) | E31: 2 | F31: Ya | G31: 100 | H31: 40 | I31: S1 | M31: L12/ L11 | N31: Tidak | O31: 0 | P31: 0 | Q31: 0 | U31: 0 | V31: Ya | W31: Listrik | X31: Hidup | Y31: L2 | AC31: DP01 | AD31: Ya | AE31: Air | AF31: Hidup | AG31: O1 | AK31: 0 | AL31: Ya | AM31: Kursi/Karpet/Sofa | AN31: Mati | AO31: K/KR/S | AS31: K01 | AT31: Tidak | AU31: 0 | AV31: 0 | AW31: 0 | BA31: 0 | BG31: Dapur | BH31: R Makan | BI31: Hidup | BJ31: J2 | BK31: J1
A32: =DP_SILVI!A31 -> 27 | B32: =DP_SILVI!B31 -> GD1 | C32: =DP_SILVI!C31 -> Mengisi ulang daya gadget | E32: 8 | F32: Ya | G32: 0 | H32: 40 | I32: S8 | M32: 0 | N32: Tidak | O32: 0 | P32: 0 | Q32: 0 | U32: 0 | V32: Ya | W32: Listrik | X32: Mati | Y32: L1 | AD32: Tidak | AE32: 0 | AF32: 0 | AG32: 0 | AK32: 0 | AL32: Tidak | AM32: 0 | AN32: 0 | AO32: 0 | AS32: 0 | AT32: Tidak | AU32: 0 | AV32: 0 | AW32: 0 | BA32: 0 | BI32: Hidup | BJ32: J2 | BK32: J1
A33: =DP_SILVI!A32 -> 28 | B33: =DP_SILVI!B32 -> GD2 | C33: =DP_SILVI!C32 -> Mengoperasikan gadget | E33: 2 | F33: Ya | G33: 100 | H33: 40 | I33: S1 | M33: L3/ L6 | N33: Ya | O33: 25 | P33: 27 | Q33: S2 | U33: AC01/ KP02 | V33: Tidak | W33: 0 | X33: 0 | Y33: 0 | AC33: 0 | AD33: Tidak | AE33: 0 | AF33: 0 | AG33: 0 | AK33: 0 | AL33: Ya | AM33: Tempat Tidur | AN33: Mati | AO33: T2 | AS33: TD1 | AT33: Ya | AU33: Kursi/Karpet/Sofa | AV33: Mati | AW33: K/KR/S | BA33: S10 | BG33: Rg Tidur Utama | BH33: Rg Keluarga | BI33: Hidup | BJ33: J2 | BK33: J1
A34: =DP_SILVI!A33 -> 29 | B34: =DP_SILVI!B33 -> TV | C34: =DP_SILVI!C33 -> Menonton TV (waktu ditentukan responden) | E34: 2 | F34: Ya | G34: 100 | H34: 40 | I34: S1 | M34: L3/ L7 | N34: Tidak | O34: 0 | P34: 0 | Q34: 0 | U34: 0 | V34: Ya | W34: Listrik | X34: Mati | Y34: L2 | AD34: Tidak | AE34: 0 | AF34: 0 | AG34: 0 | AK34: 0 | AL34: Tidak | AM34: 0 | AN34: 0 | AO34: 0 | AS34: 0 | AT34: Tidak | AU34: 0 | AV34: 0 | AW34: 0 | BA34: 0 | BG34: Rg Tidur Utama | BH34: Rg Keluarga | BI34: Hidup | BJ34: J2 | BK34: J1
A35: =DP_SILVI!A34 -> 30 | B35: =DP_SILVI!B34 -> BM1 | C35: =DP_SILVI!C34 -> Mengawasi anak/adik bermain | E35: 2 | F35: Ya | G35: 100 | H35: 40 | I35: S1 | M35: L3/ L6 | N35: Tidak | O35: 0 | P35: 0 | Q35: 0 | U35: 0 | V35: Tidak | W35: 0 | X35: 0 | Y35: 0 | AC35: 0 | AD35: Tidak | AE35: 0 | AF35: 0 | AG35: 0 | AK35: 0 | AL35: Ya | AM35: Tempat Tidur | AN35: Mati | AO35: T2 | AS35: TD1 | AT35: Ya | AU35: Kursi/Karpet/Sofa | AV35: Mati | AW35: K/KR/S | BA35: S10/ KR01 | BG35: Rg Tidur Utama | BH35: Rg Keluarga | BI35: Hidup | BJ35: J2 | BK35: J1
A36: =DP_SILVI!A35 -> 31 | B36: =DP_SILVI!B35 -> BM2 | C36: =DP_SILVI!C35 -> Bermain (waktu ditentukan responden) | E36: 2 | F36: Ya | G36: 100 | H36: 40 | I36: S1 | M36: L6 | N36: Ya | O36: 25 | P36: 27 | Q36: S2 | U36: KP01 | V36: Ya | W36: Listrik | X36: Mati | Y36: L2 | AC36: TV01 | AD36: Tidak | AE36: 0 | AF36: 0 | AG36: 0 | AK36: 0 | AL36: Ya | AM36: Kursi/Karpet/Sofa | AN36: Mati | AO36: K/KR/S | AS36: S10/ KR01 | AT36: Tidak | AU36: 0 | AV36: 0 | AW36: 0 | BA36: 0 | BG36: Rg Keluarga | BI36: Hidup | BJ36: J2 | BK36: J1
A37: =DP_SILVI!A36 -> 32 | B37: =DP_SILVI!B36 -> MT | C37: =DP_SILVI!C36 -> Menerima tamu | E37: 4 | F37: Ya | G37: 100 | H37: 40 | I37: S1 | M37: L6/ L4/ L5 | N37: Ya | O37: 25 | P37: 27 | Q37: S2 | U37: KP01 | V37: Tidak | W37: 0 | X37: 0 | Y37: 0 | AC37: 0 | AD37: Tidak | AE37: 0 | AF37: 0 | AG37: 0 | AK37: 0 | AL37: Ya | AM37: Kursi/Karpet/Sofa | AN37: Mati | AO37: K/KR/S | AS37: S10/ KR01 | AT37: Ya | AU37: Kursi/Karpet/Sofa | AV37: Mati | AW37: K/KR/S | BA37: S04 | BG37: Rg Keluarga | BH37: R Tamu | BI37: Hidup | BJ37: J2 | BK37: J1
A38: =DP_SILVI!A37 -> 33 | B38: =DP_SILVI!B37 -> IB | C38: =DP_SILVI!C37 -> Ibadah (di rumah responden) | E38: 6 | F38: Ya | G38: 100 | H38: 40 | I38: S1 | M38: L4/ L5/ L6 | N38: Tidak | O38: 0 | P38: 0 | Q38: 0 | U38: 0 | V38: Tidak | W38: 0 | X38: 0 | Y38: 0 | AC38: 0 | AD38: Tidak | AE38: 0 | AF38: 0 | AG38: 0 | AK38: 0 | AL38: Ya | AM38: Kursi/Karpet/Sofa | AN38: Mati | AO38: K/KR/S | AS38: S04 | AT38: Ya | AU38: Kursi/Karpet/Sofa | AV38: Mati | AW38: K/KR/S | BA38: S10 | BG38: R Tamu | BH38: Rg Keluarga | BI38: Hidup | BJ38: J2 | BK38: J1
A39: =DP_SILVI!A42 -> 34 | B39: =DP_SILVI!B42 -> HT | C39: =DP_SILVI!C42 -> Menggunakan home theater | E39: 8 | F39: Ya | G39: 100 | H39: 40 | I39: S1 | M39: L4/ L5/ L2 | N39: Tidak | O39: 0 | P39: 0 | Q39: 0 | U39: 0 | V39: Tidak | W39: 0 | X39: 0 | Y39: 0 | AC39: 0 | AD39: Tidak | AE39: 0 | AF39: 0 | AG39: 0 | AK39: 0 | AL39: Ya | AM39: Kursi/Karpet/Sofa | AN39: Mati | AO39: K/KR/S | AS39: S04 | AT39: Tidak | AU39: 0 | AV39: 0 | AW39: 0 | BA39: 0 | BG39: R Tamu | BH39: Garasi | BI39: Hidup | BJ39: J2 | BK39: J1
A40: =DP_SILVI!A43 -> 35 | B40: =DP_SILVI!B43 -> MK7 | C40: =DP_SILVI!C43 -> Makan bersama keluarga | E40: 4 | F40: Ya | G40: 100 | H40: 40 | I40: S1 | M40: L4/ L5 | N40: Tidak | O40: 0 | P40: 0 | Q40: 0 | U40: 0 | V40: Tidak | W40: 0 | X40: 0 | Y40: 0 | AC40: 0 | AD40: Tidak | AE40: 0 | AF40: 0 | AG40: 0 | AK40: 0 | AL40: Ya | AM40: Kursi/Karpet/Sofa | AN40: Mati | AO40: K/KR/S | AS40: S04 | AT40: Tidak | AU40: 0 | AV40: 0 | AW40: 0 | BA40: 0 | BG40: R Tamu | BI40: Hidup | BJ40: J2 | BK40: J1
...

Sheet PENDUKUNG_ALL
A1: PENDUKUNG SEBELUM | H1: PENDUKUNG SETELAH
A2: No | B2: Kode | C2: Aktivitas | D2: Durasi | F2: Status Operasional | H2: No | I2: Kode | J2: Aktivitas | K2: Durasi | M2: Status Operasional
D3: Nilai | E3: Satuan | K3: Nilai | L3: Satuan
A4: 1 | B4: S1 | C4: Menghidupkan lampu | D4: 1 | E4: menit | F4: Hidup / Mati | H4: 1 | I4: S8 | J4: Mematikan lampu | K4: 1 | L4: menit | M4: Hidup / Mati
A5: 2 | B5: S2 | C5: Menghidupkan AC/kipas | D5: 5 | E5: menit | H5: 2 | I5: S9 | J5: Mematikan AC/kipas | K5: 5 | L5: menit
A6: 3 | B6: S3 | C6: Menghidupkan setrika | D6: 1 | E6: menit | H6: 3 | I6: S10 | J6: Mematikan setrika | K6: 1 | L6: menit
A7: 4 | B7: S4 | C7: Menghidupkan TV | D7: 1 | E7: menit | H7: 4 | I7: S11 | J7: Mematikan TV | K7: 1 | L7: menit
A8: 5 | B8: S5 | C8: Menghidupkan radio | D8: 1 | E8: menit | H8: 5 | I8: S12 | J8: Mematikan radio | K8: 1 | L8: menit
A9: 6 | B9: S6 | C9: Menghidupkan komputer/laptop | D9: 1 | E9: menit | H9: 6 | I9: S13 | J9: Mematikan komputer/laptop | K9: 1 | L9: menit
A10: 7 | B10: S7 | C10: Menghidupkan mesin cuci | D10: 30 | E10: menit | H10: 7 | I10: J3 | J10: Keluar dari ruang | K10: 1 | L10: menit
A11: 8 | B11: J1 | C11: Berjalan ke ruang | D11: 1 | E11: menit | H11: 8 | I11: O9 | J11: Mematikan kran air | K11: 1 | L11: menit
A12: 9 | B12: J2 | C12: Masuk ke ruang | D12: 1 | E12: menit | H12: 9 | I12: O10 | J12: Mematikan pompa air | K12: 1 | L12: menit
A13: 10 | B13: I1 | C13: Mengisi bahan bakar | D13: 5 | E13: menit | H13: 10 | I13: O11 | J13: Menyimpan peralatan berkebun | K13: 1 | L13: menit
A14: 11 | B14: O1 | C14: Menghidupkan kran air | D14: 1 | E14: menit | H14: 11 | I14: O12 | J14: Menyimpan peralatan kerja | K14: 1 | L14: menit
A15: 12 | B15: O2 | C15: Menghidupkan pompa air | D15: 1 | E15: menit | H15: 12 | I15: O13 | J15: Menyimpan peralatan les | K15: 1 | L15: menit
A16: 13 | B16: O3 | C16: Mengambil peralatan berkebun | D16: 1 | E16: menit | H16: 13 | I16: O14 | J16: Meletakkan pakaian kotor | K16: 1 | L16: menit
... A32: 29 | B32: Kr1 | C32: Duduk di karpet | D32: 1 | E32: menit | H32: 31 | I32: B4 | J32: Mematikan blender | K32: 1 | L32: menit
A33: 30 | B33: Kk1 | C33: Membuka kulkas | D33: 1 | E33: menit
A34: 31 | B34: T1 | C34: Membereskan Tempat Tidur | D34: 2 | E34: menit
A35: 32 | B35: T2 | C35: Berbaring di Tempat Tidur | D35: 3 | E35: menit
A36: 33 | B36: B1 | C36: Berangkat belanja | D36: 10 | E36: menit
A37: 34 | B37: B3 | C37: Menghidupkan blender | D37: 1 | E37: menit
A38: 35 | B38: L1 | C38: Mematikan peralatan listrik | D38: 3 | E38: menit
A39: 36 | B39: L2 | C39: Menghidupkan peralatan listrik | D39: 3 | E39: menit
A40: 37 | B40: A1 | C40: Mengambil air masak/minum | D40: 3 | E40: menit
A41: 38 | B41: B1 | C41: Mengambil bahan bacaan | D41: 1 | E41: menit
